Workbook

Sheet Geral
B1: Local (país) | D1: Local (estado) | E1: Designação do repositório | G1: Designação do conjunto documental | I1: Designação do subconjunto documental | K1: Gênero documental | M1: Espécie/Tipo documental | O1: Técnica de registro | Q1: Forma documental | S1: Unidade de descrição
A2: 1 | B2: BR | C2: - | D2: SP | E2: GPDVE | F2: _ | G2: ARCOENGE | H2: - | I2: DEMOLICAO-CSDTCARANDIRU | J2: _ | K2: ICO | L2: - | M2: FOT | N2: - | O2: DGZ | P2: - | Q2: MB0 | R2: _ | S2: 0001- | T2: 001 | U2: .JPG
A3: 2 | B3: BR | C3: - | D3: SP | E3: GPDVE | F3: _ | G3: ARCOENGE | H3: - | I3: DEMOLICAO-CSDTCARANDIRU | J3: _ | K3: ICO | L3: - | M3: FOT | N3: - | O3: DGZ | P3: - | Q3: MB0 | R3: _ | S3: 0001- | T3: 002 | U3: .JPG
A4: 3 | B4: BR | C4: - | D4: SP | E4: GPDVE | F4: _ | G4: ARCOENGE | H4: - | I4: DEMOLICAO-CSDTCARANDIRU | J4: _ | K4: ICO | L4: - | M4: FOT | N4: - | O4: DGZ | P4: - | Q4: MB0 | R4: _ | S4: 0001- | T4: 003 | U4: .JPG
A5: 4 | B5: BR | C5: - | D5: SP | E5: GPDVE | F5: _ | G5: ARCOENGE | H5: - | I5: DEMOLICAO-CSDTCARANDIRU | J5: _ | K5: ICO | L5: - | M5: FOT | N5: - | O5: DGZ | P5: - | Q5: MB0 | R5: _ | S5: 0001- | T5: 004 | U5: .JPG
A6: 5 | B6: BR | C6: - | D6: SP | E6: GPDVE | F6: _ | G6: ARCOENGE | H6: - | I6: DEMOLICAO-CSDTCARANDIRU | J6: _ | K6: ICO | L6: - | M6: FOT | N6: - | O6: DGZ | P6: - | Q6: MB0 | R6: _ | S6: 0001- | T6: 005 | U6: .JPG
A7: 6 | B7: BR | C7: - | D7: SP | E7: GPDVE | F7: _ | G7: ARCOENGE | H7: - | I7: DEMOLICAO-CSDTCARANDIRU | J7: _ | K7: ICO | L7: - | M7: FOT | N7: - | O7: DGZ | P7: - | Q7: MB0 | R7: _ | S7: 0001- | T7: 006 | U7: .JPG
A8: 7 | B8: BR | C8: - | D8: SP | E8: GPDVE | F8: _ | G8: ARCOENGE | H8: - | I8: DEMOLICAO-CSDTCARANDIRU | J8: _ | K8: ICO | L8: - | M8: FOT | N8: - | O8: DGZ | P8: - | Q8: MB0 | R8: _ | S8: 0001- | T8: 007 | U8: .JPG
A9: 8 | B9: BR | C9: - | D9: SP | E9: GPDVE | F9: _ | G9: ARCOENGE | H9: - | I9: DEMOLICAO-CSDTCARANDIRU | J9: _ | K9: ICO | L9: - | M9: FOT | N9: - | O9: DGZ | P9: - | Q9: MB0 | R9: _ | S9: 0001- | T9: 008 | U9: .JPG
A10: 9 | B10: BR | C10: - | D10: SP | E10: GPDVE | F10: _ | G10: ARCOENGE | H10: - | I10: DEMOLICAO-CSDTCARANDIRU | J10: _ | K10: ICO | L10: - | M10: FOT | N10: - | O10: DGZ | P10: - | Q10: MB0 | R10: _ | S10: 0001- | T10: 009 | U10: .JPG
A11: 10 | B11: BR | C11: - | D11: SP | E11: GPDVE | F11: _ | G11: ARCOENGE | H11: - | I11: DEMOLICAO-CSDTCARANDIRU | J11: _ | K11: ICO | L11: - | M11: FOT | N11: - | O11: DGZ | P11: - | Q11: MB0 | R11: _ | S11: 0001- | T11: 010 | U11: .JPG
A12: 11 | B12: BR | C12: - | D12: SP | E12: GPDVE | F12: _ | G12: ARCOENGE | H12: - | I12: DEMOLICAO-CSDTCARANDIRU | J12: _ | K12: ICO | L12: - | M12: FOT | N12: - | O12: DGZ | P12: - | Q12: MB0 | R12: _ | S12: 0001- | T12: 011 | U12: .JPG
A13: 12 | B13: BR | C13: - | D13: SP | E13: GPDVE | F13: _ | G13: ARCOENGE | H13: - | I13: DEMOLICAO-CSDTCARANDIRU | J13: _ | K13: ICO | L13: - | M13: FOT | N13: - | O13: DGZ | P13: - | Q13: MB0 | R13: _ | S13: 0001- | T13: 012 | U13: .JPG
... A106: 105 | B106: BR | C106: - | D106: SP | E106: GPDVE | F106: _ | G106: ARCOENGE | H106: - | I106: DEMOLICAO-CSDTCARANDIRU | J106: _ | K106: ICO | L106: - | M106: FOT | N106: - | O106: DGZ | P106: - | Q106: MB0 | R106: _ | S106: 0004- | T106: 024 | U106: .JPG
A107: 106 | B107: BR | C107: - | D107: SP | E107: GPDVE | F107: _ | G107: ARCOENGE | H107: - | I107: DEMOLICAO-CSDTCARANDIRU | J107: _ | L107: - | N107: - | P107: - | R107: _ | U107: .JPG
A108: 107 | B108: BR | C108: - | D108: SP | E108: GPDVE | F108: _ | G108: ARCOENGE | H108: - | I108: DEMOLICAO-CSDTCARANDIRU | J108: _ | L108: - | N108: - | P108: - | R108: _ | U108: .JPG
A109: 108 | B109: BR | C109: - | D109: SP | E109: GPDVE | F109: _ | G109: ARCOENGE | H109: - | I109: DEMOLICAO-CSDTCARANDIRU | J109: _ | L109: - | N109: - | P109: - | R109: _ | U109: .JPG
A110: 109 | B110: BR | C110: - | D110: SP | E110: GPDVE | F110: _ | G110: ARCOENGE | H110: - | I110: DEMOLICAO-CSDTCARANDIRU | J110: _ | L110: - | N110: - | P110: - | R110: _ | U110: .JPG
A111: 110 | B111: BR | C111: - | D111: SP | E111: GPDVE | F111: _ | G111: ARCOENGE | H111: - | I111: DEMOLICAO-CSDTCARANDIRU | J111: _ | L111: - | N111: - | P111: - | R111: _ | U111: .JPG
A112: 111 | B112: BR | C112: - | D112: SP | E112: GPDVE | F112: _ | G112: ARCOENGE | H112: - | I112: DEMOLICAO-CSDTCARANDIRU | J112: _ | L112: - | N112: - | P112: - | R112: _ | U112: .JPG
A113: 112 | B113: BR | C113: - | D113: SP | E113: GPDVE | F113: _ | G113: ARCOENGE | H113: - | I113: DEMOLICAO-CSDTCARANDIRU | J113: _ | L113: - | N113: - | P113: - | R113: _ | U113: .JPG
A114: 113 | B114: BR | C114: - | D114: SP | E114: GPDVE | F114: _ | G114: ARCOENGE | H114: - | I114: DEMOLICAO-CSDTCARANDIRU | J114: _ | L114: - | N114: - | P114: - | R114: _ | U114: .JPG
A115: 114 | B115: BR | C115: - | D115: SP | E115: GPDVE | F115: _ | G115: ARCOENGE | H115: - | I115: DEMOLICAO-CSDTCARANDIRU | J115: _ | L115: - | N115: - | P115: - | R115: _ | U115: .JPG
A116: 115 | B116: BR | C116: - | D116: SP | E116: GPDVE | F116: _ | G116: ARCOENGE | H116: - | I116: DEMOLICAO-CSDTCARANDIRU | J116: _ | L116: - | N116: - | P116: - | R116: _ | U116: .JPG
A117: 116 | B117: BR | C117: - | D117: SP | E117: GPDVE | F117: _ | G117: ARCOENGE | H117: - | I117: DEMOLICAO-CSDTCARANDIRU | J117: _ | L117: - | N117: - | P117: - | R117: _ | U117: .JPG
A118: 117 | B118: BR | C118: - | D118: SP | E118: GPDVE | F118: _ | G118: ARCOENGE | H118: - | I118: DEMOLICAO-CSDTCARANDIRU | J118: _ | L118: - | N118: - | P118: - | R118: _ | U118: .JPG
... A365: 364 | B365: BR | C365: - | D365: SP | E365: GPDVE | F365: _ | G365: ARCOENGE | H365: - | I365: DEMOLICAO-CSDTCARANDIRU | J365: _ | L365: - | N365: - | P365: - | R365: _ | U365: .JPG

Sheet 0001
A1: Cód. | B1: Título descritivo (atribuído) | C1: Nível de descrição | D1: Data da fotografia | E1: Tamanho | F1: Suporte | G1: Local | H1: Autor/Responsável | I1: Denominação do catálogo temático (GPDVE ARCOENGE) | J1: Localização | K1: Código de referência | L1: História arquivística | M1: Conteúdo/Assunto | N1: Condições de acesso e reprodução | O1: Palavras-chave | P1: Gênero | Q1: Técnica de registro | R1: Legenda para publicações | S1: Citação ABNT | T1: Notas
A2: =MID(K2, LEN(K2)-6, 3) -> 001 | B2: Corredor de terra ladeado por muro de concreto e pavilhão com roupas estendidas, com silhuetas urbanas ao fundo. | C2: Item | D2: Sem data | E2: Gerado pelo Dataverse | F2: Fotografia digitalizada; colorida; suporte em papel fotográfico | G2: São Paulo, Brasil | H2: Grupo de Pesquisa em Direito e Violência de Estado | I2: Arcoenge - Demolição - Casa de Detenção do Carandiru (Fotografias) | J2: Pasta: 0001 | K2: =TEXTJOIN("", TRUE, Geral!B2:U2) -> BR-SPGPDVE_ARCOENGE-DEMOLICAO-CSDTCARANDIRU_ICO-FOT-DGZ-MB0_0001-001.JPG | L2: A Casa de Detenção de São Paulo, conhecida como Carandiru, foi demolida em etapas. Em 2002, ocorreu a implosão dos pavilhões 6, 8 e 9. Já em 2005, dos pavilhões 2 e 5 pela empresa Arcoenge (contratada pelo governo do estado de São Paulo). A coleção Arcoenge contém subgrupos de fotos, vídeos e texto, totalizando 164 peças documentais. | M2: Corredor longo e estreito de terra. À esquerda, um muro alto e contínuo de concreto. À direita, a fachada de um pavilhão com diversas roupas estendidas para fora das janelas. Na parte central da imagem, ao longe, pessoas caminham pelo espaço térreo. Ao fundo, despontam silhuetas de prédios modernos da cidade. | N2: O acesso aos documentos deste acervo está condicionado ao compromisso de não repassá-los a terceiros, à obrigatoriedade de mencionar que os originais pertencem ao GPDVE (?), e à necessidade de novo Termo de Responsabilidade em caso de reutilização ou uso diverso do inicialmente acordado. O uso está sujeito às restrições previstas na Lei de Arquivos (Lei nº 8.159/1991), na Lei de Direitos Autorais (Lei nº 9.610/1998), nos artigos 138 e 145 do Código Penal, e no artigo 5º, inciso X, da Constituição Federal, especialmente quanto à proteção da honra e imagem de terceiros. A pessoa física ou jurídica responsável assume integral responsabilidade civil e penal por eventuais danos decorrentes do uso das reproduções e informações, eximindo o GPDVE de qualquer responsabilidade. | O2: Sistema prisional; Arquitetura prisional; Casa de Detenção de São Paulo; Carandiru | P2: Fotografia (Iconográfico) | Q2: Digitalização de fotografia colorida (analógica original) | R2: ="Figura n – ["&B2&"]"&CHAR(10)&"Fonte: Arquivo do Estado de São Paulo, "&TEXT(D2,"yyyy")&"." -> Figura n – [Corredor de terra ladeado por muro de concreto e pavilhão com roupas estendidas, com silhuetas urbanas ao fundo.] Fonte: Arquivo do Estado de São Paulo, Sem data. | S2: ="ARQUIVO PÚBLICO DO ESTADO DE SÃO PAULO (Brasil). ["&B2&"]. "&G2&". "&TEXT(D2,"dd")&" "&LOWER(TEXT(D2,"mmm"))&" "&TEXT(D2,"yyyy")&". "&F2&". Disponível em: <link do dataverse>. Acesso em: 28 out. 2025." -> ARQUIVO PÚBLICO DO ESTADO DE SÃO PAULO (Brasil). [Corredor de terra ladeado por muro de concreto e pavilhão com roupas estendidas, com silhuetas urbanas ao fundo.]. São Paulo, Brasil. Sem data sem data Sem data. Fotografia digitalizada; colorida; suporte em papel fotográfico. Disponível em: <link do dataverse>. Acesso em: 28 out. 2025. | T2: Este item pertencia à pasta intitulada "fotos escaneadas".
A3: =MID(K3, LEN(K3)-6, 3) -> 002 | B3: Fachada de edifício retangular de cinco andares com janelas padronizadas e guarda-corpo metálico em primeiro plano. | C3: Item | D3: Sem data | E3: Gerado pelo Dataverse | F3: Fotografia digitalizada; colorida; suporte em papel fotográfico | G3: São Paulo, Brasil | H3: Grupo de Pesquisa em Direito e Violência de Estado | I3: Arcoenge - Demolição - Casa de Detenção do Carandiru (Fotografias) | J3: Pasta: 0001 | K3: =TEXTJOIN("", TRUE, Geral!B3:U3) -> BR-SPGPDVE_ARCOENGE-DEMOLICAO-CSDTCARANDIRU_ICO-FOT-DGZ-MB0_0001-002.JPG | L3: ='0001'!$L$2 -> A Casa de Detenção de São Paulo, conhecida como Carandiru, foi demolida em etapas. Em 2002, ocorreu a implosão dos pavilhões 6, 8 e 9. Já em 2005, dos pavilhões 2 e 5 pela empresa Arcoenge (contratada pelo governo do estado de São Paulo). A coleção Arcoenge contém subgrupos de fotos, vídeos e texto, totalizando 164 peças documentais. | M3: Plano fechado focado na fachada de um grande edifício retangular de concreto, com cinco andares de janelas visíveis, padronizadas e recuadas. Em primeiro plano, um muro com guarda-corpo de metal margeia o que aparenta ser um pátio rebaixado. | N3: ='0001'!$N$2 -> O acesso aos documentos deste acervo está condicionado ao compromisso de não repassá-los a terceiros, à obrigatoriedade de mencionar que os originais pertencem ao GPDVE (?), e à necessidade de novo Termo de Responsabilidade em caso de reutilização ou uso diverso do inicialmente acordado. O uso está sujeito às restrições previstas na Lei de Arquivos (Lei nº 8.159/1991), na Lei de Direitos Autorais (Lei nº 9.610/1998), nos artigos 138 e 145 do Código Penal, e no artigo 5º, inciso X, da Constituição Federal, especialmente quanto à proteção da honra e imagem de terceiros. A pessoa física ou jurídica responsável assume integral responsabilidade civil e penal por eventuais danos decorrentes do uso das reproduções e informações, eximindo o GPDVE de qualquer responsabilidade. | O3: Sistema prisional; Arquitetura prisional; Casa de Detenção de São Paulo; Carandiru | P3: Fotografia (Iconográfico) | Q3: Digitalização de fotografia colorida (analógica original) | R3: ="Figura n – ["&B3&"]"&CHAR(10)&"Fonte: Arquivo do Estado de São Paulo, "&TEXT(D3,"yyyy")&"." -> Figura n – [Fachada de edifício retangular de cinco andares com janelas padronizadas e guarda-corpo metálico em primeiro plano.] Fonte: Arquivo do Estado de São Paulo, Sem data. | S3: ="ARQUIVO PÚBLICO DO ESTADO DE SÃO PAULO (Brasil). ["&B3&"]. "&G3&". "&TEXT(D3,"dd")&" "&LOWER(TEXT(D3,"mmm"))&" "&TEXT(D3,"yyyy")&". "&F3&". Disponível em: <link do dataverse>. Acesso em: 28 out. 2025." -> ARQUIVO PÚBLICO DO ESTADO DE SÃO PAULO (Brasil). [Fachada de edifício retangular de cinco andares com janelas padronizadas e guarda-corpo metálico em primeiro plano.]. São Paulo, Brasil. Sem data sem data Sem data. Fotografia digitalizada; colorida; suporte em papel fotográfico. Disponível em: <link do dataverse>. Acesso em: 28 out. 2025. | T3: Este item pertencia à pasta intitulada "fotos escaneadas".
A4: =MID(K4, LEN(K4)-6, 3) -> 003 | B4: Corredor de concreto com pessoas em trânsito, ladeado por muro alto e pavilhão com roupas penduradas. | C4: Item | D4: Sem data | E4: Gerado pelo Dataverse | F4: Fotografia digitalizada; colorida; suporte em papel fotográfico | G4: São Paulo, Brasil | H4: Grupo de Pesquisa em Direito e Violência de Estado | I4: Arcoenge - Demolição - Casa de Detenção do Carandiru (Fotografias) | J4: Pasta: 0001 | K4: =TEXTJOIN("", TRUE, Geral!B4:U4) -> BR-SPGPDVE_ARCOENGE-DEMOLICAO-CSDTCARANDIRU_ICO-FOT-DGZ-MB0_0001-003.JPG | L4: ='0001'!$L$2 -> A Casa de Detenção de São Paulo, conhecida como Carandiru, foi demolida em etapas. Em 2002, ocorreu a implosão dos pavilhões 6, 8 e 9. Já em 2005, dos pavilhões 2 e 5 pela empresa Arcoenge (contratada pelo governo do estado de São Paulo). A coleção Arcoenge contém subgrupos de fotos, vídeos e texto, totalizando 164 peças documentais. | M4: Ângulo e composição muito semelhantes à foto BR-SPGPDVE_ARCOENGE-DEMOLICAO-CSDTCARANDIRU_ICO-FOT-DGZ-MB0_0001-001.JPG. Vista em perspectiva de um corredor de concreto margeado por um muro alto à esquerda e um pavilhão com roupas penduradas à direita. Pessoas transitam pelo térreo. | N4: ='0001'!$N$2 -> O acesso aos documentos deste acervo está condicionado ao compromisso de não repassá-los a terceiros, à obrigatoriedade de mencionar que os originais pertencem ao GPDVE (?), e à necessidade de novo Termo de Responsabilidade em caso de reutilização ou uso diverso do inicialmente acordado. O uso está sujeito às restrições previstas na Lei de Arquivos (Lei nº 8.159/1991), na Lei de Direitos Autorais (Lei nº 9.610/1998), nos artigos 138 e 145 do Código Penal, e no artigo 5º, inciso X, da Constituição Federal, especialmente quanto à proteção da honra e imagem de terceiros. A pessoa física ou jurídica responsável assume integral responsabilidade civil e penal por eventuais danos decorrentes do uso das reproduções e informações, eximindo o GPDVE de qualquer responsabilidade. | O4: Sistema prisional; Arquitetura prisional; Casa de Detenção de São Paulo; Carandiru | P4: Fotografia (Iconográfico) | Q4: Digitalização de fotografia colorida (analógica original) | R4: ="Figura n – ["&B4&"]"&CHAR(10)&"Fonte: Arquivo do Estado de São Paulo, "&TEXT(D4,"yyyy")&"." -> Figura n – [Corredor de concreto com pessoas em trânsito, ladeado por muro alto e pavilhão com roupas penduradas.] Fonte: Arquivo do Estado de São Paulo, Sem data. | S4: ="ARQUIVO PÚBLICO DO ESTADO DE SÃO PAULO (Brasil). ["&B4&"]. "&G4&". "&TEXT(D4,"dd")&" "&LOWER(TEXT(D4,"mmm"))&" "&TEXT(D4,"yyyy")&". "&F4&". Disponível em: <link do dataverse>. Acesso em: 28 out. 2025." -> ARQUIVO PÚBLICO DO ESTADO DE SÃO PAULO (Brasil). [Corredor de concreto com pessoas em trânsito, ladeado por muro alto e pavilhão com roupas penduradas.]. São Paulo, Brasil. Sem data sem data Sem data. Fotografia digitalizada; colorida; suporte em papel fotográfico. Disponível em: <link do dataverse>. Acesso em: 28 out. 2025. | T4: Este item pertencia à pasta intitulada "fotos escaneadas".
A5: =MID(K5, LEN(K5)-6, 3) -> 004 | B5: Vista superior de telhados de fibrocimento e amplo pavilhão com bloco central elevado. | C5: Item | D5: Sem data | E5: Gerado pelo Dataverse | F5: Fotografia digitalizada; colorida; suporte em papel fotográfico | G5: São Paulo, Brasil | H5: Grupo de Pesquisa em Direito e Violência de Estado | I5: Arcoenge - Demolição - Casa de Detenção do Carandiru (Fotografias) | J5: Pasta: 0001 | K5: =TEXTJOIN("", TRUE, Geral!B5:U5) -> BR-SPGPDVE_ARCOENGE-DEMOLICAO-CSDTCARANDIRU_ICO-FOT-DGZ-MB0_0001-004.JPG | L5: ='0001'!$L$2 -> A Casa de Detenção de São Paulo, conhecida como Carandiru, foi demolida em etapas. Em 2002, ocorreu a implosão dos pavilhões 6, 8 e 9. Já em 2005, dos pavilhões 2 e 5 pela empresa Arcoenge (contratada pelo governo do estado de São Paulo). A coleção Arcoenge contém subgrupos de fotos, vídeos e texto, totalizando 164 peças documentais. | M5: Enquadramento voltado para as partes superiores das estruturas. Telhados de fibrocimento compõem o primeiro plano inferior. Ao fundo, um amplo pavilhão de concreto que possui um bloco central arquitetonicamente mais alto do que suas alas laterais. | N5: ='0001'!$N$2 -> O acesso aos documentos deste acervo está condicionado ao compromisso de não repassá-los a terceiros, à obrigatoriedade de mencionar que os originais pertencem ao GPDVE (?), e à necessidade de novo Termo de Responsabilidade em caso de reutilização ou uso diverso do inicialmente acordado. O uso está sujeito às restrições previstas na Lei de Arquivos (Lei nº 8.159/1991), na Lei de Direitos Autorais (Lei nº 9.610/1998), nos artigos 138 e 145 do Código Penal, e no artigo 5º, inciso X, da Constituição Federal, especialmente quanto à proteção da honra e imagem de terceiros. A pessoa física ou jurídica responsável assume integral responsabilidade civil e penal por eventuais danos decorrentes do uso das reproduções e informações, eximindo o GPDVE de qualquer responsabilidade. | O5: Sistema prisional; Arquitetura prisional; Casa de Detenção de São Paulo; Carandiru | P5: Fotografia (Iconográfico) | Q5: Digitalização de fotografia colorida (analógica original) | R5: ="Figura n – ["&B5&"]"&CHAR(10)&"Fonte: Arquivo do Estado de São Paulo, "&TEXT(D5,"yyyy")&"." -> Figura n – [Vista superior de telhados de fibrocimento e amplo pavilhão com bloco central elevado.] Fonte: Arquivo do Estado de São Paulo, Sem data. | S5: ="ARQUIVO PÚBLICO DO ESTADO DE SÃO PAULO (Brasil). ["&B5&"]. "&G5&". "&TEXT(D5,"dd")&" "&LOWER(TEXT(D5,"mmm"))&" "&TEXT(D5,"yyyy")&". "&F5&". Disponível em: <link do dataverse>. Acesso em: 28 out. 2025." -> ARQUIVO PÚBLICO DO ESTADO DE SÃO PAULO (Brasil). [Vista superior de telhados de fibrocimento e amplo pavilhão com bloco central elevado.]. São Paulo, Brasil. Sem data sem data Sem data. Fotografia digitalizada; colorida; suporte em papel fotográfico. Disponível em: <link do dataverse>. Acesso em: 28 out. 2025. | T5: Este item pertencia à pasta intitulada "fotos escaneadas".
A6: =MID(K6, LEN(K6)-6, 3) -> 005 | B6: Pátio arborizado com reboque azul em primeiro plano, van estacionada e pavilhão ao fundo. | C6: Item | D6: Sem data | E6: Gerado pelo Dataverse | F6: Fotografia digitalizada; colorida; suporte em papel fotográfico | G6: São Paulo, Brasil | H6: Grupo de Pesquisa em Direito e Violência de Estado | I6: Arcoenge - Demolição - Casa de Detenção do Carandiru (Fotografias) | J6: Pasta: 0001 | K6: =TEXTJOIN("", TRUE, Geral!B6:U6) -> BR-SPGPDVE_ARCOENGE-DEMOLICAO-CSDTCARANDIRU_ICO-FOT-DGZ-MB0_0001-005.JPG | L6: ='0001'!$L$2 -> A Casa de Detenção de São Paulo, conhecida como Carandiru, foi demolida em etapas. Em 2002, ocorreu a implosão dos pavilhões 6, 8 e 9. Já em 2005, dos pavilhões 2 e 5 pela empresa Arcoenge (contratada pelo governo do estado de São Paulo). A coleção Arcoenge contém subgrupos de fotos, vídeos e texto, totalizando 164 peças documentais. | M6: Pátio arborizado com composição semelhante à foto BR-SPGPDVE_ARCOENGE-DEMOLICAO-CSDTCARANDIRU_ICO-FOT-DGZ-MB0_0001-010.JPG, contendo a van branca estacionada e as mesmas edificações ao fundo. A imagem se diferencia pela presença de um reboque ou equipamento azul estacionado no pátio em destaque no primeiro plano. | N6: ='0001'!$N$2 -> O acesso aos documentos deste acervo está condicionado ao compromisso de não repassá-los a terceiros, à obrigatoriedade de mencionar que os originais pertencem ao GPDVE (?), e à necessidade de novo Termo de Responsabilidade em caso de reutilização ou uso diverso do inicialmente acordado. O uso está sujeito às restrições previstas na Lei de Arquivos (Lei nº 8.159/1991), na Lei de Direitos Autorais (Lei nº 9.610/1998), nos artigos 138 e 145 do Código Penal, e no artigo 5º, inciso X, da Constituição Federal, especialmente quanto à proteção da honra e imagem de terceiros. A pessoa física ou jurídica responsável assume integral responsabilidade civil e penal por eventuais danos decorrentes do uso das reproduções e informações, eximindo o GPDVE de qualquer responsabilidade. | O6: Sistema prisional; Arquitetura prisional; Casa de Detenção de São Paulo; Carandiru | P6: Fotografia (Iconográfico) | Q6: Digitalização de fotografia colorida (analógica original) | R6: ="Figura n – ["&B6&"]"&CHAR(10)&"Fonte: Arquivo do Estado de São Paulo, "&TEXT(D6,"yyyy")&"." -> Figura n – [Pátio arborizado com reboque azul em primeiro plano, van estacionada e pavilhão ao fundo.] Fonte: Arquivo do Estado de São Paulo, Sem data. | S6: ="ARQUIVO PÚBLICO DO ESTADO DE SÃO PAULO (Brasil). ["&B6&"]. "&G6&". "&TEXT(D6,"dd")&" "&LOWER(TEXT(D6,"mmm"))&" "&TEXT(D6,"yyyy")&". "&F6&". Disponível em: <link do dataverse>. Acesso em: 28 out. 2025." -> ARQUIVO PÚBLICO DO ESTADO DE SÃO PAULO (Brasil). [Pátio arborizado com reboque azul em primeiro plano, van estacionada e pavilhão ao fundo.]. São Paulo, Brasil. Sem data sem data Sem data. Fotografia digitalizada; colorida; suporte em papel fotográfico. Disponível em: <link do dataverse>. Acesso em: 28 out. 2025. | T6: Este item pertencia à pasta intitulada "fotos escaneadas".
A7: =MID(K7, LEN(K7)-6, 3) -> 006 | B7: Área externa com lajes de concreto, varal transversal de cobertores e campo de terra com pessoas distribuídas. | C7: Item | D7: Sem data | E7: Gerado pelo Dataverse | F7: Fotografia digitalizada; colorida; suporte em papel fotográfico | G7: São Paulo, Brasil | H7: Grupo de Pesquisa em Direito e Violência de Estado | I7: Arcoenge - Demolição - Casa de Detenção do Carandiru (Fotografias) | J7: Pasta: 0001 | K7: =TEXTJOIN("", TRUE, Geral!B7:U7) -> BR-SPGPDVE_ARCOENGE-DEMOLICAO-CSDTCARANDIRU_ICO-FOT-DGZ-MB0_0001-006.JPG | L7: ='0001'!$L$2 -> A Casa de Detenção de São Paulo, conhecida como Carandiru, foi demolida em etapas. Em 2002, ocorreu a implosão dos pavilhões 6, 8 e 9. Já em 2005, dos pavilhões 2 e 5 pela empresa Arcoenge (contratada pelo governo do estado de São Paulo). A coleção Arcoenge contém subgrupos de fotos, vídeos e texto, totalizando 164 peças documentais. | M7: Ampla área externa. Em primeiro plano, lajes de concreto no chão com recortes quadrados e circulares. Uma separação visual é formada por cobertores e tecidos escuros pendurados transversalmente. Atrás dessa barreira, há um grande campo de terra onde diversas pessoas estão distribuídas. A lateral de um pavilhão preenche o canto superior direito. | N7: ='0001'!$N$2 -> O acesso aos documentos deste acervo está condicionado ao compromisso de não repassá-los a terceiros, à obrigatoriedade de mencionar que os originais pertencem ao GPDVE (?), e à necessidade de novo Termo de Responsabilidade em caso de reutilização ou uso diverso do inicialmente acordado. O uso está sujeito às restrições previstas na Lei de Arquivos (Lei nº 8.159/1991), na Lei de Direitos Autorais (Lei nº 9.610/1998), nos artigos 138 e 145 do Código Penal, e no artigo 5º, inciso X, da Constituição Federal, especialmente quanto à proteção da honra e imagem de terceiros. A pessoa física ou jurídica responsável assume integral responsabilidade civil e penal por eventuais danos decorrentes do uso das reproduções e informações, eximindo o GPDVE de qualquer responsabilidade. | O7: Sistema prisional; Arquitetura prisional; Casa de Detenção de São Paulo; Carandiru | P7: Fotografia (Iconográfico) | Q7: Digitalização de fotografia colorida (analógica original) | R7: ="Figura n – ["&B7&"]"&CHAR(10)&"Fonte: Arquivo do Estado de São Paulo, "&TEXT(D7,"yyyy")&"." -> Figura n – [Área externa com lajes de concreto, varal transversal de cobertores e campo de terra com pessoas distribuídas.] Fonte: Arquivo do Estado de São Paulo, Sem data. | S7: ="ARQUIVO PÚBLICO DO ESTADO DE SÃO PAULO (Brasil). ["&B7&"]. "&G7&". "&TEXT(D7,"dd")&" "&LOWER(TEXT(D7,"mmm"))&" "&TEXT(D7,"yyyy")&". "&F7&". Disponível em: <link do dataverse>. Acesso em: 28 out. 2025." -> ARQUIVO PÚBLICO DO ESTADO DE SÃO PAULO (Brasil). [Área externa com lajes de concreto, varal transversal de cobertores e campo de terra com pessoas distribuídas.]. São Paulo, Brasil. Sem data sem data Sem data. Fotografia digitalizada; colorida; suporte em papel fotográfico. Disponível em: <link do dataverse>. Acesso em: 28 out. 2025. | T7: Este item pertencia à pasta intitulada "fotos escaneadas".
A8: =MID(K8, LEN(K8)-6, 3) -> 007 | B8: Pessoa encostada em parapeito diante de amplo pátio de terra e pavilhão retangular ao fundo. | C8: Item | D8: Sem data | E8: Gerado pelo Dataverse | F8: Fotografia digitalizada; colorida; suporte em papel fotográfico | G8: São Paulo, Brasil | H8: Grupo de Pesquisa em Direito e Violência de Estado | I8: Arcoenge - Demolição - Casa de Detenção do Carandiru (Fotografias) | J8: Pasta: 0001 | K8: =TEXTJOIN("", TRUE, Geral!B8:U8) -> BR-SPGPDVE_ARCOENGE-DEMOLICAO-CSDTCARANDIRU_ICO-FOT-DGZ-MB0_0001-007.JPG | L8: ='0001'!$L$2 -> A Casa de Detenção de São Paulo, conhecida como Carandiru, foi demolida em etapas. Em 2002, ocorreu a implosão dos pavilhões 6, 8 e 9. Já em 2005, dos pavilhões 2 e 5 pela empresa Arcoenge (contratada pelo governo do estado de São Paulo). A coleção Arcoenge contém subgrupos de fotos, vídeos e texto, totalizando 164 peças documentais. | M8: Fotografia horizontal. Em primeiro plano, à direita, parte do braço e tronco de uma pessoa de camisa clara encostada em um parapeito. Ao centro, um amplo pátio liso de terra. Ao fundo, um pavilhão retangular de concreto com fileiras regulares de janelas pequenas. | N8: ='0001'!$N$2 -> O acesso aos documentos deste acervo está condicionado ao compromisso de não repassá-los a terceiros, à obrigatoriedade de mencionar que os originais pertencem ao GPDVE (?), e à necessidade de novo Termo de Responsabilidade em caso de reutilização ou uso diverso do inicialmente acordado. O uso está sujeito às restrições previstas na Lei de Arquivos (Lei nº 8.159/1991), na Lei de Direitos Autorais (Lei nº 9.610/1998), nos artigos 138 e 145 do Código Penal, e no artigo 5º, inciso X, da Constituição Federal, especialmente quanto à proteção da honra e imagem de terceiros. A pessoa física ou jurídica responsável assume integral responsabilidade civil e penal por eventuais danos decorrentes do uso das reproduções e informações, eximindo o GPDVE de qualquer responsabilidade. | O8: Sistema prisional; Arquitetura prisional; Casa de Detenção de São Paulo; Carandiru | P8: Fotografia (Iconográfico) | Q8: Digitalização de fotografia colorida (analógica original) | R8: ="Figura n – ["&B8&"]"&CHAR(10)&"Fonte: Arquivo do Estado de São Paulo, "&TEXT(D8,"yyyy")&"." -> Figura n – [Pessoa encostada em parapeito diante de amplo pátio de terra e pavilhão retangular ao fundo.] Fonte: Arquivo do Estado de São Paulo, Sem data. | S8: ="ARQUIVO PÚBLICO DO ESTADO DE SÃO PAULO (Brasil). ["&B8&"]. "&G8&". "&TEXT(D8,"dd")&" "&LOWER(TEXT(D8,"mmm"))&" "&TEXT(D8,"yyyy")&". "&F8&". Disponível em: <link do dataverse>. Acesso em: 28 out. 2025." -> ARQUIVO PÚBLICO DO ESTADO DE SÃO PAULO (Brasil). [Pessoa encostada em parapeito diante de amplo pátio de terra e pavilhão retangular ao fundo.]. São Paulo, Brasil. Sem data sem data Sem data. Fotografia digitalizada; colorida; suporte em papel fotográfico. Disponível em: <link do dataverse>. Acesso em: 28 out. 2025. | T8: Este item pertencia à pasta intitulada "fotos escaneadas".
A9: =MID(K9, LEN(K9)-6, 3) -> 008 | B9: Pátio de terra dividido por muro baixo, com trave de futebol ao centro e ladeado por dois pavilhões. | C9: Item | D9: Sem data | E9: Gerado pelo Dataverse | F9: Fotografia digitalizada; colorida; suporte em papel fotográfico | G9: São Paulo, Brasil | H9: Grupo de Pesquisa em Direito e Violência de Estado | I9: Arcoenge - Demolição - Casa de Detenção do Carandiru (Fotografias) | J9: Pasta: 0001 | K9: =TEXTJOIN("", TRUE, Geral!B9:U9) -> BR-SPGPDVE_ARCOENGE-DEMOLICAO-CSDTCARANDIRU_ICO-FOT-DGZ-MB0_0001-008.JPG | L9: ='0001'!$L$2 -> A Casa de Detenção de São Paulo, conhecida como Carandiru, foi demolida em etapas. Em 2002, ocorreu a implosão dos pavilhões 6, 8 e 9. Já em 2005, dos pavilhões 2 e 5 pela empresa Arcoenge (contratada pelo governo do estado de São Paulo). A coleção Arcoenge contém subgrupos de fotos, vídeos e texto, totalizando 164 peças documentais. | M9: Pátio de terra contendo uma trave de futebol metálica no centro. O espaço é ladeado por dois grandes pavilhões de concreto. Há roupas penduradas em várias janelas do prédio à esquerda. Um muro baixo divide horizontalmente o terreno. | N9: ='0001'!$N$2 -> O acesso aos documentos deste acervo está condicionado ao compromisso de não repassá-los a terceiros, à obrigatoriedade de mencionar que os originais pertencem ao GPDVE (?), e à necessidade de novo Termo de Responsabilidade em caso de reutilização ou uso diverso do inicialmente acordado. O uso está sujeito às restrições previstas na Lei de Arquivos (Lei nº 8.159/1991), na Lei de Direitos Autorais (Lei nº 9.610/1998), nos artigos 138 e 145 do Código Penal, e no artigo 5º, inciso X, da Constituição Federal, especialmente quanto à proteção da honra e imagem de terceiros. A pessoa física ou jurídica responsável assume integral responsabilidade civil e penal por eventuais danos decorrentes do uso das reproduções e informações, eximindo o GPDVE de qualquer responsabilidade. | O9: Sistema prisional; Arquitetura prisional; Casa de Detenção de São Paulo; Carandiru | P9: Fotografia (Iconográfico) | Q9: Digitalização de fotografia colorida (analógica original) | R9: ="Figura n – ["&B9&"]"&CHAR(10)&"Fonte: Arquivo do Estado de São Paulo, "&TEXT(D9,"yyyy")&"." -> Figura n – [Pátio de terra dividido por muro baixo, com trave de futebol ao centro e ladeado por dois pavilhões.] Fonte: Arquivo do Estado de São Paulo, Sem data. | S9: ="ARQUIVO PÚBLICO DO ESTADO DE SÃO PAULO (Brasil). ["&B9&"]. "&G9&". "&TEXT(D9,"dd")&" "&LOWER(TEXT(D9,"mmm"))&" "&TEXT(D9,"yyyy")&". "&F9&". Disponível em: <link do dataverse>. Acesso em: 28 out. 2025." -> ARQUIVO PÚBLICO DO ESTADO DE SÃO PAULO (Brasil). [Pátio de terra dividido por muro baixo, com trave de futebol ao centro e ladeado por dois pavilhões.]. São Paulo, Brasil. Sem data sem data Sem data. Fotografia digitalizada; colorida; suporte em papel fotográfico. Disponível em: <link do dataverse>. Acesso em: 28 out. 2025. | T9: Este item pertencia à pasta intitulada "fotos escaneadas".
A10: =MID(K10, LEN(K10)-6, 3) -> 009 | B10: Vista de passarela elevada com pessoa caminhando de costas, pátio com portão verde e torre de vigilância ao fundo. | C10: Item | D10: Sem data | E10: Gerado pelo Dataverse | F10: Fotografia digitalizada; colorida; suporte em papel fotográfico | G10: São Paulo, Brasil | H10: Grupo de Pesquisa em Direito e Violência de Estado | I10: Arcoenge - Demolição - Casa de Detenção do Carandiru (Fotografias) | J10: Pasta: 0001 | K10: =TEXTJOIN("", TRUE, Geral!B10:U10) -> BR-SPGPDVE_ARCOENGE-DEMOLICAO-CSDTCARANDIRU_ICO-FOT-DGZ-MB0_0001-009.JPG | L10: ='0001'!$L$2 -> A Casa de Detenção de São Paulo, conhecida como Carandiru, foi demolida em etapas. Em 2002, ocorreu a implosão dos pavilhões 6, 8 e 9. Já em 2005, dos pavilhões 2 e 5 pela empresa Arcoenge (contratada pelo governo do estado de São Paulo). A coleção Arcoenge contém subgrupos de fotos, vídeos e texto, totalizando 164 peças documentais. | M10: Vista a partir de uma passarela elevada de concreto. Uma pessoa vestindo camisa clara e calça caminha de costas pela passarela. Abaixo, vê-se um pátio com uma pequena estrutura e um portão verde. Ao fundo, um longo pavilhão e uma torre de vigilância. | N10: ='0001'!$N$2 -> O acesso aos documentos deste acervo está condicionado ao compromisso de não repassá-los a terceiros, à obrigatoriedade de mencionar que os originais pertencem ao GPDVE (?), e à necessidade de novo Termo de Responsabilidade em caso de reutilização ou uso diverso do inicialmente acordado. O uso está sujeito às restrições previstas na Lei de Arquivos (Lei nº 8.159/1991), na Lei de Direitos Autorais (Lei nº 9.610/1998), nos artigos 138 e 145 do Código Penal, e no artigo 5º, inciso X, da Constituição Federal, especialmente quanto à proteção da honra e imagem de terceiros. A pessoa física ou jurídica responsável assume integral responsabilidade civil e penal por eventuais danos decorrentes do uso das reproduções e informações, eximindo o GPDVE de qualquer responsabilidade. | O10: Sistema prisional; Arquitetura prisional; Casa de Detenção de São Paulo; Carandiru | P10: Fotografia (Iconográfico) | Q10: Digitalização de fotografia colorida (analógica original) | R10: ="Figura n – ["&B10&"]"&CHAR(10)&"Fonte: Arquivo do Estado de São Paulo, "&TEXT(D10,"yyyy")&"." -> Figura n – [Vista de passarela elevada com pessoa caminhando de costas, pátio com portão verde e torre de vigilância ao fundo.] Fonte: Arquivo do Estado de São Paulo, Sem data. | S10: ="ARQUIVO PÚBLICO DO ESTADO DE SÃO PAULO (Brasil). ["&B10&"]. "&G10&". "&TEXT(D10,"dd")&" "&LOWER(TEXT(D10,"mmm"))&" "&TEXT(D10,"yyyy")&". "&F10&". Disponível em: <link do dataverse>. Acesso em: 28 out. 2025." -> ARQUIVO PÚBLICO DO ESTADO DE SÃO PAULO (Brasil). [Vista de passarela elevada com pessoa caminhando de costas, pátio com portão verde e torre de vigilância ao fundo.]. São Paulo, Brasil. Sem data sem data Sem data. Fotografia digitalizada; colorida; suporte em papel fotográfico. Disponível em: <link do dataverse>. Acesso em: 28 out. 2025. | T10: Este item pertencia à pasta intitulada "fotos escaneadas".
A11: =MID(K11, LEN(K11)-6, 3) -> 010 | B11: Pátio interno arborizado com van branca estacionada diante de construção térrea e grande pavilhão ao fundo. | C11: Item | D11: Sem data | E11: Gerado pelo Dataverse | F11: Fotografia digitalizada; colorida; suporte em papel fotográfico | G11: São Paulo, Brasil | H11: Grupo de Pesquisa em Direito e Violência de Estado | I11: Arcoenge - Demolição - Casa de Detenção do Carandiru (Fotografias) | J11: Pasta: 0001 | K11: =TEXTJOIN("", TRUE, Geral!B11:U11) -> BR-SPGPDVE_ARCOENGE-DEMOLICAO-CSDTCARANDIRU_ICO-FOT-DGZ-MB0_0001-010.JPG | L11: ='0001'!$L$2 -> A Casa de Detenção de São Paulo, conhecida como Carandiru, foi demolida em etapas. Em 2002, ocorreu a implosão dos pavilhões 6, 8 e 9. Já em 2005, dos pavilhões 2 e 5 pela empresa Arcoenge (contratada pelo governo do estado de São Paulo). A coleção Arcoenge contém subgrupos de fotos, vídeos e texto, totalizando 164 peças documentais. | M11: Pátio interno. À esquerda, copas de árvores. Ao centro, uma van branca estacionada em frente a uma construção térrea clara (que exibe um mural ou pintura na parede direita). Atrás dessa construção térrea, ergue-se um grande pavilhão de concreto. No limite inferior da foto, nota-se a borda de um telhado de fibrocimento. | N11: ='0001'!$N$2 -> O acesso aos documentos deste acervo está condicionado ao compromisso de não repassá-los a terceiros, à obrigatoriedade de mencionar que os originais pertencem ao GPDVE (?), e à necessidade de novo Termo de Responsabilidade em caso de reutilização ou uso diverso do inicialmente acordado. O uso está sujeito às restrições previstas na Lei de Arquivos (Lei nº 8.159/1991), na Lei de Direitos Autorais (Lei nº 9.610/1998), nos artigos 138 e 145 do Código Penal, e no artigo 5º, inciso X, da Constituição Federal, especialmente quanto à proteção da honra e imagem de terceiros. A pessoa física ou jurídica responsável assume integral responsabilidade civil e penal por eventuais danos decorrentes do uso das reproduções e informações, eximindo o GPDVE de qualquer responsabilidade. | O11: Sistema prisional; Arquitetura prisional; Casa de Detenção de São Paulo; Carandiru | P11: Fotografia (Iconográfico) | Q11: Digitalização de fotografia colorida (analógica original) | R11: ="Figura n – ["&B11&"]"&CHAR(10)&"Fonte: Arquivo do Estado de São Paulo, "&TEXT(D11,"yyyy")&"." -> Figura n – [Pátio interno arborizado com van branca estacionada diante de construção térrea e grande pavilhão ao fundo.] Fonte: Arquivo do Estado de São Paulo, Sem data. | S11: ="ARQUIVO PÚBLICO DO ESTADO DE SÃO PAULO (Brasil). ["&B11&"]. "&G11&". "&TEXT(D11,"dd")&" "&LOWER(TEXT(D11,"mmm"))&" "&TEXT(D11,"yyyy")&". "&F11&". Disponível em: <link do dataverse>. Acesso em: 28 out. 2025." -> ARQUIVO PÚBLICO DO ESTADO DE SÃO PAULO (Brasil). [Pátio interno arborizado com van branca estacionada diante de construção térrea e grande pavilhão ao fundo.]. São Paulo, Brasil. Sem data sem data Sem data. Fotografia digitalizada; colorida; suporte em papel fotográfico. Disponível em: <link do dataverse>. Acesso em: 28 out. 2025. | T11: Este item pertencia à pasta intitulada "fotos escaneadas".
A12: =MID(K12, LEN(K12)-6, 3) -> 011 | B12: Pátio externo subdividido por alambrado, com quadra de terra, aglomeração de pessoas e dois pavilhões ao fundo. | C12: Item | D12: Sem data | E12: Gerado pelo Dataverse | F12: Fotografia digitalizada; colorida; suporte em papel fotográfico | G12: São Paulo, Brasil | H12: Grupo de Pesquisa em Direito e Violência de Estado | I12: Arcoenge - Demolição - Casa de Detenção do Carandiru (Fotografias) | J12: Pasta: 0001 | K12: =TEXTJOIN("", TRUE, Geral!B12:U12) -> BR-SPGPDVE_ARCOENGE-DEMOLICAO-CSDTCARANDIRU_ICO-FOT-DGZ-MB0_0001-011.JPG | L12: ='0001'!$L$2 -> A Casa de Detenção de São Paulo, conhecida como Carandiru, foi demolida em etapas. Em 2002, ocorreu a implosão dos pavilhões 6, 8 e 9. Já em 2005, dos pavilhões 2 e 5 pela empresa Arcoenge (contratada pelo governo do estado de São Paulo). A coleção Arcoenge contém subgrupos de fotos, vídeos e texto, totalizando 164 peças documentais. | M12: Amplo pátio externo subdividido. Em primeiro plano, à esquerda, uma quadra de terra demarcada por linhas brancas e cercada por alambrado. Atrás do alambrado, uma extensa área de terra abriga dezenas de pessoas espalhadas em meio a pequenas estruturas improvisadas e varais com roupas. Ao fundo, um longo muro escuro divide o terreno, atrás do qual se erguem dois grandes edifícios de concreto (pavilhões) com diversas janelas retangulares. Um alto poste de iluminação ergue-se à direita, com uma torre de vigilância visível ao extremo fundo direito. | N12: ='0001'!$N$2 -> O acesso aos documentos deste acervo está condicionado ao compromisso de não repassá-los a terceiros, à obrigatoriedade de mencionar que os originais pertencem ao GPDVE (?), e à necessidade de novo Termo de Responsabilidade em caso de reutilização ou uso diverso do inicialmente acordado. O uso está sujeito às restrições previstas na Lei de Arquivos (Lei nº 8.159/1991), na Lei de Direitos Autorais (Lei nº 9.610/1998), nos artigos 138 e 145 do Código Penal, e no artigo 5º, inciso X, da Constituição Federal, especialmente quanto à proteção da honra e imagem de terceiros. A pessoa física ou jurídica responsável assume integral responsabilidade civil e penal por eventuais danos decorrentes do uso das reproduções e informações, eximindo o GPDVE de qualquer responsabilidade. | O12: Sistema prisional; Arquitetura prisional; Casa de Detenção de São Paulo; Carandiru | P12: Fotografia (Iconográfico) | Q12: Digitalização de fotografia colorida (analógica original) | R12: ="Figura n – ["&B12&"]"&CHAR(10)&"Fonte: Arquivo do Estado de São Paulo, "&TEXT(D12,"yyyy")&"." -> Figura n – [Pátio externo subdividido por alambrado, com quadra de terra, aglomeração de pessoas e dois pavilhões ao fundo.] Fonte: Arquivo do Estado de São Paulo, Sem data. | S12: ="ARQUIVO PÚBLICO DO ESTADO DE SÃO PAULO (Brasil). ["&B12&"]. "&G12&". "&TEXT(D12,"dd")&" "&LOWER(TEXT(D12,"mmm"))&" "&TEXT(D12,"yyyy")&". "&F12&". Disponível em: <link do dataverse>. Acesso em: 28 out. 2025." -> ARQUIVO PÚBLICO DO ESTADO DE SÃO PAULO (Brasil). [Pátio externo subdividido por alambrado, com quadra de terra, aglomeração de pessoas e dois pavilhões ao fundo.]. São Paulo, Brasil. Sem data sem data Sem data. Fotografia digitalizada; colorida; suporte em papel fotográfico. Disponível em: <link do dataverse>. Acesso em: 28 out. 2025. | T12: Este item pertencia à pasta intitulada "fotos escaneadas".
A13: =MID(K13, LEN(K13)-6, 3) -> 012 | B13: . Amplo campo de terra com pessoas distribuídas pelo espaço, ladeado por muro alto e pavilhão ao fundo. | C13: Item | D13: Sem data | E13: Gerado pelo Dataverse | F13: Fotografia digitalizada; colorida; suporte em papel fotográfico | G13: São Paulo, Brasil | H13: Grupo de Pesquisa em Direito e Violência de Estado | I13: Arcoenge - Demolição - Casa de Detenção do Carandiru (Fotografias) | J13: Pasta: 0001 | K13: =TEXTJOIN("", TRUE, Geral!B13:U13) -> BR-SPGPDVE_ARCOENGE-DEMOLICAO-CSDTCARANDIRU_ICO-FOT-DGZ-MB0_0001-012.JPG | L13: ='0001'!$L$2 -> A Casa de Detenção de São Paulo, conhecida como Carandiru, foi demolida em etapas. Em 2002, ocorreu a implosão dos pavilhões 6, 8 e 9. Já em 2005, dos pavilhões 2 e 5 pela empresa Arcoenge (contratada pelo governo do estado de São Paulo). A coleção Arcoenge contém subgrupos de fotos, vídeos e texto, totalizando 164 peças documentais. | M13: Amplo campo de terra liso ocupando quase toda a imagem, com diversas pessoas distribuídas pelo espaço, jogando futebol. No canto inferior esquerdo, vê-se parte da estrutura tubular de uma trave esportiva. O campo é delimitado à esquerda e à direita por altos muros escuros contínuos. Ao centro, no fundo do terreno, ergue-se um grande pavilhão retangular de concreto com cinco andares visíveis de janelas, muitas delas exibindo roupas penduradas. | N13: ='0001'!$N$2 -> O acesso aos documentos deste acervo está condicionado ao compromisso de não repassá-los a terceiros, à obrigatoriedade de mencionar que os originais pertencem ao GPDVE (?), e à necessidade de novo Termo de Responsabilidade em caso de reutilização ou uso diverso do inicialmente acordado. O uso está sujeito às restrições previstas na Lei de Arquivos (Lei nº 8.159/1991), na Lei de Direitos Autorais (Lei nº 9.610/1998), nos artigos 138 e 145 do Código Penal, e no artigo 5º, inciso X, da Constituição Federal, especialmente quanto à proteção da honra e imagem de terceiros. A pessoa física ou jurídica responsável assume integral responsabilidade civil e penal por eventuais danos decorrentes do uso das reproduções e informações, eximindo o GPDVE de qualquer responsabilidade. | O13: Sistema prisional; Arquitetura prisional; Casa de Detenção de São Paulo; Carandiru | P13: Fotografia (Iconográfico) | Q13: Digitalização de fotografia colorida (analógica original) | R13: ="Figura n – ["&B13&"]"&CHAR(10)&"Fonte: Arquivo do Estado de São Paulo, "&TEXT(D13,"yyyy")&"." -> Figura n – [. Amplo campo de terra com pessoas distribuídas pelo espaço, ladeado por muro alto e pavilhão ao fundo.] Fonte: Arquivo do Estado de São Paulo, Sem data. | S13: ="ARQUIVO PÚBLICO DO ESTADO DE SÃO PAULO (Brasil). ["&B13&"]. "&G13&". "&TEXT(D13,"dd")&" "&LOWER(TEXT(D13,"mmm"))&" "&TEXT(D13,"yyyy")&". "&F13&". Disponível em: <link do dataverse>. Acesso em: 28 out. 2025." -> ARQUIVO PÚBLICO DO ESTADO DE SÃO PAULO (Brasil). [. Amplo campo de terra com pessoas distribuídas pelo espaço, ladeado por muro alto e pavilhão ao fundo.]. São Paulo, Brasil. Sem data sem data Sem data. Fotografia digitalizada; colorida; suporte em papel fotográfico. Disponível em: <link do dataverse>. Acesso em: 28 out. 2025. | T13: Este item pertencia à pasta intitulada "fotos escaneadas".
A14: =MID(K14, LEN(K14)-6, 3) -> 013 | B14: Fachada de pavilhão e topo de muro com grade em primeiro plano. | C14: Item | D14: Sem data | E14: Gerado pelo Dataverse | F14: Fotografia digitalizada; colorida; suporte em papel fotográfico | G14: São Paulo, Brasil | H14: Grupo de Pesquisa em Direito e Violência de Estado | I14: Arcoenge - Demolição - Casa de Detenção do Carandiru (Fotografias) | J14: Pasta: 0001 | K14: =TEXTJOIN("", TRUE, Geral!B14:U14) -> BR-SPGPDVE_ARCOENGE-DEMOLICAO-CSDTCARANDIRU_ICO-FOT-DGZ-MB0_0001-013.JPG | L14: ='0001'!$L$2 -> A Casa de Detenção de São Paulo, conhecida como Carandiru, foi demolida em etapas. Em 2002, ocorreu a implosão dos pavilhões 6, 8 e 9. Já em 2005, dos pavilhões 2 e 5 pela empresa Arcoenge (contratada pelo governo do estado de São Paulo). A coleção Arcoenge contém subgrupos de fotos, vídeos e texto, totalizando 164 peças documentais. | M14: Plano fechado focado exclusivamente na fachada de um pavilhão de concreto. Na margem inferior da imagem, cruzando horizontalmente o primeiro plano, nota-se o topo de um muro escuro encimado por uma grade de metal. | N14: ='0001'!$N$2 -> O acesso aos documentos deste acervo está condicionado ao compromisso de não repassá-los a terceiros, à obrigatoriedade de mencionar que os originais pertencem ao GPDVE (?), e à necessidade de novo Termo de Responsabilidade em caso de reutilização ou uso diverso do inicialmente acordado. O uso está sujeito às restrições previstas na Lei de Arquivos (Lei nº 8.159/1991), na Lei de Direitos Autorais (Lei nº 9.610/1998), nos artigos 138 e 145 do Código Penal, e no artigo 5º, inciso X, da Constituição Federal, especialmente quanto à proteção da honra e imagem de terceiros. A pessoa física ou jurídica responsável assume integral responsabilidade civil e penal por eventuais danos decorrentes do uso das reproduções e informações, eximindo o GPDVE de qualquer responsabilidade. | O14: Sistema prisional; Arquitetura prisional; Casa de Detenção de São Paulo; Carandiru | P14: Fotografia (Iconográfico) | Q14: Digitalização de fotografia colorida (analógica original) | R14: ="Figura n – ["&B14&"]"&CHAR(10)&"Fonte: Arquivo do Estado de São Paulo, "&TEXT(D14,"yyyy")&"." -> Figura n – [Fachada de pavilhão e topo de muro com grade em primeiro plano.] Fonte: Arquivo do Estado de São Paulo, Sem data. | S14: ="ARQUIVO PÚBLICO DO ESTADO DE SÃO PAULO (Brasil). ["&B14&"]. "&G14&". "&TEXT(D14,"dd")&" "&LOWER(TEXT(D14,"mmm"))&" "&TEXT(D14,"yyyy")&". "&F14&". Disponível em: <link do dataverse>. Acesso em: 28 out. 2025." -> ARQUIVO PÚBLICO DO ESTADO DE SÃO PAULO (Brasil). [Fachada de pavilhão e topo de muro com grade em primeiro plano.]. São Paulo, Brasil. Sem data sem data Sem data. Fotografia digitalizada; colorida; suporte em papel fotográfico. Disponível em: <link do dataverse>. Acesso em: 28 out. 2025. | T14: Este item pertencia à pasta intitulada "fotos escaneadas".
... A32: =MID(K32, LEN(K32)-6, 3) -> 031 | B32: Vista elevada de campo de terra com trave de futebol e pessoas, ladeado por grande pavilhão e muro longo. | C32: Item | D32: Sem data | E32: Gerado pelo Dataverse | F32: Fotografia digitalizada; colorida; suporte em papel fotográfico | G32: São Paulo, Brasil | H32: Grupo de Pesquisa em Direito e Violência de Estado | I32: Arcoenge - Demolição - Casa de Detenção do Carandiru (Fotografias) | J32: Pasta: 0001 | K32: =TEXTJOIN("", TRUE, Geral!B32:U32) -> BR-SPGPDVE_ARCOENGE-DEMOLICAO-CSDTCARANDIRU_ICO-FOT-DGZ-MB0_0001-031.JPG | L32: ='0001'!$L$2 -> A Casa de Detenção de São Paulo, conhecida como Carandiru, foi demolida em etapas. Em 2002, ocorreu a implosão dos pavilhões 6, 8 e 9. Já em 2005, dos pavilhões 2 e 5 pela empresa Arcoenge (contratada pelo governo do estado de São Paulo). A coleção Arcoenge contém subgrupos de fotos, vídeos e texto, totalizando 164 peças documentais. | M32: Fotografia em vista elevada. No primeiro plano, à esquerda, desponta o topo texturizado de um muro de concreto espesso que cruza o canto em diagonal. O centro da imagem é tomado por um amplo pátio de terra batida onde dezenas de pessoas estão distribuídas. Algumas agrupam-se e interagem próximas a uma trave metálica de futebol instalada no meio do campo, enquanto outras caminham ou descansam nas margens. À direita, domina a cena a extensa fachada de um grande pavilhão de concreto com cinco andares de janelas retangulares recuadas, muitas exibindo roupas estendidas. Ao fundo, do lado esquerdo, um longo muro escuro separa o pátio de outras construções com telhados alongados côncavos. | N32: ='0001'!$N$2 -> O acesso aos documentos deste acervo está condicionado ao compromisso de não repassá-los a terceiros, à obrigatoriedade de mencionar que os originais pertencem ao GPDVE (?), e à necessidade de novo Termo de Responsabilidade em caso de reutilização ou uso diverso do inicialmente acordado. O uso está sujeito às restrições previstas na Lei de Arquivos (Lei nº 8.159/1991), na Lei de Direitos Autorais (Lei nº 9.610/1998), nos artigos 138 e 145 do Código Penal, e no artigo 5º, inciso X, da Constituição Federal, especialmente quanto à proteção da honra e imagem de terceiros. A pessoa física ou jurídica responsável assume integral responsabilidade civil e penal por eventuais danos decorrentes do uso das reproduções e informações, eximindo o GPDVE de qualquer responsabilidade. | O32: Sistema prisional; Arquitetura prisional; Casa de Detenção de São Paulo; Carandiru | P32: Fotografia (Iconográfico) | Q32: Digitalização de fotografia colorida (analógica original) | R32: ="Figura n – ["&B32&"]"&CHAR(10)&"Fonte: Arquivo do Estado de São Paulo, "&TEXT(D32,"yyyy")&"." -> Figura n – [Vista elevada de campo de terra com trave de futebol e pessoas, ladeado por grande pavilhão e muro longo.] Fonte: Arquivo do Estado de São Paulo, Sem data. | S32: ="ARQUIVO PÚBLICO DO ESTADO DE SÃO PAULO (Brasil). ["&B32&"]. "&G32&". "&TEXT(D32,"dd")&" "&LOWER(TEXT(D32,"mmm"))&" "&TEXT(D32,"yyyy")&". "&F32&". Disponível em: <link do dataverse>. Acesso em: 28 out. 2025." -> ARQUIVO PÚBLICO DO ESTADO DE SÃO PAULO (Brasil). [Vista elevada de campo de terra com trave de futebol e pessoas, ladeado por grande pavilhão e muro longo.]. São Paulo, Brasil. Sem data sem data Sem data. Fotografia digitalizada; colorida; suporte em papel fotográfico. Disponível em: <link do dataverse>. Acesso em: 28 out. 2025. | T32: Este item pertencia à pasta intitulada "fotos escaneadas".

Sheet 0002
A1: Cód. | B1: Título descritivo (atribuído) | C1: Nível de descrição | D1: Data de criação da fotografia | E1: Tamanho | F1: Suporte | G1: Local | H1: Autor/Responsável | I1: Denominação do catálogo temático (GPDVE ARCOENGE) | J1: Localização | K1: Código de referência | L1: História arquivística | M1: Conteúdo/Assunto | N1: Condições de acesso e reprodução | O1: Palavras-chave | P1: Gênero | Q1: Técnica de registro | R1: Legenda para publicações | S1: Citação ABNT | T1: Notas
A2: =MID(K2, LEN(K2)-6, 3) -> 001 | B2: Vista geral da torre de água e bairro residencial ao fundo. | C2: Item | D2: 37690 | E2: Gerado pelo Dataverse | F2: Fotografia digitalizada; colorida; suporte em papel fotográfico | G2: São Paulo, Brasil | H2: Grupo de Pesquisa em Direito e Violência de Estado | I2: Arcoenge - Demolição - Casa de Detenção do Carandiru (Fotografias) | J2: Pasta: 0002 | K2: =TEXTJOIN("", TRUE, Geral!B33:U33) -> BR-SPGPDVE_ARCOENGE-DEMOLICAO-CSDTCARANDIRU_ICO-FOT-DGZ-MB0_0002-001.JPG | L2: ='0001'!$L$2 -> A Casa de Detenção de São Paulo, conhecida como Carandiru, foi demolida em etapas. Em 2002, ocorreu a implosão dos pavilhões 6, 8 e 9. Já em 2005, dos pavilhões 2 e 5 pela empresa Arcoenge (contratada pelo governo do estado de São Paulo). A coleção Arcoenge contém subgrupos de fotos, vídeos e texto, totalizando 164 peças documentais. | M2: Fotografia de uma ampla área de terreno em terra batida, com marcas de escavação e entulho em primeiro plano. À esquerda, destaca-se uma alta torre de água cilíndrica de concreto com escada externa. Próximo à base da torre, observam-se equipamentos e trabalhadores da construção civil utilizando capacetes de segurança. Ao fundo, vê-se o perfil de construções de um bairro residencial sob um céu parcialmente nublado. A imagem possui um Marcador numérico "3 3 '03" no canto inferior direito. | N2: ='0001'!$N$2 -> O acesso aos documentos deste acervo está condicionado ao compromisso de não repassá-los a terceiros, à obrigatoriedade de mencionar que os originais pertencem ao GPDVE (?), e à necessidade de novo Termo de Responsabilidade em caso de reutilização ou uso diverso do inicialmente acordado. O uso está sujeito às restrições previstas na Lei de Arquivos (Lei nº 8.159/1991), na Lei de Direitos Autorais (Lei nº 9.610/1998), nos artigos 138 e 145 do Código Penal, e no artigo 5º, inciso X, da Constituição Federal, especialmente quanto à proteção da honra e imagem de terceiros. A pessoa física ou jurídica responsável assume integral responsabilidade civil e penal por eventuais danos decorrentes do uso das reproduções e informações, eximindo o GPDVE de qualquer responsabilidade. | O2: Sistema prisional; Arquitetura prisional; Casa de Detenção de São Paulo; Carandiru | P2: Fotografia (Iconográfico) | Q2: Digitalização de fotografia colorida (analógica original) | R2: ="Figura n – ["&B2&"]"&CHAR(10)&"Fonte: Arquivo do Estado de São Paulo, "&TEXT(D2,"yyyy")&"." -> Figura n – [Vista geral da torre de água e bairro residencial ao fundo.] Fonte: Arquivo do Estado de São Paulo, 2003. | S2: ="ARQUIVO PÚBLICO DO ESTADO DE SÃO PAULO (Brasil). ["&B2&"]. "&G2&". "&TEXT(D2,"dd")&" "&LOWER(TEXT(D2,"mmm"))&" "&TEXT(D2,"yyyy")&". "&F2&". Disponível em: <link do dataverse>. Acesso em: 28 out. 2025." -> ARQUIVO PÚBLICO DO ESTADO DE SÃO PAULO (Brasil). [Vista geral da torre de água e bairro residencial ao fundo.]. São Paulo, Brasil. 10 mar. 2003. Fotografia digitalizada; colorida; suporte em papel fotográfico. Disponível em: <link do dataverse>. Acesso em: 28 out. 2025. | T2: Este item pertencia à pasta intitulada "caixa-d'água 1". Com relação à data de produção da fotografia, embora a lateral das fotografias indiquem 03/03/03, optou-se por utilizar a data mais antiga contida nos metadados do arquivo digital.
A3: =MID(K3, LEN(K3)-6, 3) -> 002 | B3: Torre de água de concreto e trabalhadores. | C3: Item | D3: 37690 | E3: Gerado pelo Dataverse | F3: Fotografia digitalizada; colorida; suporte em papel fotográfico | G3: São Paulo, Brasil | H3: Grupo de Pesquisa em Direito e Violência de Estado | I3: Arcoenge - Demolição - Casa de Detenção do Carandiru (Fotografias) | J3: Pasta: 0002 | K3: =TEXTJOIN("", TRUE, Geral!B34:U34) -> BR-SPGPDVE_ARCOENGE-DEMOLICAO-CSDTCARANDIRU_ICO-FOT-DGZ-MB0_0002-002.JPG | L3: ='0001'!$L$2 -> A Casa de Detenção de São Paulo, conhecida como Carandiru, foi demolida em etapas. Em 2002, ocorreu a implosão dos pavilhões 6, 8 e 9. Já em 2005, dos pavilhões 2 e 5 pela empresa Arcoenge (contratada pelo governo do estado de São Paulo). A coleção Arcoenge contém subgrupos de fotos, vídeos e texto, totalizando 164 peças documentais. | M3: Imagem com enquadramento focado na alta torre de água de concreto, posicionada à direita, com tubulações e escada metálica visíveis. À esquerda, uma árvore de grande porte compõe o primeiro plano. No solo de terra revirada, identificam-se trabalhadores da construção civil caminhando. Ao fundo, observam-se as fachadas traseiras e telhados de edificações baixas, além de torres de transmissão elétrica no horizonte. Marcador numérico "3 3 '03" no canto inferior direito. | N3: ='0001'!$N$2 -> O acesso aos documentos deste acervo está condicionado ao compromisso de não repassá-los a terceiros, à obrigatoriedade de mencionar que os originais pertencem ao GPDVE (?), e à necessidade de novo Termo de Responsabilidade em caso de reutilização ou uso diverso do inicialmente acordado. O uso está sujeito às restrições previstas na Lei de Arquivos (Lei nº 8.159/1991), na Lei de Direitos Autorais (Lei nº 9.610/1998), nos artigos 138 e 145 do Código Penal, e no artigo 5º, inciso X, da Constituição Federal, especialmente quanto à proteção da honra e imagem de terceiros. A pessoa física ou jurídica responsável assume integral responsabilidade civil e penal por eventuais danos decorrentes do uso das reproduções e informações, eximindo o GPDVE de qualquer responsabilidade. | O3: Sistema prisional; Arquitetura prisional; Casa de Detenção de São Paulo; Carandiru | P3: Fotografia (Iconográfico) | Q3: Digitalização de fotografia colorida (analógica original) | R3: ="Figura n – ["&B3&"]"&CHAR(10)&"Fonte: Arquivo do Estado de São Paulo, "&TEXT(D3,"yyyy")&"." -> Figura n – [Torre de água de concreto e trabalhadores.] Fonte: Arquivo do Estado de São Paulo, 2003. | S3: ="ARQUIVO PÚBLICO DO ESTADO DE SÃO PAULO (Brasil). ["&B3&"]. "&G3&". "&TEXT(D3,"dd")&" "&LOWER(TEXT(D3,"mmm"))&" "&TEXT(D3,"yyyy")&". "&F3&". Disponível em: <link do dataverse>. Acesso em: 28 out. 2025." -> ARQUIVO PÚBLICO DO ESTADO DE SÃO PAULO (Brasil). [Torre de água de concreto e trabalhadores.]. São Paulo, Brasil. 10 mar. 2003. Fotografia digitalizada; colorida; suporte em papel fotográfico. Disponível em: <link do dataverse>. Acesso em: 28 out. 2025. | T3: =$T$2 -> Este item pertencia à pasta intitulada "caixa-d'água 1". Com relação à data de produção da fotografia, embora a lateral das fotografias indiquem 03/03/03, optou-se por utilizar a data mais antiga contida nos metadados do arquivo digital.
