Workbook

Sheet Geral
B1: Local (país) | D1: Local (estado) | E1: Designação do repositório | G1: Designação do conjunto documental | I1: Designação do subconjunto documental | K1: Gênero documental | M1: Espécie/Tipo documental | O1: Técnica de registro | Q1: Forma documental | S1: Unidade de descrição
A2: 1 | B2: BR | C2: - | D2: SP | E2: GPDVE | F2: _ | G2: NOTICIAS | H2: - | I2: MASSACRE-CSDTCARANDIRU | J2: _ | K2: AVS | L2: - | M2: NOT | N2: - | O2: NDT | P2: - | Q2: DT1 | R2: _ | S2: 0001- | T2: 001 | V2: .mp4
A3: 2 | B3: BR | C3: - | D3: SP | E3: GPDVE | F3: _ | G3: NOTICIAS | H3: - | I3: MASSACRE-CSDTCARANDIRU | J3: _ | K3: AVS | L3: - | M3: NOT | N3: - | O3: NDT | P3: - | Q3: DT1 | R3: _ | S3: 0001- | T3: 002 | V3: .mp4
A4: 3 | B4: BR | C4: - | D4: SP | E4: GPDVE | F4: _ | G4: NOTICIAS | H4: - | I4: DEMOLICAO-CSDTCARANDIRU | J4: _ | K4: AVS | L4: - | M4: NOT | N4: - | O4: NDT | P4: - | Q4: DT1 | R4: _ | S4: 0001- | T4: 001 | V4: .mp4
A5: 4 | B5: BR | C5: - | D5: SP | E5: GPDVE | F5: _ | G5: NOTICIAS | H5: - | I5: DEMOLICAO-CSDTCARANDIRU | J5: _ | K5: AVS | L5: - | M5: NOT | N5: - | O5: NDT | P5: - | Q5: DT1 | R5: _ | S5: 0001- | T5: 002 | V5: .mp4
A6: 5 | B6: BR | C6: - | D6: SP | E6: GPDVE | F6: _ | G6: NOTICIAS | H6: - | I6: DEMOLICAO-CSDTCARANDIRU | J6: _ | K6: AVS | L6: - | M6: NOT | N6: - | O6: NDT | P6: - | Q6: DT1 | R6: _ | S6: 0001- | T6: 003 | V6: .mp4
A7: 6 | B7: BR | C7: - | D7: SP | E7: GPDVE | F7: _ | G7: NOTICIAS | H7: - | I7: DEMOLICAO-CSDTCARANDIRU | J7: _ | K7: AVS | L7: - | M7: NOT | N7: - | O7: NDT | P7: - | Q7: DT1 | R7: _ | S7: 0001- | T7: 004 | V7: .mp4
A8: 7 | B8: BR | C8: - | D8: SP | E8: GPDVE | F8: _ | G8: NOTICIAS | H8: - | I8: DEMOLICAO-CSDTCARANDIRU | J8: _ | K8: AVS | L8: - | M8: NOT | N8: - | O8: NDT | P8: - | Q8: DT1 | R8: _ | S8: 0001- | T8: 005 | V8: .mp4
A9: 8 | B9: BR | C9: - | D9: SP | E9: GPDVE | F9: _ | G9: NOTICIAS | H9: - | I9: DEMOLICAO-CSDTCARANDIRU | J9: _ | K9: AVS | L9: - | M9: NOT | N9: - | O9: NDT | P9: - | Q9: DT1 | R9: _ | S9: 0001- | T9: 006 | V9: .mp4
A10: 9 | B10: BR | C10: - | D10: SP | E10: GPDVE | F10: _ | G10: NOTICIAS | H10: - | I10: DEMOLICAO-CSDTCARANDIRU | J10: _ | K10: AVS | L10: - | M10: NOT | N10: - | O10: NDT | P10: - | Q10: DT1 | R10: _ | S10: 0001- | T10: 007 | V10: .mp4
A11: 10 | B11: BR | C11: - | D11: SP | E11: GPDVE | F11: _ | G11: NOTICIAS | H11: - | I11: DEMOLICAO-CSDTCARANDIRU | J11: _ | K11: AVS | L11: - | M11: NOT | N11: - | O11: NDT | P11: - | Q11: DT1 | R11: _ | S11: 0001- | T11: 008 | V11: .mp4
A12: 11 | B12: BR | C12: - | D12: SP | E12: GPDVE | F12: _ | G12: NOTICIAS | H12: - | I12: DEMOLICAO-CSDTCARANDIRU | J12: _ | K12: AVS | L12: - | M12: NOT | N12: - | O12: NDT | P12: - | Q12: DT1 | R12: _ | S12: 0001- | T12: 009 | V12: .mp4
A13: 12 | B13: BR | C13: - | D13: SP | E13: GPDVE | F13: _ | G13: NOTICIAS | H13: - | I13: DEMOLICAO-CSDTCARANDIRU | J13: _ | K13: AVS | L13: - | M13: NOT | N13: - | O13: NDT | P13: - | Q13: DT1 | R13: _ | S13: 0001- | T13: 010 | V13: .mp4
... A34: 34 | B34: BR | C34: - | D34: SP | E34: GPDVE | F34: _ | G34: NOTICIAS | H34: - | I34: DEMOLICAO-CSDTCARANDIRU | J34: _ | K34: AVS | L34: - | M34: NOT | N34: - | O34: NDT | P34: - | Q34: DT1 | R34: _ | S34: 0001- | T34: 031 | V34: .mp4
A35: 36 | B35: BR | C35: - | D35: SP | E35: GPDVE | F35: _ | G35: NOTICIAS | H35: - | I35: ORIGINALDVD-CSDTCARANDIRU | J35: _ | K35: AVS | L35: - | M35: NOT | N35: - | O35: NDT | P35: - | Q35: DTX | R35: _ | S35: 0001- | T35: 001 | U35: 001 | V35: .VOB
A36: 37 | B36: BR | C36: - | D36: SP | E36: GPDVE | F36: _ | G36: NOTICIAS | H36: - | I36: ORIGINALDVD-CSDTCARANDIRU | J36: _ | K36: AVS | L36: - | M36: NOT | N36: - | O36: NDT | P36: - | Q36: DTX | R36: _ | S36: 0001- | T36: 001 | U36: 002 | V36: .VOB
A37: 38 | B37: BR | C37: - | D37: SP | E37: GPDVE | F37: _ | G37: NOTICIAS | H37: - | I37: ORIGINALDVD-CSDTCARANDIRU | J37: _ | K37: AVS | L37: - | M37: NOT | N37: - | O37: NDT | P37: - | Q37: DTX | R37: _ | S37: 0001- | T37: 001 | U37: 003 | V37: .IFO
A38: 39 | B38: BR | C38: - | D38: SP | E38: GPDVE | F38: _ | G38: NOTICIAS | H38: - | I38: ORIGINALDVD-CSDTCARANDIRU | J38: _ | K38: AVS | L38: - | M38: NOT | N38: - | O38: NDT | P38: - | Q38: DTX | R38: _ | S38: 0001- | T38: 001 | U38: 004 | V38: .IFO
A39: 40 | B39: BR | C39: - | D39: SP | E39: GPDVE | F39: _ | G39: NOTICIAS | H39: - | I39: ORIGINALDVD-CSDTCARANDIRU | J39: _ | K39: AVS | L39: - | M39: NOT | N39: - | O39: NDT | P39: - | Q39: DTX | R39: _ | S39: 0001- | T39: 001 | U39: 005 | V39: .BUP
A40: 41 | B40: BR | C40: - | D40: SP | E40: GPDVE | F40: _ | G40: NOTICIAS | H40: - | I40: ORIGINALDVD2-CSDTCARANDIRU | J40: _ | K40: AVS | L40: - | M40: NOT | N40: - | O40: NDT | P40: - | Q40: DTX | R40: _ | S40: 0001- | T40: 001 | U40: 006 | V40: .BUP
A41: 42 | B41: BR | C41: - | D41: SP | E41: GPDVE | F41: _ | G41: NOTICIAS | H41: - | I41: ORIGINALDVD2-CSDTCARANDIRU | J41: _ | K41: AVS | L41: - | M41: NOT | N41: - | O41: NDT | P41: - | Q41: DTX | R41: _ | S41: 0001- | T41: 001 | U41: 001 | V41: BUP
A42: 43 | B42: BR | C42: - | D42: SP | E42: GPDVE | F42: _ | G42: NOTICIAS | H42: - | I42: ORIGINALDVD2-CSDTCARANDIRU | J42: _ | K42: AVS | L42: - | M42: NOT | N42: - | O42: NDT | P42: - | Q42: DTX | R42: _ | S42: 0001- | T42: 001 | U42: 002 | V42: IFO
A43: 44 | B43: BR | C43: - | D43: SP | E43: GPDVE | F43: _ | G43: NOTICIAS | H43: - | I43: ORIGINALDVD2-CSDTCARANDIRU | J43: _ | K43: AVS | L43: - | M43: NOT | N43: - | O43: NDT | P43: - | Q43: DTX | R43: _ | S43: 0001- | T43: 001 | U43: 003 | V43: VOB
A44: 45 | B44: BR | C44: - | D44: SP | E44: GPDVE | F44: _ | G44: NOTICIAS | H44: - | I44: ORIGINALDVD2-CSDTCARANDIRU | J44: _ | K44: AVS | L44: - | M44: NOT | N44: - | O44: NDT | P44: - | Q44: DTX | R44: _ | S44: 0001- | T44: 001 | U44: 004 | V44: BUP
A45: 46 | B45: BR | C45: - | D45: SP | E45: GPDVE | F45: _ | G45: NOTICIAS | H45: - | I45: ORIGINALDVD2-CSDTCARANDIRU | J45: _ | K45: AVS | L45: - | M45: NOT | N45: - | O45: NDT | P45: - | Q45: DTX | R45: _ | S45: 0001- | T45: 001 | U45: 005 | V45: VOB
A46: 47 | B46: BR | C46: - | D46: SP | E46: GPDVE | F46: _ | G46: NOTICIAS | H46: - | I46: ORIGINALDVD2-CSDTCARANDIRU | J46: _ | K46: AVS | L46: - | M46: NOT | N46: - | O46: NDT | P46: - | Q46: DTX | R46: _ | S46: 0001- | T46: 001 | U46: 006 | V46: VOB
A47: 48 | B47: BR | C47: - | D47: SP | E47: GPDVE | F47: _ | G47: NOTICIAS | H47: - | I47: ORIGINALDVD2-CSDTCARANDIRU | J47: _ | K47: AVS | L47: - | M47: NOT | N47: - | O47: NDT | P47: - | Q47: DTX | R47: _ | S47: 0001- | T47: 001 | U47: 007 | V47: VOB

Sheet Demolicao
A1: Cód. | B1: Título descritivo (atribuído) | C1: Nível de descrição | D1: Data | E1: Duração | F1: Suporte | G1: Local | H1: Autor/Responsável | I1: Denominação do catálogo temático (GPDVE ARCOENGE) | J1: Localização | K1: Código de referência | L1: História arquivística | M1: Conteúdo/Assunto | N1: Condições de acesso e reprodução | O1: Palavras-chave | P1: Gênero | Q1: Técnica de registro | R1: Legenda para publicações | S1: Citação ABNT | T1: Notas
A2: =MID(K2, LEN(K2)-6, 3) -> 001 | B2: Trecho de reportagem da Rede Bandeirantes, veiculada no programa Primeiro Jornal em 2005. | C2: Item | D2: 38550 | E2: 0.0014351852 | F2: Originalmente DVD (suporte físico óptico). Com tratamento, tornou-se arquivo eletrônico (MP4) em suporte digital/nato-digital | G2: São Paulo, Brasil | H2: Grupo de Pesquisa em Direito e Violência de Estado | I2: Notícias - Demolição - Casa de Detenção do Carandiru | J2: Pasta: 0001 | K2: =TEXTJOIN("", TRUE, Geral!B4:V4) -> BR-SPGPDVE_NOTICIAS-DEMOLICAO-CSDTCARANDIRU_AVS-NOT-NDT-DT1_0001-001.mp4 | L2: Verificar com a professora Maíra | M2: Demolição dos pavilhões 2 e 5 da casa de detenção do Carandiru. Trecho de reportagem da Rede Bandeirantes, veiculada no programa Primeiro Jornal em 2005. | N2: O acesso aos documentos deste acervo está condicionado ao compromisso de não repassá-los a terceiros, à obrigatoriedade de mencionar que os originais pertencem ao GPDVE (?), e à necessidade de novo Termo de Responsabilidade em caso de reutilização ou uso diverso do inicialmente acordado. O uso está sujeito às restrições previstas na Lei de Arquivos (Lei nº 8.159/1991), na Lei de Direitos Autorais (Lei nº 9.610/1998), nos artigos 138 e 145 do Código Penal, e no artigo 5º, inciso X, da Constituição Federal, especialmente quanto à proteção da honra e imagem de terceiros. A pessoa física ou jurídica responsável assume integral responsabilidade civil e penal por eventuais danos decorrentes do uso das reproduções e informações, eximindo o GPDVE de qualquer responsabilidade. | O2: Sistema prisional; Demolição; Implosão; Casa de Detenção de São Paulo; Carandiru | P2: Audiovisual | Q2: Possivelmente, filmagem digital ou vídeo digital. Optou-se por "não determinado" por incerteza quanto ao processo da técnica. | R2: ="Figura n – ["&B2&"]"&CHAR(10)&"Fonte: BANDEIRANTES, "&TEXT(D2,"yyyy")&"." -> Figura n – [Trecho de reportagem da Rede Bandeirantes, veiculada no programa Primeiro Jornal em 2005.] Fonte: BANDEIRANTES, 2005. | S2: ="BANDEIRANTES. ["&B2&"]. "&G2&". "&TEXT(D2,"dd")&" "&LOWER(TEXT(D2,"mmm"))&" "&TEXT(D2,"yyyy")&". "&F2&". Disponível em: <link do dataverse>. Acesso em: 21 mai. 2026." -> BANDEIRANTES. [Trecho de reportagem da Rede Bandeirantes, veiculada no programa Primeiro Jornal em 2005.]. São Paulo, Brasil. 17 jul. 2005. Originalmente DVD (suporte físico óptico). Com tratamento, tornou-se arquivo eletrônico (MP4) em suporte digital/nato-digital. Disponível em: <link do dataverse>. Acesso em: 21 mai. 2026. | T2: Este item pertencia à pasta intitulada "Implosão carandiru - noticiário".
A3: =MID(K3, LEN(K3)-6, 3) -> 002 | B3: Trecho de reportagem da TV Cultura, veiculada sobre o Carandiru em 2005. | C3: Item | D3: 38550 | E3: 0.0067361111 | F3: Originalmente DVD (suporte físico óptico). Com tratamento, tornou-se arquivo eletrônico (MP4) em suporte digital/nato-digital | G3: São Paulo, Brasil | H3: Grupo de Pesquisa em Direito e Violência de Estado | I3: Notícias - Demolição - Casa de Detenção do Carandiru | J3: Pasta: 0001 | K3: =TEXTJOIN("", TRUE, Geral!B5:V5) -> BR-SPGPDVE_NOTICIAS-DEMOLICAO-CSDTCARANDIRU_AVS-NOT-NDT-DT1_0001-002.mp4 | L3: =Demolicao!$L$2 -> Verificar com a professora Maíra | M3: Demolição dos pavilhões 2 e 5 da casa de detenção do Carandiru. Trecho de reportagem da TV Cultura, veiculada sobre o Carandiru (arquivo mesclado) em 2005. | N3: =Demolicao!$N$2 -> O acesso aos documentos deste acervo está condicionado ao compromisso de não repassá-los a terceiros, à obrigatoriedade de mencionar que os originais pertencem ao GPDVE (?), e à necessidade de novo Termo de Responsabilidade em caso de reutilização ou uso diverso do inicialmente acordado. O uso está sujeito às restrições previstas na Lei de Arquivos (Lei nº 8.159/1991), na Lei de Direitos Autorais (Lei nº 9.610/1998), nos artigos 138 e 145 do Código Penal, e no artigo 5º, inciso X, da Constituição Federal, especialmente quanto à proteção da honra e imagem de terceiros. A pessoa física ou jurídica responsável assume integral responsabilidade civil e penal por eventuais danos decorrentes do uso das reproduções e informações, eximindo o GPDVE de qualquer responsabilidade. | O3: Sistema prisional; Demolição; Implosão; Casa de Detenção de São Paulo; Carandiru | P3: Audiovisual | Q3: Possivelmente, filmagem digital ou vídeo digital. Optou-se por "não determinado" por incerteza quanto ao processo da técnica. | R3: ="Figura n – ["&B3&"]"&CHAR(10)&"Fonte: TV CULTURA, "&TEXT(D3,"yyyy")&"." -> Figura n – [Trecho de reportagem da TV Cultura, veiculada sobre o Carandiru em 2005.] Fonte: TV CULTURA, 2005. | S3: ="TV CULTURA. ["&B3&"]. "&G3&". "&TEXT(D3,"dd")&" "&LOWER(TEXT(D3,"mmm"))&" "&TEXT(D3,"yyyy")&". "&F3&". Disponível em: <link do dataverse>. Acesso em: 21 mai. 2026." -> TV CULTURA. [Trecho de reportagem da TV Cultura, veiculada sobre o Carandiru em 2005.]. São Paulo, Brasil. 17 jul. 2005. Originalmente DVD (suporte físico óptico). Com tratamento, tornou-se arquivo eletrônico (MP4) em suporte digital/nato-digital. Disponível em: <link do dataverse>. Acesso em: 21 mai. 2026. | T3: Este item pertencia à pasta intitulada "Implosão carandiru - noticiário".
A4: =MID(K4, LEN(K4)-6, 3) -> 003 | B4: Trecho de reportagem da TV Cultura, veiculada no programa Jornal da Cultura em 2005. | C4: Item | D4: 38550 | E4: 0.00086805556 | F4: Originalmente DVD (suporte físico óptico). Com tratamento, tornou-se arquivo eletrônico (MP4) em suporte digital/nato-digital | G4: São Paulo, Brasil | H4: Grupo de Pesquisa em Direito e Violência de Estado | I4: Notícias - Demolição - Casa de Detenção do Carandiru | J4: Pasta: 0001 | K4: =TEXTJOIN("", TRUE, Geral!B6:V6) -> BR-SPGPDVE_NOTICIAS-DEMOLICAO-CSDTCARANDIRU_AVS-NOT-NDT-DT1_0001-003.mp4 | L4: =Demolicao!$L$2 -> Verificar com a professora Maíra | M4: Demolição dos pavilhões 2 e 5 da casa de detenção do Carandiru. Trecho de reportagem da TV Cultura, veiculada no programa Jornal da Cultura em 2005. | N4: =Demolicao!$N$2 -> O acesso aos documentos deste acervo está condicionado ao compromisso de não repassá-los a terceiros, à obrigatoriedade de mencionar que os originais pertencem ao GPDVE (?), e à necessidade de novo Termo de Responsabilidade em caso de reutilização ou uso diverso do inicialmente acordado. O uso está sujeito às restrições previstas na Lei de Arquivos (Lei nº 8.159/1991), na Lei de Direitos Autorais (Lei nº 9.610/1998), nos artigos 138 e 145 do Código Penal, e no artigo 5º, inciso X, da Constituição Federal, especialmente quanto à proteção da honra e imagem de terceiros. A pessoa física ou jurídica responsável assume integral responsabilidade civil e penal por eventuais danos decorrentes do uso das reproduções e informações, eximindo o GPDVE de qualquer responsabilidade. | O4: Sistema prisional; Demolição; Implosão; Casa de Detenção de São Paulo; Carandiru | P4: Audiovisual | Q4: Possivelmente, filmagem digital ou vídeo digital. Optou-se por "não determinado" por incerteza quanto ao processo da técnica. | R4: ="Figura n – ["&B4&"]"&CHAR(10)&"Fonte: TV CULTURA, "&TEXT(D4,"yyyy")&"." -> Figura n – [Trecho de reportagem da TV Cultura, veiculada no programa Jornal da Cultura em 2005.] Fonte: TV CULTURA, 2005. | S4: ="TV CULTURA. ["&B4&"]. "&G4&". "&TEXT(D4,"dd")&" "&LOWER(TEXT(D4,"mmm"))&" "&TEXT(D4,"yyyy")&". "&F4&". Disponível em: <link do dataverse>. Acesso em: 21 mai. 2026." -> TV CULTURA. [Trecho de reportagem da TV Cultura, veiculada no programa Jornal da Cultura em 2005.]. São Paulo, Brasil. 17 jul. 2005. Originalmente DVD (suporte físico óptico). Com tratamento, tornou-se arquivo eletrônico (MP4) em suporte digital/nato-digital. Disponível em: <link do dataverse>. Acesso em: 21 mai. 2026. | T4: Este item pertencia à pasta intitulada "Implosão carandiru - noticiário".
A5: =MID(K5, LEN(K5)-6, 3) -> 004 | B5: Trecho de reportagem da TV Cultura, veiculada no programa Diário Paulista em 2005. | C5: Item | D5: 38550 | E5: 0.0014467593 | F5: Originalmente DVD (suporte físico óptico). Com tratamento, tornou-se arquivo eletrônico (MP4) em suporte digital/nato-digital | G5: São Paulo, Brasil | H5: Grupo de Pesquisa em Direito e Violência de Estado | I5: Notícias - Demolição - Casa de Detenção do Carandiru | J5: Pasta: 0001 | K5: =TEXTJOIN("", TRUE, Geral!B7:V7) -> BR-SPGPDVE_NOTICIAS-DEMOLICAO-CSDTCARANDIRU_AVS-NOT-NDT-DT1_0001-004.mp4 | L5: =Demolicao!$L$2 -> Verificar com a professora Maíra | M5: Demolição dos pavilhões 2 e 5 da casa de detenção do Carandiru. Trecho de reportagem da TV Cultura, veiculada no programa Diário Paulista em 2005. | N5: =Demolicao!$N$2 -> O acesso aos documentos deste acervo está condicionado ao compromisso de não repassá-los a terceiros, à obrigatoriedade de mencionar que os originais pertencem ao GPDVE (?), e à necessidade de novo Termo de Responsabilidade em caso de reutilização ou uso diverso do inicialmente acordado. O uso está sujeito às restrições previstas na Lei de Arquivos (Lei nº 8.159/1991), na Lei de Direitos Autorais (Lei nº 9.610/1998), nos artigos 138 e 145 do Código Penal, e no artigo 5º, inciso X, da Constituição Federal, especialmente quanto à proteção da honra e imagem de terceiros. A pessoa física ou jurídica responsável assume integral responsabilidade civil e penal por eventuais danos decorrentes do uso das reproduções e informações, eximindo o GPDVE de qualquer responsabilidade. | O5: Sistema prisional; Demolição; Implosão; Casa de Detenção de São Paulo; Carandiru | P5: Audiovisual | Q5: Possivelmente, filmagem digital ou vídeo digital. Optou-se por "não determinado" por incerteza quanto ao processo da técnica. | R5: ="Figura n – ["&B5&"]"&CHAR(10)&"Fonte: TV CULTURA, "&TEXT(D5,"yyyy")&"." -> Figura n – [Trecho de reportagem da TV Cultura, veiculada no programa Diário Paulista em 2005.] Fonte: TV CULTURA, 2005. | S5: ="TV CULTURA. ["&B5&"]. "&G5&". "&TEXT(D5,"dd")&" "&LOWER(TEXT(D5,"mmm"))&" "&TEXT(D5,"yyyy")&". "&F5&". Disponível em: <link do dataverse>. Acesso em: 21 mai. 2026." -> TV CULTURA. [Trecho de reportagem da TV Cultura, veiculada no programa Diário Paulista em 2005.]. São Paulo, Brasil. 17 jul. 2005. Originalmente DVD (suporte físico óptico). Com tratamento, tornou-se arquivo eletrônico (MP4) em suporte digital/nato-digital. Disponível em: <link do dataverse>. Acesso em: 21 mai. 2026. | T5: Este item pertencia à pasta intitulada "Implosão carandiru - noticiário".
A6: =MID(K6, LEN(K6)-6, 3) -> 005 | B6: Trecho de reportagem da TV Cultura, veiculada no programa Jornal da Cultura (Edição de Sábado) em 2005. | C6: Item | D6: 38550 | E6: 0.0014583333 | F6: Originalmente DVD (suporte físico óptico). Com tratamento, tornou-se arquivo eletrônico (MP4) em suporte digital/nato-digital | G6: São Paulo, Brasil | H6: Grupo de Pesquisa em Direito e Violência de Estado | I6: Notícias - Demolição - Casa de Detenção do Carandiru | J6: Pasta: 0001 | K6: =TEXTJOIN("", TRUE, Geral!B8:V8) -> BR-SPGPDVE_NOTICIAS-DEMOLICAO-CSDTCARANDIRU_AVS-NOT-NDT-DT1_0001-005.mp4 | L6: =Demolicao!$L$2 -> Verificar com a professora Maíra | M6: Demolição dos pavilhões 2 e 5 da casa de detenção do Carandiru. Trecho de reportagem da TV Cultura, veiculada no programa Jornal da Cultura (Edição de Sábado) em 2005. | N6: =Demolicao!$N$2 -> O acesso aos documentos deste acervo está condicionado ao compromisso de não repassá-los a terceiros, à obrigatoriedade de mencionar que os originais pertencem ao GPDVE (?), e à necessidade de novo Termo de Responsabilidade em caso de reutilização ou uso diverso do inicialmente acordado. O uso está sujeito às restrições previstas na Lei de Arquivos (Lei nº 8.159/1991), na Lei de Direitos Autorais (Lei nº 9.610/1998), nos artigos 138 e 145 do Código Penal, e no artigo 5º, inciso X, da Constituição Federal, especialmente quanto à proteção da honra e imagem de terceiros. A pessoa física ou jurídica responsável assume integral responsabilidade civil e penal por eventuais danos decorrentes do uso das reproduções e informações, eximindo o GPDVE de qualquer responsabilidade. | O6: Sistema prisional; Demolição; Implosão; Casa de Detenção de São Paulo; Carandiru | P6: Audiovisual | Q6: Possivelmente, filmagem digital ou vídeo digital. Optou-se por "não determinado" por incerteza quanto ao processo da técnica. | R6: ="Figura n – ["&B6&"]"&CHAR(10)&"Fonte: TV CULTURA, "&TEXT(D6,"yyyy")&"." -> Figura n – [Trecho de reportagem da TV Cultura, veiculada no programa Jornal da Cultura (Edição de Sábado) em 2005.] Fonte: TV CULTURA, 2005. | S6: ="TV CULTURA. ["&B6&"]. "&G6&". "&TEXT(D6,"dd")&" "&LOWER(TEXT(D6,"mmm"))&" "&TEXT(D6,"yyyy")&". "&F6&". Disponível em: <link do dataverse>. Acesso em: 21 mai. 2026." -> TV CULTURA. [Trecho de reportagem da TV Cultura, veiculada no programa Jornal da Cultura (Edição de Sábado) em 2005.]. São Paulo, Brasil. 17 jul. 2005. Originalmente DVD (suporte físico óptico). Com tratamento, tornou-se arquivo eletrônico (MP4) em suporte digital/nato-digital. Disponível em: <link do dataverse>. Acesso em: 21 mai. 2026. | T6: Este item pertencia à pasta intitulada "Implosão carandiru - noticiário".
A7: =MID(K7, LEN(K7)-6, 3) -> 006 | B7: Trecho de reportagem da TV Gazeta, veiculada no programa Jornal da Gazeta em 2005. | C7: Item | D7: 38550 | E7: 0.0027199074 | F7: Originalmente DVD (suporte físico óptico). Com tratamento, tornou-se arquivo eletrônico (MP4) em suporte digital/nato-digital | G7: São Paulo, Brasil | H7: Grupo de Pesquisa em Direito e Violência de Estado | I7: Notícias - Demolição - Casa de Detenção do Carandiru | J7: Pasta: 0001 | K7: =TEXTJOIN("", TRUE, Geral!B9:V9) -> BR-SPGPDVE_NOTICIAS-DEMOLICAO-CSDTCARANDIRU_AVS-NOT-NDT-DT1_0001-006.mp4 | L7: =Demolicao!$L$2 -> Verificar com a professora Maíra | M7: Demolição dos pavilhões 2 e 5 da casa de detenção do Carandiru. Trecho de reportagem da TV Gazeta, veiculada no programa Jornal da Gazeta (Completo) em 2005. | N7: =Demolicao!$N$2 -> O acesso aos documentos deste acervo está condicionado ao compromisso de não repassá-los a terceiros, à obrigatoriedade de mencionar que os originais pertencem ao GPDVE (?), e à necessidade de novo Termo de Responsabilidade em caso de reutilização ou uso diverso do inicialmente acordado. O uso está sujeito às restrições previstas na Lei de Arquivos (Lei nº 8.159/1991), na Lei de Direitos Autorais (Lei nº 9.610/1998), nos artigos 138 e 145 do Código Penal, e no artigo 5º, inciso X, da Constituição Federal, especialmente quanto à proteção da honra e imagem de terceiros. A pessoa física ou jurídica responsável assume integral responsabilidade civil e penal por eventuais danos decorrentes do uso das reproduções e informações, eximindo o GPDVE de qualquer responsabilidade. | O7: Sistema prisional; Demolição; Implosão; Casa de Detenção de São Paulo; Carandiru | P7: Audiovisual | Q7: Possivelmente, filmagem digital ou vídeo digital. Optou-se por "não determinado" por incerteza quanto ao processo da técnica. | R7: ="Figura n – ["&B7&"]"&CHAR(10)&"Fonte: TV GAZETA, "&TEXT(D7,"yyyy")&"." -> Figura n – [Trecho de reportagem da TV Gazeta, veiculada no programa Jornal da Gazeta em 2005.] Fonte: TV GAZETA, 2005. | S7: ="TC GAZETA. ["&B7&"]. "&G7&". "&TEXT(D7,"dd")&" "&LOWER(TEXT(D7,"mmm"))&" "&TEXT(D7,"yyyy")&". "&F7&". Disponível em: <link do dataverse>. Acesso em: 21 mai. 2026." -> TC GAZETA. [Trecho de reportagem da TV Gazeta, veiculada no programa Jornal da Gazeta em 2005.]. São Paulo, Brasil. 17 jul. 2005. Originalmente DVD (suporte físico óptico). Com tratamento, tornou-se arquivo eletrônico (MP4) em suporte digital/nato-digital. Disponível em: <link do dataverse>. Acesso em: 21 mai. 2026. | T7: Este item pertencia à pasta intitulada "Implosão carandiru - noticiário".
A8: =MID(K8, LEN(K8)-6, 3) -> 007 | B8: Trecho de reportagem da TV Gazeta, veiculada no programa Jornal da Gazeta em 2005. | C8: Item | D8: 38550 | E8: 0.00040509259 | F8: Originalmente DVD (suporte físico óptico). Com tratamento, tornou-se arquivo eletrônico (MP4) em suporte digital/nato-digital | G8: São Paulo, Brasil | H8: Grupo de Pesquisa em Direito e Violência de Estado | I8: Notícias - Demolição - Casa de Detenção do Carandiru | J8: Pasta: 0001 | K8: =TEXTJOIN("", TRUE, Geral!B10:V10) -> BR-SPGPDVE_NOTICIAS-DEMOLICAO-CSDTCARANDIRU_AVS-NOT-NDT-DT1_0001-007.mp4 | L8: =Demolicao!$L$2 -> Verificar com a professora Maíra | M8: Demolição dos pavilhões 2 e 5 da casa de detenção do Carandiru. Trecho de reportagem da TV Gazeta, veiculada no programa Jornal da Gazeta em 2005. | N8: =Demolicao!$N$2 -> O acesso aos documentos deste acervo está condicionado ao compromisso de não repassá-los a terceiros, à obrigatoriedade de mencionar que os originais pertencem ao GPDVE (?), e à necessidade de novo Termo de Responsabilidade em caso de reutilização ou uso diverso do inicialmente acordado. O uso está sujeito às restrições previstas na Lei de Arquivos (Lei nº 8.159/1991), na Lei de Direitos Autorais (Lei nº 9.610/1998), nos artigos 138 e 145 do Código Penal, e no artigo 5º, inciso X, da Constituição Federal, especialmente quanto à proteção da honra e imagem de terceiros. A pessoa física ou jurídica responsável assume integral responsabilidade civil e penal por eventuais danos decorrentes do uso das reproduções e informações, eximindo o GPDVE de qualquer responsabilidade. | O8: Sistema prisional; Demolição; Implosão; Casa de Detenção de São Paulo; Carandiru | P8: Audiovisual | Q8: Possivelmente, filmagem digital ou vídeo digital. Optou-se por "não determinado" por incerteza quanto ao processo da técnica. | R8: ="Figura n – ["&B8&"]"&CHAR(10)&"Fonte: TV GAZETA, "&TEXT(D8,"yyyy")&"." -> Figura n – [Trecho de reportagem da TV Gazeta, veiculada no programa Jornal da Gazeta em 2005.] Fonte: TV GAZETA, 2005. | S8: ="TC GAZETA. ["&B8&"]. "&G8&". "&TEXT(D8,"dd")&" "&LOWER(TEXT(D8,"mmm"))&" "&TEXT(D8,"yyyy")&". "&F8&". Disponível em: <link do dataverse>. Acesso em: 21 mai. 2026." -> TC GAZETA. [Trecho de reportagem da TV Gazeta, veiculada no programa Jornal da Gazeta em 2005.]. São Paulo, Brasil. 17 jul. 2005. Originalmente DVD (suporte físico óptico). Com tratamento, tornou-se arquivo eletrônico (MP4) em suporte digital/nato-digital. Disponível em: <link do dataverse>. Acesso em: 21 mai. 2026. | T8: Este item pertencia à pasta intitulada "Implosão carandiru - noticiário".
A9: =MID(K9, LEN(K9)-6, 3) -> 008 | B9: Trecho de reportagem da Rede Globo, veiculada no programa SPTV em 2005. | C9: Item | D9: 38550 | E9: 0.0028125 | F9: Originalmente DVD (suporte físico óptico). Com tratamento, tornou-se arquivo eletrônico (MP4) em suporte digital/nato-digital | G9: São Paulo, Brasil | H9: Grupo de Pesquisa em Direito e Violência de Estado | I9: Notícias - Demolição - Casa de Detenção do Carandiru | J9: Pasta: 0001 | K9: =TEXTJOIN("", TRUE, Geral!B11:V11) -> BR-SPGPDVE_NOTICIAS-DEMOLICAO-CSDTCARANDIRU_AVS-NOT-NDT-DT1_0001-008.mp4 | L9: =Demolicao!$L$2 -> Verificar com a professora Maíra | M9: Demolição dos pavilhões 2 e 5 da casa de detenção do Carandiru. Trecho de reportagem da Rede Globo, veiculada no programa SPTV em 2005. | N9: =Demolicao!$N$2 -> O acesso aos documentos deste acervo está condicionado ao compromisso de não repassá-los a terceiros, à obrigatoriedade de mencionar que os originais pertencem ao GPDVE (?), e à necessidade de novo Termo de Responsabilidade em caso de reutilização ou uso diverso do inicialmente acordado. O uso está sujeito às restrições previstas na Lei de Arquivos (Lei nº 8.159/1991), na Lei de Direitos Autorais (Lei nº 9.610/1998), nos artigos 138 e 145 do Código Penal, e no artigo 5º, inciso X, da Constituição Federal, especialmente quanto à proteção da honra e imagem de terceiros. A pessoa física ou jurídica responsável assume integral responsabilidade civil e penal por eventuais danos decorrentes do uso das reproduções e informações, eximindo o GPDVE de qualquer responsabilidade. | O9: Sistema prisional; Demolição; Implosão; Casa de Detenção de São Paulo; Carandiru | P9: Audiovisual | Q9: Possivelmente, filmagem digital ou vídeo digital. Optou-se por "não determinado" por incerteza quanto ao processo da técnica. | R9: ="Figura n – ["&B9&"]"&CHAR(10)&"Fonte: GLOBO, "&TEXT(D9,"yyyy")&"." -> Figura n – [Trecho de reportagem da Rede Globo, veiculada no programa SPTV em 2005.] Fonte: GLOBO, 2005. | S9: ="GLOBO. ["&B9&"]. "&G9&". "&TEXT(D9,"dd")&" "&LOWER(TEXT(D9,"mmm"))&" "&TEXT(D9,"yyyy")&". "&F9&". Disponível em: <link do dataverse>. Acesso em: 21 mai. 2026." -> GLOBO. [Trecho de reportagem da Rede Globo, veiculada no programa SPTV em 2005.]. São Paulo, Brasil. 17 jul. 2005. Originalmente DVD (suporte físico óptico). Com tratamento, tornou-se arquivo eletrônico (MP4) em suporte digital/nato-digital. Disponível em: <link do dataverse>. Acesso em: 21 mai. 2026. | T9: Este item pertencia à pasta intitulada "Implosão carandiru - noticiário".
A10: =MID(K10, LEN(K10)-6, 3) -> 009 | B10: Trecho de reportagem da GloboNews, veiculada no programa Em Cima da Hora em 2005. | C10: Item | D10: 38550 | E10: 0.0021180556 | F10: Originalmente DVD (suporte físico óptico). Com tratamento, tornou-se arquivo eletrônico (MP4) em suporte digital/nato-digital | G10: São Paulo, Brasil | H10: Grupo de Pesquisa em Direito e Violência de Estado | I10: Notícias - Demolição - Casa de Detenção do Carandiru | J10: Pasta: 0001 | K10: =TEXTJOIN("", TRUE, Geral!B12:V12) -> BR-SPGPDVE_NOTICIAS-DEMOLICAO-CSDTCARANDIRU_AVS-NOT-NDT-DT1_0001-009.mp4 | L10: =Demolicao!$L$2 -> Verificar com a professora Maíra | M10: Demolição dos pavilhões 2 e 5 da casa de detenção do Carandiru. Trecho de reportagem da GloboNews, veiculada no programa Em Cima da Hora em 2005. | N10: =Demolicao!$N$2 -> O acesso aos documentos deste acervo está condicionado ao compromisso de não repassá-los a terceiros, à obrigatoriedade de mencionar que os originais pertencem ao GPDVE (?), e à necessidade de novo Termo de Responsabilidade em caso de reutilização ou uso diverso do inicialmente acordado. O uso está sujeito às restrições previstas na Lei de Arquivos (Lei nº 8.159/1991), na Lei de Direitos Autorais (Lei nº 9.610/1998), nos artigos 138 e 145 do Código Penal, e no artigo 5º, inciso X, da Constituição Federal, especialmente quanto à proteção da honra e imagem de terceiros. A pessoa física ou jurídica responsável assume integral responsabilidade civil e penal por eventuais danos decorrentes do uso das reproduções e informações, eximindo o GPDVE de qualquer responsabilidade. | O10: Sistema prisional; Demolição; Implosão; Casa de Detenção de São Paulo; Carandiru | P10: Audiovisual | Q10: Possivelmente, filmagem digital ou vídeo digital. Optou-se por "não determinado" por incerteza quanto ao processo da técnica. | R10: ="Figura n – ["&B10&"]"&CHAR(10)&"Fonte: GLOBO NEWS, "&TEXT(D10,"yyyy")&"." -> Figura n – [Trecho de reportagem da GloboNews, veiculada no programa Em Cima da Hora em 2005.] Fonte: GLOBO NEWS, 2005. | S10: ="GLOBO NEWS. ["&B10&"]. "&G10&". "&TEXT(D10,"dd")&" "&LOWER(TEXT(D10,"mmm"))&" "&TEXT(D10,"yyyy")&". "&F10&". Disponível em: <link do dataverse>. Acesso em: 21 mai. 2026." -> GLOBO NEWS. [Trecho de reportagem da GloboNews, veiculada no programa Em Cima da Hora em 2005.]. São Paulo, Brasil. 17 jul. 2005. Originalmente DVD (suporte físico óptico). Com tratamento, tornou-se arquivo eletrônico (MP4) em suporte digital/nato-digital. Disponível em: <link do dataverse>. Acesso em: 21 mai. 2026. | T10: Este item pertencia à pasta intitulada "Implosão carandiru - noticiário".
A11: =MID(K11, LEN(K11)-6, 3) -> 010 | B11: Trecho de reportagem da Rede Globo, veiculada no programa Fantástico em 2005. | C11: Item | D11: 38550 | E11: 0.00053240741 | F11: Originalmente DVD (suporte físico óptico). Com tratamento, tornou-se arquivo eletrônico (MP4) em suporte digital/nato-digital | G11: São Paulo, Brasil | H11: Grupo de Pesquisa em Direito e Violência de Estado | I11: Notícias - Demolição - Casa de Detenção do Carandiru | J11: Pasta: 0001 | K11: =TEXTJOIN("", TRUE, Geral!B13:V13) -> BR-SPGPDVE_NOTICIAS-DEMOLICAO-CSDTCARANDIRU_AVS-NOT-NDT-DT1_0001-010.mp4 | L11: =Demolicao!$L$2 -> Verificar com a professora Maíra | M11: Demolição dos pavilhões 2 e 5 da casa de detenção do Carandiru. Trecho de reportagem da Rede Globo, veiculada no programa Fantástico em 2005. | N11: =Demolicao!$N$2 -> O acesso aos documentos deste acervo está condicionado ao compromisso de não repassá-los a terceiros, à obrigatoriedade de mencionar que os originais pertencem ao GPDVE (?), e à necessidade de novo Termo de Responsabilidade em caso de reutilização ou uso diverso do inicialmente acordado. O uso está sujeito às restrições previstas na Lei de Arquivos (Lei nº 8.159/1991), na Lei de Direitos Autorais (Lei nº 9.610/1998), nos artigos 138 e 145 do Código Penal, e no artigo 5º, inciso X, da Constituição Federal, especialmente quanto à proteção da honra e imagem de terceiros. A pessoa física ou jurídica responsável assume integral responsabilidade civil e penal por eventuais danos decorrentes do uso das reproduções e informações, eximindo o GPDVE de qualquer responsabilidade. | O11: Sistema prisional; Demolição; Implosão; Casa de Detenção de São Paulo; Carandiru | P11: Audiovisual | Q11: Possivelmente, filmagem digital ou vídeo digital. Optou-se por "não determinado" por incerteza quanto ao processo da técnica. | R11: ="Figura n – ["&B11&"]"&CHAR(10)&"Fonte: GLOBO, "&TEXT(D11,"yyyy")&"." -> Figura n – [Trecho de reportagem da Rede Globo, veiculada no programa Fantástico em 2005.] Fonte: GLOBO, 2005. | S11: ="GLOBO. ["&B11&"]. "&G11&". "&TEXT(D11,"dd")&" "&LOWER(TEXT(D11,"mmm"))&" "&TEXT(D11,"yyyy")&". "&F11&". Disponível em: <link do dataverse>. Acesso em: 21 mai. 2026." -> GLOBO. [Trecho de reportagem da Rede Globo, veiculada no programa Fantástico em 2005.]. São Paulo, Brasil. 17 jul. 2005. Originalmente DVD (suporte físico óptico). Com tratamento, tornou-se arquivo eletrônico (MP4) em suporte digital/nato-digital. Disponível em: <link do dataverse>. Acesso em: 21 mai. 2026. | T11: Este item pertencia à pasta intitulada "Implosão carandiru - noticiário".
A12: =MID(K12, LEN(K12)-6, 3) -> 011 | B12: Trecho de reportagem da Rede Globo, veiculada no programa Bom Dia São Paulo [Parte 1] em 2005. | C12: Item | D12: 38550 | E12: 0.0045949074 | F12: Originalmente DVD (suporte físico óptico). Com tratamento, tornou-se arquivo eletrônico (MP4) em suporte digital/nato-digital | G12: São Paulo, Brasil | H12: Grupo de Pesquisa em Direito e Violência de Estado | I12: Notícias - Demolição - Casa de Detenção do Carandiru | J12: Pasta: 0001 | K12: =TEXTJOIN("", TRUE, Geral!B14:V14) -> BR-SPGPDVE_NOTICIAS-DEMOLICAO-CSDTCARANDIRU_AVS-NOT-NDT-DT1_0001-011.mp4 | L12: =Demolicao!$L$2 -> Verificar com a professora Maíra | M12: Demolição dos pavilhões 2 e 5 da casa de detenção do Carandiru. Trecho de reportagem da Rede Globo, veiculada no programa Bom Dia São Paulo [Parte 1] em 2005. | N12: =Demolicao!$N$2 -> O acesso aos documentos deste acervo está condicionado ao compromisso de não repassá-los a terceiros, à obrigatoriedade de mencionar que os originais pertencem ao GPDVE (?), e à necessidade de novo Termo de Responsabilidade em caso de reutilização ou uso diverso do inicialmente acordado. O uso está sujeito às restrições previstas na Lei de Arquivos (Lei nº 8.159/1991), na Lei de Direitos Autorais (Lei nº 9.610/1998), nos artigos 138 e 145 do Código Penal, e no artigo 5º, inciso X, da Constituição Federal, especialmente quanto à proteção da honra e imagem de terceiros. A pessoa física ou jurídica responsável assume integral responsabilidade civil e penal por eventuais danos decorrentes do uso das reproduções e informações, eximindo o GPDVE de qualquer responsabilidade. | O12: Sistema prisional; Demolição; Implosão; Casa de Detenção de São Paulo; Carandiru | P12: Audiovisual | Q12: Possivelmente, filmagem digital ou vídeo digital. Optou-se por "não determinado" por incerteza quanto ao processo da técnica. | R12: ="Figura n – ["&B12&"]"&CHAR(10)&"Fonte: GLOBO, "&TEXT(D12,"yyyy")&"." -> Figura n – [Trecho de reportagem da Rede Globo, veiculada no programa Bom Dia São Paulo [Parte 1] em 2005.] Fonte: GLOBO, 2005. | S12: ="GLOBO. ["&B12&"]. "&G12&". "&TEXT(D12,"dd")&" "&LOWER(TEXT(D12,"mmm"))&" "&TEXT(D12,"yyyy")&". "&F12&". Disponível em: <link do dataverse>. Acesso em: 21 mai. 2026." -> GLOBO. [Trecho de reportagem da Rede Globo, veiculada no programa Bom Dia São Paulo [Parte 1] em 2005.]. São Paulo, Brasil. 17 jul. 2005. Originalmente DVD (suporte físico óptico). Com tratamento, tornou-se arquivo eletrônico (MP4) em suporte digital/nato-digital. Disponível em: <link do dataverse>. Acesso em: 21 mai. 2026. | T12: Este item pertencia à pasta intitulada "Implosão carandiru - noticiário".
A13: =MID(K13, LEN(K13)-6, 3) -> 012 | B13: Trecho de reportagem da Rede Globo, veiculada no programa Bom Dia São Paulo [Parte 2] em 2005. | C13: Item | D13: 38550 | E13: 0.00054398148 | F13: Originalmente DVD (suporte físico óptico). Com tratamento, tornou-se arquivo eletrônico (MP4) em suporte digital/nato-digital | G13: São Paulo, Brasil | H13: Grupo de Pesquisa em Direito e Violência de Estado | I13: Notícias - Demolição - Casa de Detenção do Carandiru | J13: Pasta: 0001 | K13: =TEXTJOIN("", TRUE, Geral!B15:V15) -> BR-SPGPDVE_NOTICIAS-DEMOLICAO-CSDTCARANDIRU_AVS-NOT-NDT-DT1_0001-012.mp4 | L13: =Demolicao!$L$2 -> Verificar com a professora Maíra | M13: Demolição dos pavilhões 2 e 5 da casa de detenção do Carandiru. Trecho de reportagem da Rede Globo, veiculada no programa Bom Dia São Paulo [Parte 2] em 2005. | N13: =Demolicao!$N$2 -> O acesso aos documentos deste acervo está condicionado ao compromisso de não repassá-los a terceiros, à obrigatoriedade de mencionar que os originais pertencem ao GPDVE (?), e à necessidade de novo Termo de Responsabilidade em caso de reutilização ou uso diverso do inicialmente acordado. O uso está sujeito às restrições previstas na Lei de Arquivos (Lei nº 8.159/1991), na Lei de Direitos Autorais (Lei nº 9.610/1998), nos artigos 138 e 145 do Código Penal, e no artigo 5º, inciso X, da Constituição Federal, especialmente quanto à proteção da honra e imagem de terceiros. A pessoa física ou jurídica responsável assume integral responsabilidade civil e penal por eventuais danos decorrentes do uso das reproduções e informações, eximindo o GPDVE de qualquer responsabilidade. | O13: Sistema prisional; Demolição; Implosão; Casa de Detenção de São Paulo; Carandiru | P13: Audiovisual | Q13: Possivelmente, filmagem digital ou vídeo digital. Optou-se por "não determinado" por incerteza quanto ao processo da técnica. | R13: ="Figura n – ["&B13&"]"&CHAR(10)&"Fonte: GLOBO, "&TEXT(D13,"yyyy")&"." -> Figura n – [Trecho de reportagem da Rede Globo, veiculada no programa Bom Dia São Paulo [Parte 2] em 2005.] Fonte: GLOBO, 2005. | S13: ="GLOBO. ["&B13&"]. "&G13&". "&TEXT(D13,"dd")&" "&LOWER(TEXT(D13,"mmm"))&" "&TEXT(D13,"yyyy")&". "&F13&". Disponível em: <link do dataverse>. Acesso em: 21 mai. 2026." -> GLOBO. [Trecho de reportagem da Rede Globo, veiculada no programa Bom Dia São Paulo [Parte 2] em 2005.]. São Paulo, Brasil. 17 jul. 2005. Originalmente DVD (suporte físico óptico). Com tratamento, tornou-se arquivo eletrônico (MP4) em suporte digital/nato-digital. Disponível em: <link do dataverse>. Acesso em: 21 mai. 2026. | T13: Este item pertencia à pasta intitulada "Implosão carandiru - noticiário".
A14: =MID(K14, LEN(K14)-6, 3) -> 013 | B14: Vinheta da Rede Record, veiculada no programa São Paulo no Ar em 2005. | C14: Item | D14: 38550 | E14: 0.0038194444 | F14: Originalmente DVD (suporte físico óptico). Com tratamento, tornou-se arquivo eletrônico (MP4) em suporte digital/nato-digital | G14: São Paulo, Brasil | H14: Grupo de Pesquisa em Direito e Violência de Estado | I14: Notícias - Demolição - Casa de Detenção do Carandiru | J14: Pasta: 0001 | K14: =TEXTJOIN("", TRUE, Geral!B16:V16) -> BR-SPGPDVE_NOTICIAS-DEMOLICAO-CSDTCARANDIRU_AVS-NOT-NDT-DT1_0001-013.mp4 | L14: =Demolicao!$L$2 -> Verificar com a professora Maíra | M14: Vinheta da Rede Record, veiculada no programa São Paulo no Ar em 2005. | N14: =Demolicao!$N$2 -> O acesso aos documentos deste acervo está condicionado ao compromisso de não repassá-los a terceiros, à obrigatoriedade de mencionar que os originais pertencem ao GPDVE (?), e à necessidade de novo Termo de Responsabilidade em caso de reutilização ou uso diverso do inicialmente acordado. O uso está sujeito às restrições previstas na Lei de Arquivos (Lei nº 8.159/1991), na Lei de Direitos Autorais (Lei nº 9.610/1998), nos artigos 138 e 145 do Código Penal, e no artigo 5º, inciso X, da Constituição Federal, especialmente quanto à proteção da honra e imagem de terceiros. A pessoa física ou jurídica responsável assume integral responsabilidade civil e penal por eventuais danos decorrentes do uso das reproduções e informações, eximindo o GPDVE de qualquer responsabilidade. | O14: Sistema prisional; Demolição; Implosão; Casa de Detenção de São Paulo; Carandiru | P14: Audiovisual | Q14: Possivelmente, filmagem digital ou vídeo digital. Optou-se por "não determinado" por incerteza quanto ao processo da técnica. | R14: ="Figura n – ["&B14&"]"&CHAR(10)&"Fonte: RECORD, "&TEXT(D14,"yyyy")&"." -> Figura n – [Vinheta da Rede Record, veiculada no programa São Paulo no Ar em 2005.] Fonte: RECORD, 2005. | S14: ="RECORD. ["&B14&"]. "&G14&". "&TEXT(D14,"dd")&" "&LOWER(TEXT(D14,"mmm"))&" "&TEXT(D14,"yyyy")&". "&F14&". Disponível em: <link do dataverse>. Acesso em: 21 mai. 2026." -> RECORD. [Vinheta da Rede Record, veiculada no programa São Paulo no Ar em 2005.]. São Paulo, Brasil. 17 jul. 2005. Originalmente DVD (suporte físico óptico). Com tratamento, tornou-se arquivo eletrônico (MP4) em suporte digital/nato-digital. Disponível em: <link do dataverse>. Acesso em: 21 mai. 2026. | T14: Este item pertencia à pasta intitulada "Implosão carandiru - noticiário".
A15: =MID(K15, LEN(K15)-6, 3) -> 014 | B15: Trecho de reportagem da Rede Record, veiculada no programa Fala Brasil [Parte 1] em 2005. | C15: Item | D15: 38550 | E15: 0.0022222222 | F15: Originalmente DVD (suporte físico óptico). Com tratamento, tornou-se arquivo eletrônico (MP4) em suporte digital/nato-digital | G15: São Paulo, Brasil | H15: Grupo de Pesquisa em Direito e Violência de Estado | I15: Notícias - Demolição - Casa de Detenção do Carandiru | J15: Pasta: 0001 | K15: =TEXTJOIN("", TRUE, Geral!B17:V17) -> BR-SPGPDVE_NOTICIAS-DEMOLICAO-CSDTCARANDIRU_AVS-NOT-NDT-DT1_0001-014.mp4 | L15: =Demolicao!$L$2 -> Verificar com a professora Maíra | M15: Demolição dos pavilhões 2 e 5 da casa de detenção do Carandiru. Trecho de reportagem da Rede Record, veiculada no programa Fala Brasil [Parte 1] em 2005. | N15: =Demolicao!$N$2 -> O acesso aos documentos deste acervo está condicionado ao compromisso de não repassá-los a terceiros, à obrigatoriedade de mencionar que os originais pertencem ao GPDVE (?), e à necessidade de novo Termo de Responsabilidade em caso de reutilização ou uso diverso do inicialmente acordado. O uso está sujeito às restrições previstas na Lei de Arquivos (Lei nº 8.159/1991), na Lei de Direitos Autorais (Lei nº 9.610/1998), nos artigos 138 e 145 do Código Penal, e no artigo 5º, inciso X, da Constituição Federal, especialmente quanto à proteção da honra e imagem de terceiros. A pessoa física ou jurídica responsável assume integral responsabilidade civil e penal por eventuais danos decorrentes do uso das reproduções e informações, eximindo o GPDVE de qualquer responsabilidade. | O15: Sistema prisional; Demolição; Implosão; Casa de Detenção de São Paulo; Carandiru | P15: Audiovisual | Q15: Possivelmente, filmagem digital ou vídeo digital. Optou-se por "não determinado" por incerteza quanto ao processo da técnica. | R15: ="Figura n – ["&B15&"]"&CHAR(10)&"Fonte: RECORD, "&TEXT(D15,"yyyy")&"." -> Figura n – [Trecho de reportagem da Rede Record, veiculada no programa Fala Brasil [Parte 1] em 2005.] Fonte: RECORD, 2005. | S15: ="RECORD. ["&B15&"]. "&G15&". "&TEXT(D15,"dd")&" "&LOWER(TEXT(D15,"mmm"))&" "&TEXT(D15,"yyyy")&". "&F15&". Disponível em: <link do dataverse>. Acesso em: 21 mai. 2026." -> RECORD. [Trecho de reportagem da Rede Record, veiculada no programa Fala Brasil [Parte 1] em 2005.]. São Paulo, Brasil. 17 jul. 2005. Originalmente DVD (suporte físico óptico). Com tratamento, tornou-se arquivo eletrônico (MP4) em suporte digital/nato-digital. Disponível em: <link do dataverse>. Acesso em: 21 mai. 2026. | T15: Este item pertencia à pasta intitulada "Implosão carandiru - noticiário".
A16: =MID(K16, LEN(K16)-6, 3) -> 015 | B16: Trecho de reportagem da Rede Record, veiculada no programa Edição de Notícias em 2005. | C16: Item | D16: 38550 | E16: 0.0019675926 | F16: Originalmente DVD (suporte físico óptico). Com tratamento, tornou-se arquivo eletrônico (MP4) em suporte digital/nato-digital | G16: São Paulo, Brasil | H16: Grupo de Pesquisa em Direito e Violência de Estado | I16: Notícias - Demolição - Casa de Detenção do Carandiru | J16: Pasta: 0001 | K16: =TEXTJOIN("", TRUE, Geral!B18:V18) -> BR-SPGPDVE_NOTICIAS-DEMOLICAO-CSDTCARANDIRU_AVS-NOT-NDT-DT1_0001-015.mp4 | L16: =Demolicao!$L$2 -> Verificar com a professora Maíra | M16: Demolição dos pavilhões 2 e 5 da casa de detenção do Carandiru. Trecho de reportagem da Rede Record, veiculada no programa Edição de Notícias em 2005. | N16: =Demolicao!$N$2 -> O acesso aos documentos deste acervo está condicionado ao compromisso de não repassá-los a terceiros, à obrigatoriedade de mencionar que os originais pertencem ao GPDVE (?), e à necessidade de novo Termo de Responsabilidade em caso de reutilização ou uso diverso do inicialmente acordado. O uso está sujeito às restrições previstas na Lei de Arquivos (Lei nº 8.159/1991), na Lei de Direitos Autorais (Lei nº 9.610/1998), nos artigos 138 e 145 do Código Penal, e no artigo 5º, inciso X, da Constituição Federal, especialmente quanto à proteção da honra e imagem de terceiros. A pessoa física ou jurídica responsável assume integral responsabilidade civil e penal por eventuais danos decorrentes do uso das reproduções e informações, eximindo o GPDVE de qualquer responsabilidade. | O16: Sistema prisional; Demolição; Implosão; Casa de Detenção de São Paulo; Carandiru | P16: Audiovisual | Q16: Possivelmente, filmagem digital ou vídeo digital. Optou-se por "não determinado" por incerteza quanto ao processo da técnica. | R16: ="Figura n – ["&B16&"]"&CHAR(10)&"Fonte: RECORD, "&TEXT(D16,"yyyy")&"." -> Figura n – [Trecho de reportagem da Rede Record, veiculada no programa Edição de Notícias em 2005.] Fonte: RECORD, 2005. | S16: ="RECORD. ["&B16&"]. "&G16&". "&TEXT(D16,"dd")&" "&LOWER(TEXT(D16,"mmm"))&" "&TEXT(D16,"yyyy")&". "&F16&". Disponível em: <link do dataverse>. Acesso em: 21 mai. 2026." -> RECORD. [Trecho de reportagem da Rede Record, veiculada no programa Edição de Notícias em 2005.]. São Paulo, Brasil. 17 jul. 2005. Originalmente DVD (suporte físico óptico). Com tratamento, tornou-se arquivo eletrônico (MP4) em suporte digital/nato-digital. Disponível em: <link do dataverse>. Acesso em: 21 mai. 2026. | T16: Este item pertencia à pasta intitulada "Implosão carandiru - noticiário".
A17: =MID(K17, LEN(K17)-6, 3) -> 016 | B17: Trecho de reportagem da Rede Record, veiculada no programa Jornal da Record em 2005. | C17: Item | D17: 38550 | E17: 0.00085648148 | F17: Originalmente DVD (suporte físico óptico). Com tratamento, tornou-se arquivo eletrônico (MP4) em suporte digital/nato-digital | G17: São Paulo, Brasil | H17: Grupo de Pesquisa em Direito e Violência de Estado | I17: Notícias - Demolição - Casa de Detenção do Carandiru | J17: Pasta: 0001 | K17: =TEXTJOIN("", TRUE, Geral!B19:V19) -> BR-SPGPDVE_NOTICIAS-DEMOLICAO-CSDTCARANDIRU_AVS-NOT-NDT-DT1_0001-016.mp4 | L17: =Demolicao!$L$2 -> Verificar com a professora Maíra | M17: Demolição dos pavilhões 2 e 5 da casa de detenção do Carandiru. Trecho de reportagem da Rede Record, veiculada no programa Jornal da Record em 2005. | N17: =Demolicao!$N$2 -> O acesso aos documentos deste acervo está condicionado ao compromisso de não repassá-los a terceiros, à obrigatoriedade de mencionar que os originais pertencem ao GPDVE (?), e à necessidade de novo Termo de Responsabilidade em caso de reutilização ou uso diverso do inicialmente acordado. O uso está sujeito às restrições previstas na Lei de Arquivos (Lei nº 8.159/1991), na Lei de Direitos Autorais (Lei nº 9.610/1998), nos artigos 138 e 145 do Código Penal, e no artigo 5º, inciso X, da Constituição Federal, especialmente quanto à proteção da honra e imagem de terceiros. A pessoa física ou jurídica responsável assume integral responsabilidade civil e penal por eventuais danos decorrentes do uso das reproduções e informações, eximindo o GPDVE de qualquer responsabilidade. | O17: Sistema prisional; Demolição; Implosão; Casa de Detenção de São Paulo; Carandiru | P17: Audiovisual | Q17: Possivelmente, filmagem digital ou vídeo digital. Optou-se por "não determinado" por incerteza quanto ao processo da técnica. | R17: ="Figura n – ["&B17&"]"&CHAR(10)&"Fonte: RECORD, "&TEXT(D17,"yyyy")&"." -> Figura n – [Trecho de reportagem da Rede Record, veiculada no programa Jornal da Record em 2005.] Fonte: RECORD, 2005. | S17: ="RECORD. ["&B17&"]. "&G17&". "&TEXT(D17,"dd")&" "&LOWER(TEXT(D17,"mmm"))&" "&TEXT(D17,"yyyy")&". "&F17&". Disponível em: <link do dataverse>. Acesso em: 21 mai. 2026." -> RECORD. [Trecho de reportagem da Rede Record, veiculada no programa Jornal da Record em 2005.]. São Paulo, Brasil. 17 jul. 2005. Originalmente DVD (suporte físico óptico). Com tratamento, tornou-se arquivo eletrônico (MP4) em suporte digital/nato-digital. Disponível em: <link do dataverse>. Acesso em: 21 mai. 2026. | T17: Este item pertencia à pasta intitulada "Implosão carandiru - noticiário".
A18: =MID(K18, LEN(K18)-6, 3) -> 017 | B18: Trecho de reportagem da Rede Record, veiculada no programa Domingo Espetacular em 2005. | C18: Item | D18: 38550 | E18: 0.00070601852 | F18: Originalmente DVD (suporte físico óptico). Com tratamento, tornou-se arquivo eletrônico (MP4) em suporte digital/nato-digital | G18: São Paulo, Brasil | H18: Grupo de Pesquisa em Direito e Violência de Estado | I18: Notícias - Demolição - Casa de Detenção do Carandiru | J18: Pasta: 0001 | K18: =TEXTJOIN("", TRUE, Geral!B20:V20) -> BR-SPGPDVE_NOTICIAS-DEMOLICAO-CSDTCARANDIRU_AVS-NOT-NDT-DT1_0001-017.mp4 | L18: =Demolicao!$L$2 -> Verificar com a professora Maíra | M18: Demolição dos pavilhões 2 e 5 da casa de detenção do Carandiru. Trecho de reportagem da Rede Record, veiculada no programa Domingo Espetacular em 2005. | N18: =Demolicao!$N$2 -> O acesso aos documentos deste acervo está condicionado ao compromisso de não repassá-los a terceiros, à obrigatoriedade de mencionar que os originais pertencem ao GPDVE (?), e à necessidade de novo Termo de Responsabilidade em caso de reutilização ou uso diverso do inicialmente acordado. O uso está sujeito às restrições previstas na Lei de Arquivos (Lei nº 8.159/1991), na Lei de Direitos Autorais (Lei nº 9.610/1998), nos artigos 138 e 145 do Código Penal, e no artigo 5º, inciso X, da Constituição Federal, especialmente quanto à proteção da honra e imagem de terceiros. A pessoa física ou jurídica responsável assume integral responsabilidade civil e penal por eventuais danos decorrentes do uso das reproduções e informações, eximindo o GPDVE de qualquer responsabilidade. | O18: Sistema prisional; Demolição; Implosão; Casa de Detenção de São Paulo; Carandiru | P18: Audiovisual | Q18: Possivelmente, filmagem digital ou vídeo digital. Optou-se por "não determinado" por incerteza quanto ao processo da técnica. | R18: ="Figura n – ["&B18&"]"&CHAR(10)&"Fonte: RECORD, "&TEXT(D18,"yyyy")&"." -> Figura n – [Trecho de reportagem da Rede Record, veiculada no programa Domingo Espetacular em 2005.] Fonte: RECORD, 2005. | S18: ="RECORD. ["&B18&"]. "&G18&". "&TEXT(D18,"dd")&" "&LOWER(TEXT(D18,"mmm"))&" "&TEXT(D18,"yyyy")&". "&F18&". Disponível em: <link do dataverse>. Acesso em: 21 mai. 2026." -> RECORD. [Trecho de reportagem da Rede Record, veiculada no programa Domingo Espetacular em 2005.]. São Paulo, Brasil. 17 jul. 2005. Originalmente DVD (suporte físico óptico). Com tratamento, tornou-se arquivo eletrônico (MP4) em suporte digital/nato-digital. Disponível em: <link do dataverse>. Acesso em: 21 mai. 2026. | T18: Este item pertencia à pasta intitulada "Implosão carandiru - noticiário".
A19: =MID(K19, LEN(K19)-6, 3) -> 018 | B19: Trecho de reportagem da Rede Record, veiculada no programa São Paulo no Ar em 2005. | C19: Item | D19: 38550 | E19: 0.0034259259 | F19: Originalmente DVD (suporte físico óptico). Com tratamento, tornou-se arquivo eletrônico (MP4) em suporte digital/nato-digital | G19: São Paulo, Brasil | H19: Grupo de Pesquisa em Direito e Violência de Estado | I19: Notícias - Demolição - Casa de Detenção do Carandiru | J19: Pasta: 0001 | K19: =TEXTJOIN("", TRUE, Geral!B21:V21) -> BR-SPGPDVE_NOTICIAS-DEMOLICAO-CSDTCARANDIRU_AVS-NOT-NDT-DT1_0001-018.mp4 | L19: =Demolicao!$L$2 -> Verificar com a professora Maíra | M19: Demolição dos pavilhões 2 e 5 da casa de detenção do Carandiru. Trecho de reportagem da Rede Record, veiculada no programa São Paulo no Ar em 2005. | N19: =Demolicao!$N$2 -> O acesso aos documentos deste acervo está condicionado ao compromisso de não repassá-los a terceiros, à obrigatoriedade de mencionar que os originais pertencem ao GPDVE (?), e à necessidade de novo Termo de Responsabilidade em caso de reutilização ou uso diverso do inicialmente acordado. O uso está sujeito às restrições previstas na Lei de Arquivos (Lei nº 8.159/1991), na Lei de Direitos Autorais (Lei nº 9.610/1998), nos artigos 138 e 145 do Código Penal, e no artigo 5º, inciso X, da Constituição Federal, especialmente quanto à proteção da honra e imagem de terceiros. A pessoa física ou jurídica responsável assume integral responsabilidade civil e penal por eventuais danos decorrentes do uso das reproduções e informações, eximindo o GPDVE de qualquer responsabilidade. | O19: Sistema prisional; Demolição; Implosão; Casa de Detenção de São Paulo; Carandiru | P19: Audiovisual | Q19: Possivelmente, filmagem digital ou vídeo digital. Optou-se por "não determinado" por incerteza quanto ao processo da técnica. | R19: ="Figura n – ["&B19&"]"&CHAR(10)&"Fonte: RECORD, "&TEXT(D19,"yyyy")&"." -> Figura n – [Trecho de reportagem da Rede Record, veiculada no programa São Paulo no Ar em 2005.] Fonte: RECORD, 2005. | S19: ="RECORD. ["&B19&"]. "&G19&". "&TEXT(D19,"dd")&" "&LOWER(TEXT(D19,"mmm"))&" "&TEXT(D19,"yyyy")&". "&F19&". Disponível em: <link do dataverse>. Acesso em: 21 mai. 2026." -> RECORD. [Trecho de reportagem da Rede Record, veiculada no programa São Paulo no Ar em 2005.]. São Paulo, Brasil. 17 jul. 2005. Originalmente DVD (suporte físico óptico). Com tratamento, tornou-se arquivo eletrônico (MP4) em suporte digital/nato-digital. Disponível em: <link do dataverse>. Acesso em: 21 mai. 2026. | T19: Este item pertencia à pasta intitulada "Implosão carandiru - noticiário".
A20: =MID(K20, LEN(K20)-6, 3) -> 019 | B20: Trecho de reportagem da Rede Record, veiculada no programa Fala Brasil [Parte 2] em 2005. | C20: Item | D20: 38550 | E20: 0.0048148148 | F20: Originalmente DVD (suporte físico óptico). Com tratamento, tornou-se arquivo eletrônico (MP4) em suporte digital/nato-digital | G20: São Paulo, Brasil | H20: Grupo de Pesquisa em Direito e Violência de Estado | I20: Notícias - Demolição - Casa de Detenção do Carandiru | J20: Pasta: 0001 | K20: =TEXTJOIN("", TRUE, Geral!B22:V22) -> BR-SPGPDVE_NOTICIAS-DEMOLICAO-CSDTCARANDIRU_AVS-NOT-NDT-DT1_0001-019.mp4 | L20: =Demolicao!$L$2 -> Verificar com a professora Maíra | M20: Demolição dos pavilhões 2 e 5 da casa de detenção do Carandiru. Trecho de reportagem da Rede Record, veiculada no programa Fala Brasil [Parte 2] em 2005. | N20: =Demolicao!$N$2 -> O acesso aos documentos deste acervo está condicionado ao compromisso de não repassá-los a terceiros, à obrigatoriedade de mencionar que os originais pertencem ao GPDVE (?), e à necessidade de novo Termo de Responsabilidade em caso de reutilização ou uso diverso do inicialmente acordado. O uso está sujeito às restrições previstas na Lei de Arquivos (Lei nº 8.159/1991), na Lei de Direitos Autorais (Lei nº 9.610/1998), nos artigos 138 e 145 do Código Penal, e no artigo 5º, inciso X, da Constituição Federal, especialmente quanto à proteção da honra e imagem de terceiros. A pessoa física ou jurídica responsável assume integral responsabilidade civil e penal por eventuais danos decorrentes do uso das reproduções e informações, eximindo o GPDVE de qualquer responsabilidade. | O20: Sistema prisional; Demolição; Implosão; Casa de Detenção de São Paulo; Carandiru | P20: Audiovisual | Q20: Possivelmente, filmagem digital ou vídeo digital. Optou-se por "não determinado" por incerteza quanto ao processo da técnica. | R20: ="Figura n – ["&B20&"]"&CHAR(10)&"Fonte: RECORD, "&TEXT(D20,"yyyy")&"." -> Figura n – [Trecho de reportagem da Rede Record, veiculada no programa Fala Brasil [Parte 2] em 2005.] Fonte: RECORD, 2005. | S20: ="RECORD. ["&B20&"]. "&G20&". "&TEXT(D20,"dd")&" "&LOWER(TEXT(D20,"mmm"))&" "&TEXT(D20,"yyyy")&". "&F20&". Disponível em: <link do dataverse>. Acesso em: 21 mai. 2026." -> RECORD. [Trecho de reportagem da Rede Record, veiculada no programa Fala Brasil [Parte 2] em 2005.]. São Paulo, Brasil. 17 jul. 2005. Originalmente DVD (suporte físico óptico). Com tratamento, tornou-se arquivo eletrônico (MP4) em suporte digital/nato-digital. Disponível em: <link do dataverse>. Acesso em: 21 mai. 2026. | T20: Este item pertencia à pasta intitulada "Implosão carandiru - noticiário".
A21: =MID(K21, LEN(K21)-6, 3) -> 020 | B21: Trecho de reportagem da RedeTV!, veiculada no programa Esporte Notícias [Parte 1] em 2005. | C21: Item | D21: 38550 | E21: 0.0010300926 | F21: Originalmente DVD (suporte físico óptico). Com tratamento, tornou-se arquivo eletrônico (MP4) em suporte digital/nato-digital | G21: São Paulo, Brasil | H21: Grupo de Pesquisa em Direito e Violência de Estado | I21: Notícias - Demolição - Casa de Detenção do Carandiru | J21: Pasta: 0001 | K21: =TEXTJOIN("", TRUE, Geral!B23:V23) -> BR-SPGPDVE_NOTICIAS-DEMOLICAO-CSDTCARANDIRU_AVS-NOT-NDT-DT1_0001-020.mp4 | L21: =Demolicao!$L$2 -> Verificar com a professora Maíra | M21: Demolição dos pavilhões 2 e 5 da casa de detenção do Carandiru. Trecho de reportagem da RedeTV!, veiculada no programa Esporte Notícias [Parte 1] em 2005. | N21: =Demolicao!$N$2 -> O acesso aos documentos deste acervo está condicionado ao compromisso de não repassá-los a terceiros, à obrigatoriedade de mencionar que os originais pertencem ao GPDVE (?), e à necessidade de novo Termo de Responsabilidade em caso de reutilização ou uso diverso do inicialmente acordado. O uso está sujeito às restrições previstas na Lei de Arquivos (Lei nº 8.159/1991), na Lei de Direitos Autorais (Lei nº 9.610/1998), nos artigos 138 e 145 do Código Penal, e no artigo 5º, inciso X, da Constituição Federal, especialmente quanto à proteção da honra e imagem de terceiros. A pessoa física ou jurídica responsável assume integral responsabilidade civil e penal por eventuais danos decorrentes do uso das reproduções e informações, eximindo o GPDVE de qualquer responsabilidade. | O21: Sistema prisional; Demolição; Implosão; Casa de Detenção de São Paulo; Carandiru | P21: Audiovisual | Q21: Possivelmente, filmagem digital ou vídeo digital. Optou-se por "não determinado" por incerteza quanto ao processo da técnica. | R21: ="Figura n – ["&B21&"]"&CHAR(10)&"Fonte: REDE TV, "&TEXT(D21,"yyyy")&"." -> Figura n – [Trecho de reportagem da RedeTV!, veiculada no programa Esporte Notícias [Parte 1] em 2005.] Fonte: REDE TV, 2005. | S21: ="REDE TV!. ["&B21&"]. "&G21&". "&TEXT(D21,"dd")&" "&LOWER(TEXT(D21,"mmm"))&" "&TEXT(D21,"yyyy")&". "&F21&". Disponível em: <link do dataverse>. Acesso em: 21 mai. 2026." -> REDE TV!. [Trecho de reportagem da RedeTV!, veiculada no programa Esporte Notícias [Parte 1] em 2005.]. São Paulo, Brasil. 17 jul. 2005. Originalmente DVD (suporte físico óptico). Com tratamento, tornou-se arquivo eletrônico (MP4) em suporte digital/nato-digital. Disponível em: <link do dataverse>. Acesso em: 21 mai. 2026. | T21: Este item pertencia à pasta intitulada "Implosão carandiru - noticiário".
