Workbook

Sheet Geral
B1: Local (país) | D1: Local (estado) | E1: Designação do repositório | G1: Designação do conjunto documental | I1: Designação do subconjunto documental | K1: Gênero documental | M1: Espécie/Tipo documental | O1: Técnica de registro | Q1: Forma documental | S1: Unidade de descrição
A2: 1 | B2: BR | C2: - | D2: SP | E2: APESP | F2: _ | G2: DASP | H2: - | I2: PENITPRE-CSDTCARANDIRU | J2: _ | K2: ICO | L2: - | M2: FOT | N2: - | O2: DGZ | P2: - | Q2: MT0 | R2: _ | S2: 3055-005- | T2: 001 | U2: F | V2: .jpg
A3: 2 | B3: BR | C3: - | D3: SP | E3: APESP | F3: _ | G3: DASP | H3: - | I3: PENITPRE-CSDTCARANDIRU | J3: _ | K3: ICO | L3: - | M3: FOT | N3: - | O3: DGZ | P3: - | Q3: MT0 | R3: _ | S3: 3055-005- | T3: 001 | U3: V | V3: .jpg
A4: 3 | B4: BR | C4: - | D4: SP | E4: APESP | F4: _ | G4: DASP | H4: - | I4: PENITPRE-CSDTCARANDIRU | J4: _ | K4: ICO | L4: - | M4: FOT | N4: - | O4: DGZ | P4: - | Q4: MT0 | R4: _ | S4: 3055-005- | T4: 002 | U4: F | V4: .jpg
A5: 4 | B5: BR | C5: - | D5: SP | E5: APESP | F5: _ | G5: DASP | H5: - | I5: PENITPRE-CSDTCARANDIRU | J5: _ | K5: ICO | L5: - | M5: FOT | N5: - | O5: DGZ | P5: - | Q5: MT0 | R5: _ | S5: 3055-005- | T5: 002 | U5: V | V5: .jpg
A6: 5 | B6: BR | C6: - | D6: SP | E6: APESP | F6: _ | G6: DASP | H6: - | I6: PENITPRE-CSDTCARANDIRU | J6: _ | K6: ICO | L6: - | M6: FOT | N6: - | O6: DGZ | P6: - | Q6: MT0 | R6: _ | S6: 3055-005- | T6: 003 | U6: F | V6: .jpg
A7: 6 | B7: BR | C7: - | D7: SP | E7: APESP | F7: _ | G7: DASP | H7: - | I7: PENITPRE-CSDTCARANDIRU | J7: _ | K7: ICO | L7: - | M7: FOT | N7: - | O7: DGZ | P7: - | Q7: MT0 | R7: _ | S7: 3055-005- | T7: 003 | U7: V | V7: .jpg
A8: 7 | B8: BR | C8: - | D8: SP | E8: APESP | F8: _ | G8: DASP | H8: - | I8: PENITPRE-CSDTCARANDIRU | J8: _ | K8: ICO | L8: - | M8: FOT | N8: - | O8: DGZ | P8: - | Q8: MT0 | R8: _ | S8: 3055-005- | T8: 004 | U8: F | V8: .jpg
A9: 8 | B9: BR | C9: - | D9: SP | E9: APESP | F9: _ | G9: DASP | H9: - | I9: PENITPRE-CSDTCARANDIRU | J9: _ | K9: ICO | L9: - | M9: FOT | N9: - | O9: DGZ | P9: - | Q9: MT0 | R9: _ | S9: 3055-005- | T9: 004 | U9: V | V9: .jpg
A10: 9 | B10: BR | C10: - | D10: SP | E10: APESP | F10: _ | G10: DASP | H10: - | I10: PENITPRE-CSDTCARANDIRU | J10: _ | K10: ICO | L10: - | M10: FOT | N10: - | O10: DGZ | P10: - | Q10: MT0 | R10: _ | S10: 3055-005- | T10: 006 | U10: F | V10: .jpg
A11: 10 | B11: BR | C11: - | D11: SP | E11: APESP | F11: _ | G11: DASP | H11: - | I11: PENITPRE-CSDTCARANDIRU | J11: _ | K11: ICO | L11: - | M11: FOT | N11: - | O11: DGZ | P11: - | Q11: MT0 | R11: _ | S11: 3055-005- | T11: 006 | U11: V | V11: .jpg
A12: 11 | B12: BR | C12: - | D12: SP | E12: APESP | F12: _ | G12: DASP | H12: - | I12: PENITPRE-CSDTCARANDIRU | J12: _ | K12: ICO | L12: - | M12: FOT | N12: - | O12: DGZ | P12: - | Q12: MT0 | R12: _ | S12: 3055-005- | T12: 007 | U12: F | V12: .jpg
A13: 12 | B13: BR | C13: - | D13: SP | E13: APESP | F13: _ | G13: DASP | H13: - | I13: PENITPRE-CSDTCARANDIRU | J13: _ | K13: ICO | L13: - | M13: FOT | N13: - | O13: DGZ | P13: - | Q13: MT0 | R13: _ | S13: 3055-005- | T13: 007 | U13: V | V13: .jpg
... A174: 173 | B174: BR | C174: - | D174: SP | E174: APESP | F174: _ | G174: DASP | H174: - | I174: PENITPRE-CSDTCARANDIRU | J174: _ | K174: ICO | L174: - | M174: FOT | N174: - | O174: DGZ | P174: - | Q174: MT0 | R174: _ | S174: 3055-005- | T174: 088 | U174: V | V174: .jpg
A175: 174 | B175: BR | C175: - | D175: SP | E175: APESP | F175: _ | G175: DASP | H175: - | I175: PENITPRE-CSDTCARANDIRU | J175: _ | K175: ICO | L175: - | M175: FOT | N175: - | O175: DGZ | P175: - | Q175: MT0 | S175: 2767-011- | T175: 001 | U175: F | V175: .jpg
A176: 175 | B176: BR | C176: - | D176: SP | E176: APESP | F176: _ | G176: DASP | H176: - | I176: PENITPRE-CSDTCARANDIRU | J176: _ | K176: ICO | L176: - | M176: FOT | N176: - | O176: DGZ | P176: - | Q176: MT0 | R176: _ | S176: 2767-011- | T176: 001 | U176: V | V176: .jpg
A177: 176 | B177: BR | C177: - | D177: SP | E177: APESP | F177: _ | G177: DASP | H177: - | I177: PENITPRE-CSDTCARANDIRU | J177: _ | K177: ICO | L177: - | M177: FOT | N177: - | O177: DGZ | P177: - | Q177: MT0 | R177: _ | S177: 2767-011- | T177: 002 | U177: F | V177: .jpg
A178: 177 | B178: BR | C178: - | D178: SP | E178: APESP | F178: _ | G178: DASP | H178: - | I178: PENITPRE-CSDTCARANDIRU | J178: _ | K178: ICO | L178: - | M178: FOT | N178: - | O178: DGZ | P178: - | Q178: MT0 | R178: _ | S178: 2767-011- | T178: 002 | U178: V | V178: .jpg
A179: 178 | B179: BR | C179: - | D179: SP | E179: APESP | F179: _ | G179: DASP | H179: - | I179: PENITPRE-CSDTCARANDIRU | J179: _ | K179: ICO | L179: - | M179: FOT | N179: - | O179: DGZ | P179: - | Q179: MT0 | R179: _ | S179: 2767-011- | T179: 003 | U179: F | V179: .jpg
A180: 179 | B180: BR | C180: - | D180: SP | E180: APESP | F180: _ | G180: DASP | H180: - | I180: PENITPRE-CSDTCARANDIRU | J180: _ | K180: ICO | L180: - | M180: FOT | N180: - | O180: DGZ | P180: - | Q180: MT0 | R180: _ | S180: 2767-011- | T180: 003 | U180: V | V180: .jpg
A181: 180 | B181: BR | C181: - | D181: SP | E181: APESP | F181: _ | G181: DASP | H181: - | I181: PENITPRE-CSDTCARANDIRU | J181: _ | K181: ICO | L181: - | M181: FOT | N181: - | O181: DGZ | P181: - | Q181: MT0 | R181: _ | S181: 2767-011- | T181: 004 | U181: F | V181: .jpg
A182: 181 | B182: BR | C182: - | D182: SP | E182: APESP | F182: _ | G182: DASP | H182: - | I182: PENITPRE-CSDTCARANDIRU | J182: _ | K182: ICO | L182: - | M182: FOT | N182: - | O182: DGZ | P182: - | Q182: MT0 | R182: _ | S182: 2767-011- | T182: 004 | U182: V | V182: .jpg
A183: 182 | B183: BR | C183: - | D183: SP | E183: APESP | F183: _ | G183: DASP | H183: - | I183: PENITPRE-CSDTCARANDIRU | J183: _ | K183: ICO | L183: - | M183: FOT | N183: - | O183: DGZ | P183: - | Q183: MT0 | R183: _ | S183: 2767-011- | T183: 005 | U183: F | V183: .jpg
A184: 183 | B184: BR | C184: - | D184: SP | E184: APESP | F184: _ | G184: DASP | H184: - | I184: PENITPRE-CSDTCARANDIRU | J184: _ | K184: ICO | L184: - | M184: FOT | N184: - | O184: DGZ | P184: - | Q184: MT0 | R184: _ | S184: 2767-011- | T184: 005 | U184: V | V184: .jpg
A185: 184 | B185: BR | C185: - | D185: SP | E185: APESP | F185: _ | G185: DASP | H185: - | I185: PENITPRE-CSDTCARANDIRU | J185: _ | K185: ICO | L185: - | M185: FOT | N185: - | O185: DGZ | P185: - | Q185: MT0 | R185: _ | S185: 2767-011- | T185: 006 | U185: F | V185: .jpg
A186: 185 | B186: BR | C186: - | D186: SP | E186: APESP | F186: _ | G186: DASP | H186: - | I186: PENITPRE-CSDTCARANDIRU | J186: _ | K186: ICO | L186: - | M186: FOT | N186: - | O186: DGZ | P186: - | Q186: MT0 | R186: _ | S186: 2767-011- | T186: 006 | U186: V | V186: .jpg
A187: 186 | B187: BR | C187: - | D187: SP | E187: APESP | F187: _ | G187: DASP | H187: - | I187: PENITPRE-CSDTCARANDIRU | J187: _ | K187: ICO | L187: - | M187: FOT | N187: - | O187: DGZ | P187: - | Q187: MT0 | R187: _ | S187: 2767-011- | T187: 007 | U187: F | V187: .jpg
... A366: 365 | B366: BR | C366: - | D366: SP | E366: APESP | F366: _ | G366: DASP | H366: - | I366: PENITPRE-CSDTCARANDIRU | J366: _ | K366: ICO | L366: - | M366: FOT | N366: - | O366: DGZ | P366: - | Q366: MT0 | R366: _ | S366: 3055-003- | T366: 030 | U366: V | V366: .jpg

Sheet 3055-005
A1: Cód. | B1: Título descritivo (atribuído) | C1: Nível de descrição | D1: Data de difusão da fotografia (mais antiga contida no verso) | E1: Tamanho | F1: Suporte | G1: Local | H1: Autor/Responsável | I1: Denominação do catálogo temático (APESP DASP) | J1: Localização | K1: Código de referência | L1: História arquivística | M1: Conteúdo/Assunto | N1: Condições de acesso e reprodução | O1: Palavras-chave | P1: Gênero | Q1: Técnica de registro | R1: Legenda para publicações | S1: Citação ABNT | T1: Notas (transcrição das informações do verso)
A2: =RIGHT(K2,3) -> 001 | B2: Av. Cruzeiro do Sul (1979) | C2: Item | D2: 19150 | E2: Gerado pelo Dataverse | F2: Fotografia digitalizada; preto e branco; suporte em papel fotográfico | G2: São Paulo, Brasil | H2: Arquivo Público do Estado de São Paulo, Jornal Diários Associados | I2: Estado De São Paulo - Penitenciárias e Presídios - Casa de Detenção do Carandiru (Fotografias) | J2: Caixa: 3055 Folder: 5 | K2: =TEXTJOIN("", TRUE, Geral!B2:T2) -> BR-SPAPESP_DASP-PENITPRE-CSDTCARANDIRU_ICO-FOT-DGZ-MT0_3055-005-001 | L2: A Casa de Detenção de São Paulo, conhecida como Carandiru, foi formalmente criada em 1938 por decreto do interventor Adhemar de Barros, embora ainda instalada no edifício da Avenida Tiradentes. Sua implantação no bairro do Carandiru só se iniciou décadas depois, quando o governo estadual contratou, em 1951, o Escritório Técnico Ramos de Azevedo, Severo & Villares para projetar e conduzir a construção do novo complexo penitenciário em terreno contíguo à Penitenciária do Estado. As obras avançaram de forma modular, e o primeiro edifício concluído — o Pavilhão 2 — foi inaugurado em 1956, marcando a abertura parcial da chamada “Nova Casa de Detenção”. Ao longo dos anos seguintes, novos pavilhões foram sendo erguidos e inaugurados, compondo um conjunto arquitetônico que se consolidaria como um dos principais símbolos do sistema prisional paulista no século XX. Esta fotografia integra o fundo documental do grupo Diários Associados do Estado de São Paulo (DASP), custodiado pelo Arquivo Público do Estado de São Paulo (APESP), e registra aspectos desse prolongado processo de criação (1938), construção (a partir de 1951) e inauguração (a partir de 1956) da Casa de Detenção, conforme aponta a pesquisa de Maíra Rocha Machado, Bianca Tavolari e Maira Rosín (2025)[1]. | M2: Fotografia em preto e branco mostrando a fachada principal da Casa de Detenção, com a inscrição “CASA DE DETENÇÃO” visível na parte superior da imagem. No primeiro plano, observam-se pessoas reunidas junto ao portão de entrada e dois veículos estacionados. Iluminação artificial, tomada noturna ou ao entardecer. | N2: O acesso aos documentos deste acervo está condicionado ao compromisso de não repassá-los a terceiros, à obrigatoriedade de mencionar que os originais pertencem ao Arquivo Público do Estado de São Paulo, e à necessidade de novo Termo de Responsabilidade em caso de reutilização ou uso diverso do inicialmente acordado. O uso está sujeito às restrições previstas na Lei de Arquivos (Lei nº 8.159/1991), na Lei de Direitos Autorais (Lei nº 9.610/1998), nos artigos 138 e 145 do Código Penal, e no artigo 5º, inciso X, da Constituição Federal, especialmente quanto à proteção da honra e imagem de terceiros. A pessoa física ou jurídica responsável assume integral responsabilidade civil e penal por eventuais danos decorrentes do uso das reproduções e informações, eximindo o Arquivo Público do Estado de São Paulo de qualquer responsabilidade. | O2: Sistema prisional; Arquitetura prisional; Casa de Detenção de São Paulo; Carandiru; Fotografia documental. | P2: Fotografia (Iconográfico) | Q2: Digitalização de fotografia em preto e branco (analógica original) | R2: ="Figura n – ["&B2&"]"&CHAR(10)&"Fonte: Arquivo do Estado de São Paulo, "&TEXT(D2,"yyyy")&"." -> Figura n – [Av. Cruzeiro do Sul (1979)] Fonte: Arquivo do Estado de São Paulo, 1952. | S2: ="ARQUIVO PÚBLICO DO ESTADO DE SÃO PAULO (Brasil). ["&B2&"]. "&G2&". "&TEXT(D2,"dd")&" "&LOWER(TEXT(D2,"mmm"))&" "&TEXT(D2,"yyyy")&". "&F2&". Disponível em: <link do dataverse>. Acesso em: 28 out. 2025." -> ARQUIVO PÚBLICO DO ESTADO DE SÃO PAULO (Brasil). [Av. Cruzeiro do Sul (1979)]. São Paulo, Brasil. 05 jun. 1952. Fotografia digitalizada; preto e branco; suporte em papel fotográfico. Disponível em: <link do dataverse>. Acesso em: 28 out. 2025. | T2: Estado de São Paulo – XXXXX penitenciárias e presídios – Casa de Detenção DN – 23/06/1979
A3: =RIGHT(K3,3) -> 002 | B3: Sentinela em passarela de vigilância — Casa de Detenção (Carandiru) em 1979 | C3: Item | D3: 19150 | E3: Gerado pelo Dataverse | F3: Fotografia digitalizada; preto e branco; suporte em papel fotográfico | G3: São Paulo, Brasil | H3: Arquivo Público do Estado de São Paulo, Jornal Diários Associados | I3: Estado De São Paulo - Penitenciárias e Presídios - Casa de Detenção do Carandiru (Fotografias) | J3: Caixa: 3055 Folder: 5 | K3: =TEXTJOIN("", TRUE, Geral!B4:T4) -> BR-SPAPESP_DASP-PENITPRE-CSDTCARANDIRU_ICO-FOT-DGZ-MT0_3055-005-002 | L3: =$L$2 -> A Casa de Detenção de São Paulo, conhecida como Carandiru, foi formalmente criada em 1938 por decreto do interventor Adhemar de Barros, embora ainda instalada no edifício da Avenida Tiradentes. Sua implantação no bairro do Carandiru só se iniciou décadas depois, quando o governo estadual contratou, em 1951, o Escritório Técnico Ramos de Azevedo, Severo & Villares para projetar e conduzir a construção do novo complexo penitenciário em terreno contíguo à Penitenciária do Estado. As obras avançaram de forma modular, e o primeiro edifício concluído — o Pavilhão 2 — foi inaugurado em 1956, marcando a abertura parcial da chamada “Nova Casa de Detenção”. Ao longo dos anos seguintes, novos pavilhões foram sendo erguidos e inaugurados, compondo um conjunto arquitetônico que se consolidaria como um dos principais símbolos do sistema prisional paulista no século XX. Esta fotografia integra o fundo documental do grupo Diários Associados do Estado de São Paulo (DASP), custodiado pelo Arquivo Público do Estado de São Paulo (APESP), e registra aspectos desse prolongado processo de criação (1938), construção (a partir de 1951) e inauguração (a partir de 1956) da Casa de Detenção, conforme aponta a pesquisa de Maíra Rocha Machado, Bianca Tavolari e Maira Rosín (2025)[1]. | M3: Fotografia em preto e branco retratando um agente de segurança armado caminhando sobre uma passarela elevada junto à fachada de um dos pavilhões da Casa de Detenção. A construção exibe janelas gradeadas e estrutura de concreto que caracteriza a arquitetura prisional. | N3: O acesso aos documentos deste acervo está condicionado ao compromisso de não repassá-los a terceiros, à obrigatoriedade de mencionar que os originais pertencem ao Arquivo Público do Estado de São Paulo, e à necessidade de novo Termo de Responsabilidade em caso de reutilização ou uso diverso do inicialmente acordado. O uso está sujeito às restrições previstas na Lei de Arquivos (Lei nº 8.159/1991), na Lei de Direitos Autorais (Lei nº 9.610/1998), nos artigos 138 e 145 do Código Penal, e no artigo 5º, inciso X, da Constituição Federal, especialmente quanto à proteção da honra e imagem de terceiros. A pessoa física ou jurídica responsável assume integral responsabilidade civil e penal por eventuais danos decorrentes do uso das reproduções e informações, eximindo o Arquivo Público do Estado de São Paulo de qualquer responsabilidade. | O3: Sistema prisional; Vigilância penitenciária; Segurança prisional; Arquitetura carcerária; Casa de Detenção de São Paulo; Carandiru. | P3: Fotografia (Iconográfico) | Q3: Digitalização de fotografia em preto e branco (analógica original) | R3: ="Figura n – ["&B3&"]"&CHAR(10)&"Fonte: Arquivo do Estado de São Paulo, "&TEXT(D3,"yyyy")&"." -> Figura n – [Sentinela em passarela de vigilância — Casa de Detenção (Carandiru) em 1979] Fonte: Arquivo do Estado de São Paulo, 1952. | S3: ="ARQUIVO PÚBLICO DO ESTADO DE SÃO PAULO (Brasil). ["&B3&"]. "&G3&". "&TEXT(D3,"dd")&" "&LOWER(TEXT(D3,"mmm"))&" "&TEXT(D3,"yyyy")&". "&F3&". Disponível em: <link do dataverse>. Acesso em: 28 out. 2025." -> ARQUIVO PÚBLICO DO ESTADO DE SÃO PAULO (Brasil). [Sentinela em passarela de vigilância — Casa de Detenção (Carandiru) em 1979]. São Paulo, Brasil. 05 jun. 1952. Fotografia digitalizada; preto e branco; suporte em papel fotográfico. Disponível em: <link do dataverse>. Acesso em: 28 out. 2025. | T3: Estado de São Paulo – Penitenciárias e presídios – Casa de Detenção Vista parcial da Detenção. DN – 16/02/1979
A4: =RIGHT(K4,3) -> 003 | B4: Celebração da Páscoa na Casa de Detenção (Carandiru) em 1963 | C4: Item | D4: 19150 | E4: Gerado pelo Dataverse | F4: Fotografia digitalizada; preto e branco; suporte em papel fotográfico | G4: São Paulo, Brasil | H4: Arquivo Público do Estado de São Paulo, Jornal Diários Associados | I4: Estado De São Paulo - Penitenciárias e Presídios - Casa de Detenção do Carandiru (Fotografias) | J4: Caixa: 3055 Folder: 5 | K4: =TEXTJOIN("", TRUE, Geral!B6:T6) -> BR-SPAPESP_DASP-PENITPRE-CSDTCARANDIRU_ICO-FOT-DGZ-MT0_3055-005-003 | L4: =$L$2 -> A Casa de Detenção de São Paulo, conhecida como Carandiru, foi formalmente criada em 1938 por decreto do interventor Adhemar de Barros, embora ainda instalada no edifício da Avenida Tiradentes. Sua implantação no bairro do Carandiru só se iniciou décadas depois, quando o governo estadual contratou, em 1951, o Escritório Técnico Ramos de Azevedo, Severo & Villares para projetar e conduzir a construção do novo complexo penitenciário em terreno contíguo à Penitenciária do Estado. As obras avançaram de forma modular, e o primeiro edifício concluído — o Pavilhão 2 — foi inaugurado em 1956, marcando a abertura parcial da chamada “Nova Casa de Detenção”. Ao longo dos anos seguintes, novos pavilhões foram sendo erguidos e inaugurados, compondo um conjunto arquitetônico que se consolidaria como um dos principais símbolos do sistema prisional paulista no século XX. Esta fotografia integra o fundo documental do grupo Diários Associados do Estado de São Paulo (DASP), custodiado pelo Arquivo Público do Estado de São Paulo (APESP), e registra aspectos desse prolongado processo de criação (1938), construção (a partir de 1951) e inauguração (a partir de 1956) da Casa de Detenção, conforme aponta a pesquisa de Maíra Rocha Machado, Bianca Tavolari e Maira Rosín (2025)[1]. | M4: Fotografia em preto e branco registra a celebração da comunhão pascal dos detentos da Casa de Detenção do Carandiru, realizada em 7 de julho de 1963. A cerimônia litúrgica ocorre em área interna do complexo, diante do pátio da Capela de Nossa Senhora Aparecida. Em primeiro plano, um altar improvisado com toalha branca e arranjo floral serve de ponto focal para o ofício conduzido pelo padre Paulo Ruffier, capelão da Penitenciária do Estado. Participam da celebração freiras, mulheres e homens em trajes formais, dispostos em atitude reverente. Ao fundo, vê-se o pátio cercado por galerias com janelas gradeadas, decorado com bandeirolas, compondo um cenário de fé e solenidade em meio ao ambiente prisional. | N4: O acesso aos documentos deste acervo está condicionado ao compromisso de não repassá-los a terceiros, à obrigatoriedade de mencionar que os originais pertencem ao Arquivo Público do Estado de São Paulo, e à necessidade de novo Termo de Responsabilidade em caso de reutilização ou uso diverso do inicialmente acordado. O uso está sujeito às restrições previstas na Lei de Arquivos (Lei nº 8.159/1991), na Lei de Direitos Autorais (Lei nº 9.610/1998), nos artigos 138 e 145 do Código Penal, e no artigo 5º, inciso X, da Constituição Federal, especialmente quanto à proteção da honra e imagem de terceiros. A pessoa física ou jurídica responsável assume integral responsabilidade civil e penal por eventuais danos decorrentes do uso das reproduções e informações, eximindo o Arquivo Público do Estado de São Paulo de qualquer responsabilidade. | O4: Sistema prisional; Assistência religiosa; Cerimônias católicas; Vida institucional; Casa de Detenção de São Paulo; Carandiru. | P4: Fotografia (Iconográfico) | Q4: Digitalização de fotografia em preto e branco (analógica original) | R4: ="Figura n – ["&B4&"]"&CHAR(10)&"Fonte: Arquivo do Estado de São Paulo, "&TEXT(D4,"yyyy")&"." -> Figura n – [Celebração da Páscoa na Casa de Detenção (Carandiru) em 1963] Fonte: Arquivo do Estado de São Paulo, 1952. | S4: ="ARQUIVO PÚBLICO DO ESTADO DE SÃO PAULO (Brasil). ["&B4&"]. "&G4&". "&TEXT(D4,"dd")&" "&LOWER(TEXT(D4,"mmm"))&" "&TEXT(D4,"yyyy")&". "&F4&". Disponível em: <link do dataverse>. Acesso em: 28 out. 2025." -> ARQUIVO PÚBLICO DO ESTADO DE SÃO PAULO (Brasil). [Celebração da Páscoa na Casa de Detenção (Carandiru) em 1963]. São Paulo, Brasil. 05 jun. 1952. Fotografia digitalizada; preto e branco; suporte em papel fotográfico. Disponível em: <link do dataverse>. Acesso em: 28 out. 2025. | T4: Penitenciárias e presídios – Casa de Detenção do Carandiru Detentos tiveram a sua comunhão pascal Aspecto da Páscoa dos detentos da Casa de Detenção do Carandiru, ontem realizada. DN. 1ª Ed., 8/7/1963 - wpj Reverentes, concentrados e em absoluto silêncio, os detentos recolhidos no Pavilhão n. 8 da Casa de Detenção fizeram na manhã de ontem a sua comunhão pascal. A cerimonia litúrgica, que se constituiu num admirável espetáculo de fé cristã, foi celebrada defronte ao pátio da Capela de Nossa Senhora Aparecida, pelo pe. Paulo Ruffier, capelão da Penitenciária do Estado.
A5: =RIGHT(K5,3) -> 004 | B5: Mulheres em atividade de artesanato em cômodo com decoração religiosa na Casa de Detenção (Carandiru) em 1963 | C5: Item | D5: 19312 | E5: Gerado pelo Dataverse | F5: Fotografia digitalizada; preto e branco; suporte em papel fotográfico | G5: São Paulo, Brasil | H5: Arquivo Público do Estado de São Paulo, Jornal Diários Associados | I5: Estado De São Paulo - Penitenciárias e Presídios - Casa de Detenção do Carandiru (Fotografias) | J5: Caixa: 3055 Folder: 5 | K5: =TEXTJOIN("", TRUE, Geral!B8:T8) -> BR-SPAPESP_DASP-PENITPRE-CSDTCARANDIRU_ICO-FOT-DGZ-MT0_3055-005-004 | L5: =$L$2 -> A Casa de Detenção de São Paulo, conhecida como Carandiru, foi formalmente criada em 1938 por decreto do interventor Adhemar de Barros, embora ainda instalada no edifício da Avenida Tiradentes. Sua implantação no bairro do Carandiru só se iniciou décadas depois, quando o governo estadual contratou, em 1951, o Escritório Técnico Ramos de Azevedo, Severo & Villares para projetar e conduzir a construção do novo complexo penitenciário em terreno contíguo à Penitenciária do Estado. As obras avançaram de forma modular, e o primeiro edifício concluído — o Pavilhão 2 — foi inaugurado em 1956, marcando a abertura parcial da chamada “Nova Casa de Detenção”. Ao longo dos anos seguintes, novos pavilhões foram sendo erguidos e inaugurados, compondo um conjunto arquitetônico que se consolidaria como um dos principais símbolos do sistema prisional paulista no século XX. Esta fotografia integra o fundo documental do grupo Diários Associados do Estado de São Paulo (DASP), custodiado pelo Arquivo Público do Estado de São Paulo (APESP), e registra aspectos desse prolongado processo de criação (1938), construção (a partir de 1951) e inauguração (a partir de 1956) da Casa de Detenção, conforme aponta a pesquisa de Maíra Rocha Machado, Bianca Tavolari e Maira Rosín (2025)[1]. | M5: A imagem em preto e branco mostra um grupo de seis mulheres (quatro brancas e duas negras) reunidas em uma mesa de trabalho. Elas parecem concentradas em atividades manuais, talvez de corte, desenho ou modelagem de moldes — há réguas, papéis e ferramentas sobre a mesa. No centro da composição, ao fundo, há um crucifixo fixado na parede, logo acima da mesa. As mulheres usam roupas simples e claras, o que reforça uma atmosfera de disciplina e uniformidade. | N5: O acesso aos documentos deste acervo está condicionado ao compromisso de não repassá-los a terceiros, à obrigatoriedade de mencionar que os originais pertencem ao Arquivo Público do Estado de São Paulo, e à necessidade de novo Termo de Responsabilidade em caso de reutilização ou uso diverso do inicialmente acordado. O uso está sujeito às restrições previstas na Lei de Arquivos (Lei nº 8.159/1991), na Lei de Direitos Autorais (Lei nº 9.610/1998), nos artigos 138 e 145 do Código Penal, e no artigo 5º, inciso X, da Constituição Federal, especialmente quanto à proteção da honra e imagem de terceiros. A pessoa física ou jurídica responsável assume integral responsabilidade civil e penal por eventuais danos decorrentes do uso das reproduções e informações, eximindo o Arquivo Público do Estado de São Paulo de qualquer responsabilidade. | O5: Trabalho feminino; religião e cárcere; oficinas de artesanato; ressocialização. | P5: Fotografia (Iconográfico) | Q5: Digitalização de fotografia em preto e branco (analógica original) | R5: ="Figura n – ["&B5&"]"&CHAR(10)&"Fonte: Arquivo do Estado de São Paulo, "&TEXT(D5,"yyyy")&"." -> Figura n – [Mulheres em atividade de artesanato em cômodo com decoração religiosa na Casa de Detenção (Carandiru) em 1963] Fonte: Arquivo do Estado de São Paulo, 1952. | S5: ="ARQUIVO PÚBLICO DO ESTADO DE SÃO PAULO (Brasil). ["&B5&"]. "&G5&". "&TEXT(D5,"dd")&" "&LOWER(TEXT(D5,"mmm"))&" "&TEXT(D5,"yyyy")&". "&F5&". Disponível em: <link do dataverse>. Acesso em: 28 out. 2025." -> ARQUIVO PÚBLICO DO ESTADO DE SÃO PAULO (Brasil). [Mulheres em atividade de artesanato em cômodo com decoração religiosa na Casa de Detenção (Carandiru) em 1963]. São Paulo, Brasil. 14 nov. 1952. Fotografia digitalizada; preto e branco; suporte em papel fotográfico. Disponível em: <link do dataverse>. Acesso em: 28 out. 2025. | T5: Estado de São Paulo – Casa de Detenção do Carandiru Detentas do presidio do Carandirú, são preparadas pela Madre do Divino Salvador, para retornar ao convívio da sociedade. Recebem um pecúlio e os ensinamentos necessários para enfrentar a vida nas grandes cidades. Arq. 24/1/1963
A6: =RIGHT(K6,3) -> 006 | B6: Autoridades de gravata e de farda cruzam portões da Casa de Detenção “por ocasião de sua inauguração”, conforme legenda (12.11.1956) | C6: Item | D6: 20086 | E6: Gerado pelo Dataverse | F6: Fotografia digitalizada; preto e branco; suporte em papel fotográfico | G6: São Paulo, Brasil | H6: Arquivo Público do Estado de São Paulo, Jornal Diários Associados | I6: Estado De São Paulo - Penitenciárias e Presídios - Casa de Detenção do Carandiru (Fotografias) | J6: Caixa: 3055 Folder: 5 | K6: =TEXTJOIN("", TRUE, Geral!B10:T10) -> BR-SPAPESP_DASP-PENITPRE-CSDTCARANDIRU_ICO-FOT-DGZ-MT0_3055-005-006 | L6: =$L$2 -> A Casa de Detenção de São Paulo, conhecida como Carandiru, foi formalmente criada em 1938 por decreto do interventor Adhemar de Barros, embora ainda instalada no edifício da Avenida Tiradentes. Sua implantação no bairro do Carandiru só se iniciou décadas depois, quando o governo estadual contratou, em 1951, o Escritório Técnico Ramos de Azevedo, Severo & Villares para projetar e conduzir a construção do novo complexo penitenciário em terreno contíguo à Penitenciária do Estado. As obras avançaram de forma modular, e o primeiro edifício concluído — o Pavilhão 2 — foi inaugurado em 1956, marcando a abertura parcial da chamada “Nova Casa de Detenção”. Ao longo dos anos seguintes, novos pavilhões foram sendo erguidos e inaugurados, compondo um conjunto arquitetônico que se consolidaria como um dos principais símbolos do sistema prisional paulista no século XX. Esta fotografia integra o fundo documental do grupo Diários Associados do Estado de São Paulo (DASP), custodiado pelo Arquivo Público do Estado de São Paulo (APESP), e registra aspectos desse prolongado processo de criação (1938), construção (a partir de 1951) e inauguração (a partir de 1956) da Casa de Detenção, conforme aponta a pesquisa de Maíra Rocha Machado, Bianca Tavolari e Maira Rosín (2025)[1]. | M6: Imagem em preto e branco registra autoridades civis e militares em deslocamento por área externa do complexo penitenciário do Carandiru, em São Paulo. À frente do grupo, homens trajando ternos e uniformes dialogam enquanto atravessam um portão de ferro. A cena documenta um momento da inauguração oficial do novo pavilhão da Casa de Detenção, realizada em 12 de setembro de 1956, nos terrenos da Penitenciária do Estado, na avenida General Ataliba Leonel. Presentes estavam representantes do Judiciário, da Segurança Pública, da Justiça, da Guarda Civil, da Força Pública, da Polícia Feminina e de comandos militares da região. | N6: O acesso aos documentos deste acervo está condicionado ao compromisso de não repassá-los a terceiros, à obrigatoriedade de mencionar que os originais pertencem ao Arquivo Público do Estado de São Paulo, e à necessidade de novo Termo de Responsabilidade em caso de reutilização ou uso diverso do inicialmente acordado. O uso está sujeito às restrições previstas na Lei de Arquivos (Lei nº 8.159/1991), na Lei de Direitos Autorais (Lei nº 9.610/1998), nos artigos 138 e 145 do Código Penal, e no artigo 5º, inciso X, da Constituição Federal, especialmente quanto à proteção da honra e imagem de terceiros. A pessoa física ou jurídica responsável assume integral responsabilidade civil e penal por eventuais danos decorrentes do uso das reproduções e informações, eximindo o Arquivo Público do Estado de São Paulo de qualquer responsabilidade. | O6: Administração penitenciária; visita institucional; segurança pública; Carandiru; autoridades civis e militares. | P6: Fotografia (Iconográfico) | Q6: Digitalização de fotografia em preto e branco (analógica original) | R6: ="Figura n – ["&B6&"]"&CHAR(10)&"Fonte: Arquivo do Estado de São Paulo, "&TEXT(D6,"yyyy")&"." -> Figura n – [Autoridades de gravata e de farda cruzam portões da Casa de Detenção “por ocasião de sua inauguração”, conforme legenda (12.11.1956)] Fonte: Arquivo do Estado de São Paulo, 1954. | S6: ="ARQUIVO PÚBLICO DO ESTADO DE SÃO PAULO (Brasil). ["&B6&"]. "&G6&". "&TEXT(D6,"dd")&" "&LOWER(TEXT(D6,"mmm"))&" "&TEXT(D6,"yyyy")&". "&F6&". Disponível em: <link do dataverse>. Acesso em: 28 out. 2025." -> ARQUIVO PÚBLICO DO ESTADO DE SÃO PAULO (Brasil). [Autoridades de gravata e de farda cruzam portões da Casa de Detenção “por ocasião de sua inauguração”, conforme legenda (12.11.1956)]. São Paulo, Brasil. 28 dez. 1954. Fotografia digitalizada; preto e branco; suporte em papel fotográfico. Disponível em: <link do dataverse>. Acesso em: 28 out. 2025. | T6: Estado de São Paulo - Penitenciárias e Presídios – Casa de Detenção - Carandiru Realizou-se a inauguração oficial do novo pavilhão da Casa de Detenção, construído nos terrenos da Penitenciária do Estado. Da inauguração é o flagrante. DN, ed. 12/9/1956 Inaugurado um pavilhão na nova Casa de Detenção – Realizou-se ontem a inauguração oficial do novo pavilhão da Casa de Detenção, construído nos terrenos da Penitenciária do Estado, na Avenida General Ataliba Leonel. O edifício, que estava praticamente terminado há algum tempo, necessitava de obras complementares externas, bem como do aparelhamento indispensável para o seu funcionamento. Ainda assim, porém, parte do prédio vinha sendo utilizada há alguns meses, sendo ali alojados parte dos detentos — os mais perigosos — que se achavam no Presídio do Hipódromo ou na Casa de Detenção. O novo pavilhão, que faz parte de um conjunto a ser construído o mais rapidamente possível, tem capacidade para 500 presos, alojados em quatro pavimentos distintos. Ao ato inaugural compareceram o juiz das Execuções Criminais, sr. Valentim Alves da Silva; o sr. Nereu César de Morais, diretor-geral dos Presídios; o sr. Carlos Eugênio Bittencourt da Fonseca, secretário da Segurança Pública; o sr. Lincoln Feliciano, secretário da Justiça; a diretoria da Guarda Civil; o comandante da Força Pública; representantes do comando da 2ª Região Militar e da Zona Militar Centro; delegados auxiliares, especializados e de distritos; bem como a diretora da Polícia Feminina. O clichê fixa aspecto tomado durante a solenidade.
A7: =RIGHT(K7,3) -> 007 | B7: Repórter examinando o colchão cujos panos foram utilizados para a produção de uma corda para a fuga de detentos da Casa de Detenção (Carandiru) em 1956 | C7: Item | D7: 20086 | E7: Gerado pelo Dataverse | F7: Fotografia digitalizada; preto e branco; suporte em papel fotográfico | G7: São Paulo, Brasil | H7: Arquivo Público do Estado de São Paulo, Jornal Diários Associados | I7: Estado De São Paulo - Penitenciárias e Presídios - Casa de Detenção do Carandiru (Fotografias) | J7: Caixa: 3055 Folder: 5 | K7: =TEXTJOIN("", TRUE, Geral!B12:T12) -> BR-SPAPESP_DASP-PENITPRE-CSDTCARANDIRU_ICO-FOT-DGZ-MT0_3055-005-007 | L7: =$L$2 -> A Casa de Detenção de São Paulo, conhecida como Carandiru, foi formalmente criada em 1938 por decreto do interventor Adhemar de Barros, embora ainda instalada no edifício da Avenida Tiradentes. Sua implantação no bairro do Carandiru só se iniciou décadas depois, quando o governo estadual contratou, em 1951, o Escritório Técnico Ramos de Azevedo, Severo & Villares para projetar e conduzir a construção do novo complexo penitenciário em terreno contíguo à Penitenciária do Estado. As obras avançaram de forma modular, e o primeiro edifício concluído — o Pavilhão 2 — foi inaugurado em 1956, marcando a abertura parcial da chamada “Nova Casa de Detenção”. Ao longo dos anos seguintes, novos pavilhões foram sendo erguidos e inaugurados, compondo um conjunto arquitetônico que se consolidaria como um dos principais símbolos do sistema prisional paulista no século XX. Esta fotografia integra o fundo documental do grupo Diários Associados do Estado de São Paulo (DASP), custodiado pelo Arquivo Público do Estado de São Paulo (APESP), e registra aspectos desse prolongado processo de criação (1938), construção (a partir de 1951) e inauguração (a partir de 1956) da Casa de Detenção, conforme aponta a pesquisa de Maíra Rocha Machado, Bianca Tavolari e Maira Rosín (2025)[1]. | M7: Fotografia em preto e branco mostra uma pessoa curvada dentro de uma cela da Casa de Detenção do Carandiru, ao lado de um monte de palha. Sobre a palha, repousam um colchão listrado e tecidos, evidenciando improviso nas condições de repouso. O ambiente revela aspectos da precariedade estrutural do sistema prisional à época. O registro está relacionado à fuga de quatro detentos, ocorrida na madrugada de 6 de julho de 1956, quando lençóis e partes de colchões foram utilizados na confecção de uma corda improvisada. | N7: O acesso aos documentos deste acervo está condicionado ao compromisso de não repassá-los a terceiros, à obrigatoriedade de mencionar que os originais pertencem ao Arquivo Público do Estado de São Paulo, e à necessidade de novo Termo de Responsabilidade em caso de reutilização ou uso diverso do inicialmente acordado. O uso está sujeito às restrições previstas na Lei de Arquivos (Lei nº 8.159/1991), na Lei de Direitos Autorais (Lei nº 9.610/1998), nos artigos 138 e 145 do Código Penal, e no artigo 5º, inciso X, da Constituição Federal, especialmente quanto à proteção da honra e imagem de terceiros. A pessoa física ou jurídica responsável assume integral responsabilidade civil e penal por eventuais danos decorrentes do uso das reproduções e informações, eximindo o Arquivo Público do Estado de São Paulo de qualquer responsabilidade. | O7: Fuga de detentos; Cela (Prisional); Precariedade estrutural; Colchão improvisado; Palha (Leito); Reporter examinando; Carandiru; Incidentes de segurança; Meios de fuga; Cotidiano carcerário. | P7: Fotografia (Iconográfico) | Q7: Digitalização de fotografia em preto e branco (analógica original) | R7: ="Figura n – ["&B7&"]"&CHAR(10)&"Fonte: Arquivo do Estado de São Paulo, "&TEXT(D7,"yyyy")&"." -> Figura n – [Repórter examinando o colchão cujos panos foram utilizados para a produção de uma corda para a fuga de detentos da Casa de Detenção (Carandiru) em 1956] Fonte: Arquivo do Estado de São Paulo, 1954. | S7: ="ARQUIVO PÚBLICO DO ESTADO DE SÃO PAULO (Brasil). ["&B7&"]. "&G7&". "&TEXT(D7,"dd")&" "&LOWER(TEXT(D7,"mmm"))&" "&TEXT(D7,"yyyy")&". "&F7&". Disponível em: <link do dataverse>. Acesso em: 28 out. 2025." -> ARQUIVO PÚBLICO DO ESTADO DE SÃO PAULO (Brasil). [Repórter examinando o colchão cujos panos foram utilizados para a produção de uma corda para a fuga de detentos da Casa de Detenção (Carandiru) em 1956]. São Paulo, Brasil. 28 dez. 1954. Fotografia digitalizada; preto e branco; suporte em papel fotográfico. Disponível em: <link do dataverse>. Acesso em: 28 out. 2025. | T7: Estado de São Paulo - Penitenciárias e Presídios – Casa de Detenção Carandiru Quatro delinquentes fugiram de madrugada da Casa de Detenção O repórter examina o colchão que foi destruído pelos fugitivos, cujo pano aproveitaram para reforçar a improvisada corda feita com lençóis. DN, 1ª ed., 6/7/1956 – W
A8: =RIGHT(K8,3) -> 008 | B8: Mulheres em atividade de artesanato em ambiente com elementos religiosos na Casa de Detenção (Carandiru), 1963 | C8: Item | D8: 20116 | E8: Gerado pelo Dataverse | F8: Fotografia digitalizada; preto e branco; suporte em papel fotográfico | G8: São Paulo, Brasil | H8: Arquivo Público do Estado de São Paulo, Jornal Diários Associados | I8: Estado De São Paulo - Penitenciárias e Presídios - Casa de Detenção do Carandiru (Fotografias) | J8: Caixa: 3055 Folder: 5 | K8: =TEXTJOIN("", TRUE, Geral!B14:T14) -> BR-SPAPESP_DASP-PENITPRE-CSDTCARANDIRU_ICO-FOT-DGZ-MT0_3055-005-008 | L8: =$L$2 -> A Casa de Detenção de São Paulo, conhecida como Carandiru, foi formalmente criada em 1938 por decreto do interventor Adhemar de Barros, embora ainda instalada no edifício da Avenida Tiradentes. Sua implantação no bairro do Carandiru só se iniciou décadas depois, quando o governo estadual contratou, em 1951, o Escritório Técnico Ramos de Azevedo, Severo & Villares para projetar e conduzir a construção do novo complexo penitenciário em terreno contíguo à Penitenciária do Estado. As obras avançaram de forma modular, e o primeiro edifício concluído — o Pavilhão 2 — foi inaugurado em 1956, marcando a abertura parcial da chamada “Nova Casa de Detenção”. Ao longo dos anos seguintes, novos pavilhões foram sendo erguidos e inaugurados, compondo um conjunto arquitetônico que se consolidaria como um dos principais símbolos do sistema prisional paulista no século XX. Esta fotografia integra o fundo documental do grupo Diários Associados do Estado de São Paulo (DASP), custodiado pelo Arquivo Público do Estado de São Paulo (APESP), e registra aspectos desse prolongado processo de criação (1938), construção (a partir de 1951) e inauguração (a partir de 1956) da Casa de Detenção, conforme aponta a pesquisa de Maíra Rocha Machado, Bianca Tavolari e Maira Rosín (2025)[1]. | M8: A imagem em preto e branco mostra um grupo de seis mulheres (quatro brancas e duas negras) reunidas em uma mesa de trabalho. Elas parecem concentradas em atividades manuais, talvez de corte, desenho ou modelagem de moldes — há réguas, papéis e ferramentas sobre a mesa. No centro da composição, ao fundo, há um crucifixo fixado na parede, logo acima da mesa. As mulheres usam roupas simples e claras, o que reforça uma atmosfera de disciplina e uniformidade. | N8: O acesso aos documentos deste acervo está condicionado ao compromisso de não repassá-los a terceiros, à obrigatoriedade de mencionar que os originais pertencem ao Arquivo Público do Estado de São Paulo, e à necessidade de novo Termo de Responsabilidade em caso de reutilização ou uso diverso do inicialmente acordado. O uso está sujeito às restrições previstas na Lei de Arquivos (Lei nº 8.159/1991), na Lei de Direitos Autorais (Lei nº 9.610/1998), nos artigos 138 e 145 do Código Penal, e no artigo 5º, inciso X, da Constituição Federal, especialmente quanto à proteção da honra e imagem de terceiros. A pessoa física ou jurídica responsável assume integral responsabilidade civil e penal por eventuais danos decorrentes do uso das reproduções e informações, eximindo o Arquivo Público do Estado de São Paulo de qualquer responsabilidade. | O8: Trabalho feminino; religião e cárcere; oficinas de artesanato; ressocialização. | P8: Fotografia (Iconográfico) | Q8: Digitalização de fotografia em preto e branco (analógica original) | R8: ="Figura n – ["&B8&"]"&CHAR(10)&"Fonte: Arquivo do Estado de São Paulo, "&TEXT(D8,"yyyy")&"." -> Figura n – [Mulheres em atividade de artesanato em ambiente com elementos religiosos na Casa de Detenção (Carandiru), 1963] Fonte: Arquivo do Estado de São Paulo, 1955. | S8: ="ARQUIVO PÚBLICO DO ESTADO DE SÃO PAULO (Brasil). ["&B8&"]. "&G8&". "&TEXT(D8,"dd")&" "&LOWER(TEXT(D8,"mmm"))&" "&TEXT(D8,"yyyy")&". "&F8&". Disponível em: <link do dataverse>. Acesso em: 28 out. 2025." -> ARQUIVO PÚBLICO DO ESTADO DE SÃO PAULO (Brasil). [Mulheres em atividade de artesanato em ambiente com elementos religiosos na Casa de Detenção (Carandiru), 1963]. São Paulo, Brasil. 27 jan. 1955. Fotografia digitalizada; preto e branco; suporte em papel fotográfico. Disponível em: <link do dataverse>. Acesso em: 28 out. 2025. | T8: Estado de São Paulo - Penitenciárias e Presídios – Casa de Detenção do Carandiru Detentas do presídio do Carandiru são preparadas pela Madre do Divino Salvador para retornar ao convívio da sociedade. Recebem um pecúlio e os ensinamentos necessários para enfrentar a vida nas grandes cidades. Arq., 24/1/1963 – ACF
A9: =RIGHT(K9,3) -> 009 | B9: Pessoa com a mão estendida através de abertura em porta metálica prisional da Casa de Detenção (Carandiru) em 1979 | C9: Item | D9: 20641 | E9: Gerado pelo Dataverse | F9: Fotografia digitalizada; preto e branco; suporte em papel fotográfico | G9: São Paulo, Brasil | H9: Arquivo Público do Estado de São Paulo, Jornal Diários Associados | I9: Estado De São Paulo - Penitenciárias e Presídios - Casa de Detenção do Carandiru (Fotografias) | J9: Caixa: 3055 Folder: 5 | K9: =TEXTJOIN("", TRUE, Geral!B16:T16) -> BR-SPAPESP_DASP-PENITPRE-CSDTCARANDIRU_ICO-FOT-DGZ-MT0_3055-005-009 | L9: =$L$2 -> A Casa de Detenção de São Paulo, conhecida como Carandiru, foi formalmente criada em 1938 por decreto do interventor Adhemar de Barros, embora ainda instalada no edifício da Avenida Tiradentes. Sua implantação no bairro do Carandiru só se iniciou décadas depois, quando o governo estadual contratou, em 1951, o Escritório Técnico Ramos de Azevedo, Severo & Villares para projetar e conduzir a construção do novo complexo penitenciário em terreno contíguo à Penitenciária do Estado. As obras avançaram de forma modular, e o primeiro edifício concluído — o Pavilhão 2 — foi inaugurado em 1956, marcando a abertura parcial da chamada “Nova Casa de Detenção”. Ao longo dos anos seguintes, novos pavilhões foram sendo erguidos e inaugurados, compondo um conjunto arquitetônico que se consolidaria como um dos principais símbolos do sistema prisional paulista no século XX. Esta fotografia integra o fundo documental do grupo Diários Associados do Estado de São Paulo (DASP), custodiado pelo Arquivo Público do Estado de São Paulo (APESP), e registra aspectos desse prolongado processo de criação (1938), construção (a partir de 1951) e inauguração (a partir de 1956) da Casa de Detenção, conforme aponta a pesquisa de Maíra Rocha Machado, Bianca Tavolari e Maira Rosín (2025)[1]. | M9: A imagem em preto e branco retrata uma pessoa estendendo a mão através de uma pequena abertura retangular em uma porta metálica, da cela prisional. O gesto sugere tentativa de contato, comunicação ou expressão com o ambiente exterior. Registro associado à superlotação na Casa de Detenção (Carandiru) | N9: O acesso aos documentos deste acervo está condicionado ao compromisso de não repassá-los a terceiros, à obrigatoriedade de mencionar que os originais pertencem ao Arquivo Público do Estado de São Paulo, e à necessidade de novo Termo de Responsabilidade em caso de reutilização ou uso diverso do inicialmente acordado. O uso está sujeito às restrições previstas na Lei de Arquivos (Lei nº 8.159/1991), na Lei de Direitos Autorais (Lei nº 9.610/1998), nos artigos 138 e 145 do Código Penal, e no artigo 5º, inciso X, da Constituição Federal, especialmente quanto à proteção da honra e imagem de terceiros. A pessoa física ou jurídica responsável assume integral responsabilidade civil e penal por eventuais danos decorrentes do uso das reproduções e informações, eximindo o Arquivo Público do Estado de São Paulo de qualquer responsabilidade. | O9: Cela (Prisional); Precariedade estrutural; Carandiru; Superlotação. | P9: Fotografia (Iconográfico) | Q9: Digitalização de fotografia em preto e branco (analógica original) | R9: ="Figura n – ["&B9&"]"&CHAR(10)&"Fonte: Arquivo do Estado de São Paulo, "&TEXT(D9,"yyyy")&"." -> Figura n – [Pessoa com a mão estendida através de abertura em porta metálica prisional da Casa de Detenção (Carandiru) em 1979] Fonte: Arquivo do Estado de São Paulo, 1956. | S9: ="ARQUIVO PÚBLICO DO ESTADO DE SÃO PAULO (Brasil). ["&B9&"]. "&G9&". "&TEXT(D9,"dd")&" "&LOWER(TEXT(D9,"mmm"))&" "&TEXT(D9,"yyyy")&". "&F9&". Disponível em: <link do dataverse>. Acesso em: 28 out. 2025." -> ARQUIVO PÚBLICO DO ESTADO DE SÃO PAULO (Brasil). [Pessoa com a mão estendida através de abertura em porta metálica prisional da Casa de Detenção (Carandiru) em 1979]. São Paulo, Brasil. 05 jul. 1956. Fotografia digitalizada; preto e branco; suporte em papel fotográfico. Disponível em: <link do dataverse>. Acesso em: 28 out. 2025. | T9: Estado de São Paulo – Penitenciárias e Presídios – Casa de Detenção A Detenção está com superlotação e ameaça explodir. DN, 31/5/1979
A10: =RIGHT(K10,3) -> 010 | B10: Detentos com transtornos psiquiátricos em celas isoladas da Casa de Detenção da Avenida Tiradentes (1955) | C10: Item | D10: 20642 | E10: Gerado pelo Dataverse | F10: Fotografia digitalizada; preto e branco; suporte em papel fotográfico | G10: São Paulo, Brasil | H10: Arquivo Público do Estado de São Paulo, Jornal Diários Associados | I10: Estado De São Paulo - Penitenciárias e Presídios - Casa de Detenção do Carandiru (Fotografias) | J10: Caixa: 3055 Folder: 5 | K10: =TEXTJOIN("", TRUE, Geral!B18:T18) -> BR-SPAPESP_DASP-PENITPRE-CSDTCARANDIRU_ICO-FOT-DGZ-MT0_3055-005-010 | L10: =$L$2 -> A Casa de Detenção de São Paulo, conhecida como Carandiru, foi formalmente criada em 1938 por decreto do interventor Adhemar de Barros, embora ainda instalada no edifício da Avenida Tiradentes. Sua implantação no bairro do Carandiru só se iniciou décadas depois, quando o governo estadual contratou, em 1951, o Escritório Técnico Ramos de Azevedo, Severo & Villares para projetar e conduzir a construção do novo complexo penitenciário em terreno contíguo à Penitenciária do Estado. As obras avançaram de forma modular, e o primeiro edifício concluído — o Pavilhão 2 — foi inaugurado em 1956, marcando a abertura parcial da chamada “Nova Casa de Detenção”. Ao longo dos anos seguintes, novos pavilhões foram sendo erguidos e inaugurados, compondo um conjunto arquitetônico que se consolidaria como um dos principais símbolos do sistema prisional paulista no século XX. Esta fotografia integra o fundo documental do grupo Diários Associados do Estado de São Paulo (DASP), custodiado pelo Arquivo Público do Estado de São Paulo (APESP), e registra aspectos desse prolongado processo de criação (1938), construção (a partir de 1951) e inauguração (a partir de 1956) da Casa de Detenção, conforme aponta a pesquisa de Maíra Rocha Machado, Bianca Tavolari e Maira Rosín (2025)[1]. | M10: A fotografia em preto e branco registra um homem, detento da Casa de Detenção da Avenida Tiradentes (presídio anterior ao Carandiru), posicionado em uma área que o verso identifica como a "Isolada". O homem negro veste camisa de manga longa e encontra-se com os braços apoiados em uma superfície grade e as mãos entrelaçadas, olhando para cima. | N10: O acesso aos documentos deste acervo está condicionado ao compromisso de não repassá-los a terceiros, à obrigatoriedade de mencionar que os originais pertencem ao Arquivo Público do Estado de São Paulo, e à necessidade de novo Termo de Responsabilidade em caso de reutilização ou uso diverso do inicialmente acordado. O uso está sujeito às restrições previstas na Lei de Arquivos (Lei nº 8.159/1991), na Lei de Direitos Autorais (Lei nº 9.610/1998), nos artigos 138 e 145 do Código Penal, e no artigo 5º, inciso X, da Constituição Federal, especialmente quanto à proteção da honra e imagem de terceiros. A pessoa física ou jurídica responsável assume integral responsabilidade civil e penal por eventuais danos decorrentes do uso das reproduções e informações, eximindo o Arquivo Público do Estado de São Paulo de qualquer responsabilidade. | O10: Detento psiquiátrico; Cela isolada; Condições carcerárias; Assistência psiquiátrica; Presídio Tiradentes; Casa de Detenção (Avenida Tiradentes); Manicômio Judiciário; Superlotação; 1955; Fotojornalismo. | P10: Fotografia (Iconográfico) | Q10: Digitalização de fotografia em preto e branco (analógica original) | R10: ="Figura n – ["&B10&"]"&CHAR(10)&"Fonte: Arquivo do Estado de São Paulo, "&TEXT(D10,"yyyy")&"." -> Figura n – [Detentos com transtornos psiquiátricos em celas isoladas da Casa de Detenção da Avenida Tiradentes (1955)] Fonte: Arquivo do Estado de São Paulo, 1956. | S10: ="ARQUIVO PÚBLICO DO ESTADO DE SÃO PAULO (Brasil). ["&B10&"]. "&G10&". "&TEXT(D10,"dd")&" "&LOWER(TEXT(D10,"mmm"))&" "&TEXT(D10,"yyyy")&". "&F10&". Disponível em: <link do dataverse>. Acesso em: 28 out. 2025." -> ARQUIVO PÚBLICO DO ESTADO DE SÃO PAULO (Brasil). [Detentos com transtornos psiquiátricos em celas isoladas da Casa de Detenção da Avenida Tiradentes (1955)]. São Paulo, Brasil. 06 jul. 1956. Fotografia digitalizada; preto e branco; suporte em papel fotográfico. Disponível em: <link do dataverse>. Acesso em: 28 out. 2025. | T10: Estado de São Paulo – Penitenciárias e Presídios – Casa de Detenção da Avenida Tiradentes Na “Isolada” Detentos com transtornos mentais estão, irregularmente, jogados nas celas isoladas no presídio da Avenida Tiradentes. O Estado não toma nenhuma providência para removê-los para o Manicômio Judiciário. D.N., 2ª ed., 27/1/1955 – JL
A11: =RIGHT(K11,3) -> 011 | B11: Corredor de celas e circulação de pessoas no interior da Casa de Detenção (1978) | C11: Item | D11: 20710 | E11: Gerado pelo Dataverse | F11: Fotografia digitalizada; preto e branco; suporte em papel fotográfico | G11: São Paulo, Brasil | H11: Arquivo Público do Estado de São Paulo, Jornal Diários Associados | I11: Estado De São Paulo - Penitenciárias e Presídios - Casa de Detenção do Carandiru (Fotografias) | J11: Caixa: 3055 Folder: 5 | K11: =TEXTJOIN("", TRUE, Geral!B20:T20) -> BR-SPAPESP_DASP-PENITPRE-CSDTCARANDIRU_ICO-FOT-DGZ-MT0_3055-005-011 | L11: =$L$2 -> A Casa de Detenção de São Paulo, conhecida como Carandiru, foi formalmente criada em 1938 por decreto do interventor Adhemar de Barros, embora ainda instalada no edifício da Avenida Tiradentes. Sua implantação no bairro do Carandiru só se iniciou décadas depois, quando o governo estadual contratou, em 1951, o Escritório Técnico Ramos de Azevedo, Severo & Villares para projetar e conduzir a construção do novo complexo penitenciário em terreno contíguo à Penitenciária do Estado. As obras avançaram de forma modular, e o primeiro edifício concluído — o Pavilhão 2 — foi inaugurado em 1956, marcando a abertura parcial da chamada “Nova Casa de Detenção”. Ao longo dos anos seguintes, novos pavilhões foram sendo erguidos e inaugurados, compondo um conjunto arquitetônico que se consolidaria como um dos principais símbolos do sistema prisional paulista no século XX. Esta fotografia integra o fundo documental do grupo Diários Associados do Estado de São Paulo (DASP), custodiado pelo Arquivo Público do Estado de São Paulo (APESP), e registra aspectos desse prolongado processo de criação (1938), construção (a partir de 1951) e inauguração (a partir de 1956) da Casa de Detenção, conforme aponta a pesquisa de Maíra Rocha Machado, Bianca Tavolari e Maira Rosín (2025)[1]. | M11: Fotografia em preto e branco de corredor com portas metálicas dispostas em ambos os lados. Duas pessoas caminham pelo corredor com as costas voltadas para a câmera. Outras figuras são visíveis ao fundo. As portas possuem pequenas janelas e mecanismos de travamento. Registro de circulação em espaço prisional. | N11: O acesso aos documentos deste acervo está condicionado ao compromisso de não repassá-los a terceiros, à obrigatoriedade de mencionar que os originais pertencem ao Arquivo Público do Estado de São Paulo, e à necessidade de novo Termo de Responsabilidade em caso de reutilização ou uso diverso do inicialmente acordado. O uso está sujeito às restrições previstas na Lei de Arquivos (Lei nº 8.159/1991), na Lei de Direitos Autorais (Lei nº 9.610/1998), nos artigos 138 e 145 do Código Penal, e no artigo 5º, inciso X, da Constituição Federal, especialmente quanto à proteção da honra e imagem de terceiros. A pessoa física ou jurídica responsável assume integral responsabilidade civil e penal por eventuais danos decorrentes do uso das reproduções e informações, eximindo o Arquivo Público do Estado de São Paulo de qualquer responsabilidade. | O11: Sistema prisional; Arquitetura prisional; Casa de Detenção (Carandiru); Carandiru; Fotografia documental. | P11: Fotografia (Iconográfico) | Q11: Digitalização de fotografia em preto e branco (analógica original) | R11: ="Figura n – ["&B11&"]"&CHAR(10)&"Fonte: Arquivo do Estado de São Paulo, "&TEXT(D11,"yyyy")&"." -> Figura n – [Corredor de celas e circulação de pessoas no interior da Casa de Detenção (1978)] Fonte: Arquivo do Estado de São Paulo, 1956. | S11: ="ARQUIVO PÚBLICO DO ESTADO DE SÃO PAULO (Brasil). ["&B11&"]. "&G11&". "&TEXT(D11,"dd")&" "&LOWER(TEXT(D11,"mmm"))&" "&TEXT(D11,"yyyy")&". "&F11&". Disponível em: <link do dataverse>. Acesso em: 28 out. 2025." -> ARQUIVO PÚBLICO DO ESTADO DE SÃO PAULO (Brasil). [Corredor de celas e circulação de pessoas no interior da Casa de Detenção (1978)]. São Paulo, Brasil. 12 set. 1956. Fotografia digitalizada; preto e branco; suporte em papel fotográfico. Disponível em: <link do dataverse>. Acesso em: 28 out. 2025. | T11: Estado de São Paulo – Penitenciárias e Presídios – Casa de Detenção DN, 17/2/1978
A12: =RIGHT(K12,3) -> 012 | B12: Visita de familiares após motim na Casa de Detenção do Carandiru (1964) | C12: Item | D12: 20710 | E12: Gerado pelo Dataverse | F12: Fotografia digitalizada; preto e branco; suporte em papel fotográfico | G12: São Paulo, Brasil | H12: Arquivo Público do Estado de São Paulo, Jornal Diários Associados | I12: Estado De São Paulo - Penitenciárias e Presídios - Casa de Detenção do Carandiru (Fotografias) | J12: Caixa: 3055 Folder: 5 | K12: =TEXTJOIN("", TRUE, Geral!B22:T22) -> BR-SPAPESP_DASP-PENITPRE-CSDTCARANDIRU_ICO-FOT-DGZ-MT0_3055-005-012 | L12: =$L$2 -> A Casa de Detenção de São Paulo, conhecida como Carandiru, foi formalmente criada em 1938 por decreto do interventor Adhemar de Barros, embora ainda instalada no edifício da Avenida Tiradentes. Sua implantação no bairro do Carandiru só se iniciou décadas depois, quando o governo estadual contratou, em 1951, o Escritório Técnico Ramos de Azevedo, Severo & Villares para projetar e conduzir a construção do novo complexo penitenciário em terreno contíguo à Penitenciária do Estado. As obras avançaram de forma modular, e o primeiro edifício concluído — o Pavilhão 2 — foi inaugurado em 1956, marcando a abertura parcial da chamada “Nova Casa de Detenção”. Ao longo dos anos seguintes, novos pavilhões foram sendo erguidos e inaugurados, compondo um conjunto arquitetônico que se consolidaria como um dos principais símbolos do sistema prisional paulista no século XX. Esta fotografia integra o fundo documental do grupo Diários Associados do Estado de São Paulo (DASP), custodiado pelo Arquivo Público do Estado de São Paulo (APESP), e registra aspectos desse prolongado processo de criação (1938), construção (a partir de 1951) e inauguração (a partir de 1956) da Casa de Detenção, conforme aponta a pesquisa de Maíra Rocha Machado, Bianca Tavolari e Maira Rosín (2025)[1]. | M12: A fotografia em preto e branco registra o momento de visita familiar em frente ao portão de acesso da Casa de Detenção do Carandiru. O primeiro plano exibe dois grupos de familiares: à esquerda, uma mulher e duas crianças, e, à direita, outra mulher e um homem. O verso da fotografia contextualiza este momento como um período de alta tensão em 17 de agosto de 1964, seguindo um motim causado pelo "Regime do Terror", no qual os familiares foram mantidos em "afflictiva espera" de notícias ou permissão para visitar. O registro, portanto, documenta a dimensão afetiva da rotina prisional em um cenário de crise e repressão institucional. | N12: O acesso aos documentos deste acervo está condicionado ao compromisso de não repassá-los a terceiros, à obrigatoriedade de mencionar que os originais pertencem ao Arquivo Público do Estado de São Paulo, e à necessidade de novo Termo de Responsabilidade em caso de reutilização ou uso diverso do inicialmente acordado. O uso está sujeito às restrições previstas na Lei de Arquivos (Lei nº 8.159/1991), na Lei de Direitos Autorais (Lei nº 9.610/1998), nos artigos 138 e 145 do Código Penal, e no artigo 5º, inciso X, da Constituição Federal, especialmente quanto à proteção da honra e imagem de terceiros. A pessoa física ou jurídica responsável assume integral responsabilidade civil e penal por eventuais danos decorrentes do uso das reproduções e informações, eximindo o Arquivo Público do Estado de São Paulo de qualquer responsabilidade. | O12: Visita familiar; Motim; Regime do terror; Crise prisional; Tensão; Agente penitenciário; Grades (prisão); Família de detento; Carandiru; Casa de Detenção; 1964; Fotojornalismo. | P12: Fotografia (Iconográfico) | Q12: Digitalização de fotografia em preto e branco (analógica original) | R12: ="Figura n – ["&B12&"]"&CHAR(10)&"Fonte: Arquivo do Estado de São Paulo, "&TEXT(D12,"yyyy")&"." -> Figura n – [Visita de familiares após motim na Casa de Detenção do Carandiru (1964)] Fonte: Arquivo do Estado de São Paulo, 1956. | S12: ="ARQUIVO PÚBLICO DO ESTADO DE SÃO PAULO (Brasil). ["&B12&"]. "&G12&". "&TEXT(D12,"dd")&" "&LOWER(TEXT(D12,"mmm"))&" "&TEXT(D12,"yyyy")&". "&F12&". Disponível em: <link do dataverse>. Acesso em: 28 out. 2025." -> ARQUIVO PÚBLICO DO ESTADO DE SÃO PAULO (Brasil). [Visita de familiares após motim na Casa de Detenção do Carandiru (1964)]. São Paulo, Brasil. 12 set. 1956. Fotografia digitalizada; preto e branco; suporte em papel fotográfico. Disponível em: <link do dataverse>. Acesso em: 28 out. 2025. | T12: Estado de São Paulo – Penitenciárias e Presídios – Casa de Detenção do Carandiru Detenção: regime do terror provocou motim [Texto em pequeno retângulo, possivelmente um recorte de legenda ou matéria] Cenas dramáticas foram registradas na Casa de Detenção, defronte ao portão principal. Familiares de presos ficaram horas e horas em aflitiva espera, até que a direção do presídio permitisse a visitação. DN, 2ª ed., 17/8/1964 – CJS Miliciano comandava a tortura de presos na Casa de Detenção DN, 2ª ed., 18/8/1964 – CJS Cadeia vai abrir suas portas DN, 1ª ed., 1/9/1971 – DEC
